<?xml version="1.0" ?>
<!-- =================================================================================== -->
<!-- |    This document was autogenerated by xacro from /home/suturo/ros_ws/deps_ws/src/suturo_resources/suturo_resources/urdf/ms3_room_04.urdf.xacro | -->
<!-- |    EDITING THIS FILE BY HAND IS NOT RECOMMENDED                                 | -->
<!-- =================================================================================== -->
<robot name="iai-kitchen">
  <!--<material name="table_grey">
    <color rgba="0.8 0.8 0.8 1"/>
  </material>
  -->
  <material name="table_grey">
    <color rgba="0.255 0.62 0.223 1"/>
  </material>
  <material name="round_table_grey">
    <color rgba="0.8 0.8 0.8 1"/>
  </material>
  <material name="wall_pink">
    <color rgba="0.95 0.43 0.96 1"/>
  </material>
  <material name="shelf_blue">
    <color rgba="0.59 0.88 0.9 1"/>
  </material>
  <material name="shelf_door_green">
    <color rgba="0.64 0.87 0.82 1"/>
  </material>
  <material name="shelf_openable_handle_red">
    <color rgba="0.74 0.25 0.25 1"/>
  </material>
  <!-- <xacro:macro name="suturo_shelf_right_door_openable" params="name parent *origin size_x size_y size_z shelf_x_size"> -->
  <!--   <link name="${name}:shelf_link"> -->
  <!--     <visual> -->
  <!--       <material name="shelf_door_green"/> -->
  <!--       <origin xyz="0 0 0" rpy="0 0 0" /> -->
  <!--       <geometry> -->
  <!--         <box size="${size_x} ${size_y} ${size_z}" /> -->
  <!--       </geometry> -->
  <!--     </visual> -->
  <!--     <collision> -->
  <!--       <origin xyz="0 0 0" rpy="0 0 0" /> -->
  <!--       <geometry> -->
  <!--         <box size="${size_x} ${size_y} ${size_z}" /> -->
  <!--       </geometry> -->
  <!--     </collision> -->
  <!--   </link> -->
  <!--   <joint name="${name}:shelf_joint" type="revolute"> -->
  <!--     <origin xyz="${shelf_x_size/-2} ${size_y/2} 0" rpy="0 0 -3.1416"/> -->
  <!--     <axis xyz="0 0 1" /> -->
  <!--     <parent link="${parent}:shelf_piece"/> -->
  <!--     <child link="${name}:shelf_link"/> -->
  <!--     <limit effort="30" velocity="1.0" lower="0.0" upper="1.91986" /> -->
  <!--   </joint> -->
  <!-- </xacro:macro> -->
  <material name="shelf_hohc_handle_red">
    <color rgba="0.74 0.25 0.25 1"/>
  </material>
  <!-- <xacro:macro name="suturo_shelf_right_door_openable" params="name parent *origin size_x size_y size_z shelf_x_size"> -->
  <!--   <link name="${name}:shelf_link"> -->
  <!--     <visual> -->
  <!--       <material name="shelf_door_green"/> -->
  <!--       <origin xyz="0 0 0" rpy="0 0 0" /> -->
  <!--       <geometry> -->
  <!--         <box size="${size_x} ${size_y} ${size_z}" /> -->
  <!--       </geometry> -->
  <!--     </visual> -->
  <!--     <collision> -->
  <!--       <origin xyz="0 0 0" rpy="0 0 0" /> -->
  <!--       <geometry> -->
  <!--         <box size="${size_x} ${size_y} ${size_z}" /> -->
  <!--       </geometry> -->
  <!--     </collision> -->
  <!--   </link> -->
  <!--   <joint name="${name}:shelf_joint" type="revolute"> -->
  <!--     <origin xyz="${shelf_x_size/-2} ${size_y/2} 0" rpy="0 0 -3.1416"/> -->
  <!--     <axis xyz="0 0 1" /> -->
  <!--     <parent link="${parent}:shelf_piece"/> -->
  <!--     <child link="${name}:shelf_link"/> -->
  <!--     <limit effort="30" velocity="1.0" lower="0.0" upper="1.91986" /> -->
  <!--   </joint> -->
  <!-- </xacro:macro> -->
  <material name="shelf_billy_handle_red">
    <color rgba="0.74 0.25 0.25 1"/>
  </material>
  <gazebo>
    <gravity>0</gravity>
  </gazebo>
  <material name="door_green">
    <color rgba="0 0.31 0.22 1"/>
  </material>
  <material name="hinge_red">
    <color rgba="0.74 0.25 0.25 1"/>
  </material>
  <material name="handle_blue">
    <color rgba="0.3 0.5 0.78 1"/>
  </material>
  <material name="bucket_grey">
    <color rgba="0.8 0.8 0.8 1"/>
  </material>
  <material name="white">
    <color rgba="1 1 1 1"/>
  </material>
  <material name="orange">
    <color rgba="1 0.7 0 1"/>
  </material>
  <material name="handle_white">
    <color rgba="1 1 1 1"/>
  </material>
  <material name="bottom_white">
    <color rgba="1 1 1 1"/>
  </material>
  <material name="frame_wood">
    <color rgba="0.68 0.63 0.47 1"/>
  </material>
  <material name="handle_grey">
    <color rgba="0.7 0.7 0.7 1"/>
  </material>
  <material name="dishwasher_table_color">
    <color rgba="0.255 0.62 0.223 1"/>
  </material>
  <material name="color_grey">
    <color rgba="0.8 0.8 0.8 1"/>
  </material>
  <material name="color_red">
    <color rgba="1 0 0 1"/>
  </material>
  <material name="color_blue">
    <color rgba="0 0 1 1"/>
  </material>
  <material name="simple_couch_color_grey">
    <color rgba="0.8 0.8 0.8 1"/>
  </material>
  <material name="simple_couch_color_red">
    <color rgba="1 0 0 1"/>
  </material>
  <material name="simple_couch_color_blue">
    <color rgba="0 0 1 1"/>
  </material>
  <!--<material name="table_grey">
    <color rgba="0.8 0.8 0.8 1"/>
  </material>
  -->
  <material name="chair_color">
    <color rgba="0 0 0.5 1"/>
  </material>
  <!--<xacro:macro name="dishwasher_loop" params="dishwasher_number">
        <xacro:suturo_dishwasher
            name="${data['dishwashers'][dishwasher_number]['name']}:${data['dishwashers'][dishwasher_number]['knowledge_role']}"
            parent="${data['dishwashers'][dishwasher_number]['parent']}"
             size_x="${data['dishwashers'][dishwasher_number]['depth']}"
            size_y="${data['dishwashers'][dishwasher_number]['width']}"
            size_z="${data['dishwashers'][dishwasher_number]['height']}">
            <origin
                xyz="${data['dishwashers'][dishwasher_number]['x_pos']} ${data['dishwashers'][dishwasher_number]['y_pos']} 0.33475"
                rpy="0 0 ${data['dishwashers'][dishwasher_number]['z_rot']}" />
        </xacro:suturo_dishwasher>
        <xacro:if value="${(number_of_dishwashers - 1) > dishwasher_number}">
            <xacro:dishwasher_loop couch_number="${dishwasher_number + 1}" />
        </xacro:if>
    </xacro:macro> -->
  <!-- LINKS -->
  <link name="long_table:l_table:table_center">
    <visual>
      <material name="table_grey"/>
      <origin rpy="0 0 0" xyz="0 0 -0.3675"/>
      <geometry>
        <box size="0.73 1.17 0.735"/>
      </geometry>
    </visual>
    <collision>
      <origin rpy="0 0 0" xyz="0 0 -0.3675"/>
      <geometry>
        <box size="0.73 1.17 0.735"/>
      </geometry>
    </collision>
    <inertial>
      <origin rpy="0 0 0" xyz="0 0 0"/>
      <mass value="1.0"/>
      <inertia ixx="0.1" ixy="0.0" ixz="0.0" iyy="0.1" iyz="0.0" izz="0.1"/>
    </inertial>
  </link>
  <link name="long_table:l_table:table_origin"/>
  <link name="long_table:l_table:table_front_edge_center"/>
  <!-- JOINTS -->
  <joint name="long_table:l_table:table_origin_joint" type="fixed">
    <origin rpy="0 0 3.15" xyz="1.01 2.13 0"/>
    <parent link="urdf_offset"/>
    <child link="long_table:l_table:table_origin"/>
  </joint>
  <joint name="long_table:l_table:center_joint" type="fixed">
    <origin rpy="0 0 0" xyz="0.365 0.585 0.735"/>
    <parent link="long_table:l_table:table_origin"/>
    <child link="long_table:l_table:table_center"/>
  </joint>
  <joint name="long_table:l_table:table_front_edge_center_joint" type="fixed">
    <origin rpy="0 0 0" xyz="0 0.585 0.735"/>
    <parent link="long_table:l_table:table_origin"/>
    <child link="long_table:l_table:table_front_edge_center"/>
  </joint>
  <!-- LINKS -->
  <link name="popcorn_table:p_table:table_center">
    <visual>
      <material name="table_grey"/>
      <origin rpy="0 0 0" xyz="0 0 -0.355"/>
      <geometry>
        <box size="0.55 1.8 0.71"/>
      </geometry>
    </visual>
    <collision>
      <origin rpy="0 0 0" xyz="0 0 -0.355"/>
      <geometry>
        <box size="0.55 1.8 0.71"/>
      </geometry>
    </collision>
    <inertial>
      <origin rpy="0 0 0" xyz="0 0 0"/>
      <mass value="1.0"/>
      <inertia ixx="0.1" ixy="0.0" ixz="0.0" iyy="0.1" iyz="0.0" izz="0.1"/>
    </inertial>
  </link>
  <link name="popcorn_table:p_table:table_origin"/>
  <link name="popcorn_table:p_table:table_front_edge_center"/>
  <!-- JOINTS -->
  <joint name="popcorn_table:p_table:table_origin_joint" type="fixed">
    <origin rpy="0 0 1.57" xyz="3.03 5.68 0"/>
    <parent link="urdf_offset"/>
    <child link="popcorn_table:p_table:table_origin"/>
  </joint>
  <joint name="popcorn_table:p_table:center_joint" type="fixed">
    <origin rpy="0 0 0" xyz="0.275 0.9 0.71"/>
    <parent link="popcorn_table:p_table:table_origin"/>
    <child link="popcorn_table:p_table:table_center"/>
  </joint>
  <joint name="popcorn_table:p_table:table_front_edge_center_joint" type="fixed">
    <origin rpy="0 0 0" xyz="0 0.9 0.71"/>
    <parent link="popcorn_table:p_table:table_origin"/>
    <child link="popcorn_table:p_table:table_front_edge_center"/>
  </joint>
  <!-- LINKS -->
  <link name="couch_table:couch_table:table_center">
    <visual>
      <material name="table_grey"/>
      <origin rpy="0 0 0" xyz="0 0 -0.2165"/>
      <geometry>
        <box size="0.37 0.909 0.433"/>
      </geometry>
    </visual>
    <collision>
      <origin rpy="0 0 0" xyz="0 0 -0.2165"/>
      <geometry>
        <box size="0.37 0.909 0.433"/>
      </geometry>
    </collision>
    <inertial>
      <origin rpy="0 0 0" xyz="0 0 0"/>
      <mass value="1.0"/>
      <inertia ixx="0.1" ixy="0.0" ixz="0.0" iyy="0.1" iyz="0.0" izz="0.1"/>
    </inertial>
  </link>
  <link name="couch_table:couch_table:table_origin"/>
  <link name="couch_table:couch_table:table_front_edge_center"/>
  <!-- JOINTS -->
  <joint name="couch_table:couch_table:table_origin_joint" type="fixed">
    <origin rpy="0 0 0" xyz="4.83 1.99 0"/>
    <parent link="urdf_offset"/>
    <child link="couch_table:couch_table:table_origin"/>
  </joint>
  <joint name="couch_table:couch_table:center_joint" type="fixed">
    <origin rpy="0 0 0" xyz="0.185 0.4545 0.433"/>
    <parent link="couch_table:couch_table:table_origin"/>
    <child link="couch_table:couch_table:table_center"/>
  </joint>
  <joint name="couch_table:couch_table:table_front_edge_center_joint" type="fixed">
    <origin rpy="0 0 0" xyz="0 0.4545 0.433"/>
    <parent link="couch_table:couch_table:table_origin"/>
    <child link="couch_table:couch_table:table_front_edge_center"/>
  </joint>
  <!-- LINKS -->
  <link name="kitchen_island:kitchen_island:table_center">
    <visual>
      <material name="table_grey"/>
      <origin rpy="0 0 0" xyz="0 0 -0.4265"/>
      <geometry>
        <box size="0.796 -2.47 0.853"/>
      </geometry>
    </visual>
    <collision>
      <origin rpy="0 0 0" xyz="0 0 -0.4265"/>
      <geometry>
        <box size="0.796 -2.47 0.853"/>
      </geometry>
    </collision>
    <inertial>
      <origin rpy="0 0 0" xyz="0 0 0"/>
      <mass value="1.0"/>
      <inertia ixx="0.1" ixy="0.0" ixz="0.0" iyy="0.1" iyz="0.0" izz="0.1"/>
    </inertial>
  </link>
  <link name="kitchen_island:kitchen_island:table_origin"/>
  <link name="kitchen_island:kitchen_island:table_front_edge_center"/>
  <!-- JOINTS -->
  <joint name="kitchen_island:kitchen_island:table_origin_joint" type="fixed">
    <origin rpy="0 0 1.57" xyz="3 0.134 0"/>
    <parent link="urdf_offset"/>
    <child link="kitchen_island:kitchen_island:table_origin"/>
  </joint>
  <joint name="kitchen_island:kitchen_island:center_joint" type="fixed">
    <origin rpy="0 0 0" xyz="0.398 -1.235 0.853"/>
    <parent link="kitchen_island:kitchen_island:table_origin"/>
    <child link="kitchen_island:kitchen_island:table_center"/>
  </joint>
  <joint name="kitchen_island:kitchen_island:table_front_edge_center_joint" type="fixed">
    <origin rpy="0 0 0" xyz="0 -1.235 0.853"/>
    <parent link="kitchen_island:kitchen_island:table_origin"/>
    <child link="kitchen_island:kitchen_island:table_front_edge_center"/>
  </joint>
  <!-- LINKS -->
  <link name="oven_area:oven_area:table_center">
    <visual>
      <material name="table_grey"/>
      <origin rpy="0 0 0" xyz="0 0 -0.755"/>
      <geometry>
        <box size="0.68 1.2 1.51"/>
      </geometry>
    </visual>
    <collision>
      <origin rpy="0 0 0" xyz="0 0 -0.755"/>
      <geometry>
        <box size="0.68 1.2 1.51"/>
      </geometry>
    </collision>
    <inertial>
      <origin rpy="0 0 0" xyz="0 0 0"/>
      <mass value="1.0"/>
      <inertia ixx="0.1" ixy="0.0" ixz="0.0" iyy="0.1" iyz="0.0" izz="0.1"/>
    </inertial>
  </link>
  <link name="oven_area:oven_area:table_origin"/>
  <link name="oven_area:oven_area:table_front_edge_center"/>
  <!-- JOINTS -->
  <joint name="oven_area:oven_area:table_origin_joint" type="fixed">
    <origin rpy="0 0 4.72" xyz="3.77 -1.8 0"/>
    <parent link="urdf_offset"/>
    <child link="oven_area:oven_area:table_origin"/>
  </joint>
  <joint name="oven_area:oven_area:center_joint" type="fixed">
    <origin rpy="0 0 0" xyz="0.34 0.6 1.51"/>
    <parent link="oven_area:oven_area:table_origin"/>
    <child link="oven_area:oven_area:table_center"/>
  </joint>
  <joint name="oven_area:oven_area:table_front_edge_center_joint" type="fixed">
    <origin rpy="0 0 0" xyz="0 0.6 1.51"/>
    <parent link="oven_area:oven_area:table_origin"/>
    <child link="oven_area:oven_area:table_front_edge_center"/>
  </joint>
  <!-- LINKS -->
  <link name="work_surface_left:work_surface_left:table_center">
    <visual>
      <material name="table_grey"/>
      <origin rpy="0 0 0" xyz="0 0 -0.42"/>
      <geometry>
        <box size="0.68 0.82 0.84"/>
      </geometry>
    </visual>
    <collision>
      <origin rpy="0 0 0" xyz="0 0 -0.42"/>
      <geometry>
        <box size="0.68 0.82 0.84"/>
      </geometry>
    </collision>
    <inertial>
      <origin rpy="0 0 0" xyz="0 0 0"/>
      <mass value="1.0"/>
      <inertia ixx="0.1" ixy="0.0" ixz="0.0" iyy="0.1" iyz="0.0" izz="0.1"/>
    </inertial>
  </link>
  <link name="work_surface_left:work_surface_left:table_origin"/>
  <link name="work_surface_left:work_surface_left:table_front_edge_center"/>
  <!-- JOINTS -->
  <joint name="work_surface_left:work_surface_left:table_origin_joint" type="fixed">
    <origin rpy="0 0 4.72" xyz="2.94 -1.84 0"/>
    <parent link="urdf_offset"/>
    <child link="work_surface_left:work_surface_left:table_origin"/>
  </joint>
  <joint name="work_surface_left:work_surface_left:center_joint" type="fixed">
    <origin rpy="0 0 0" xyz="0.34 0.41 0.84"/>
    <parent link="work_surface_left:work_surface_left:table_origin"/>
    <child link="work_surface_left:work_surface_left:table_center"/>
  </joint>
  <joint name="work_surface_left:work_surface_left:table_front_edge_center_joint" type="fixed">
    <origin rpy="0 0 0" xyz="0 0.41 0.84"/>
    <parent link="work_surface_left:work_surface_left:table_origin"/>
    <child link="work_surface_left:work_surface_left:table_front_edge_center"/>
  </joint>
  <!-- LINKS -->
  <link name="work_surface_right:work_surface_right:table_center">
    <visual>
      <material name="table_grey"/>
      <origin rpy="0 0 0" xyz="0 0 -0.42"/>
      <geometry>
        <box size="0.68 0.64 0.84"/>
      </geometry>
    </visual>
    <collision>
      <origin rpy="0 0 0" xyz="0 0 -0.42"/>
      <geometry>
        <box size="0.68 0.64 0.84"/>
      </geometry>
    </collision>
    <inertial>
      <origin rpy="0 0 0" xyz="0 0 0"/>
      <mass value="1.0"/>
      <inertia ixx="0.1" ixy="0.0" ixz="0.0" iyy="0.1" iyz="0.0" izz="0.1"/>
    </inertial>
  </link>
  <link name="work_surface_right:work_surface_right:table_origin"/>
  <link name="work_surface_right:work_surface_right:table_front_edge_center"/>
  <!-- JOINTS -->
  <joint name="work_surface_right:work_surface_right:table_origin_joint" type="fixed">
    <origin rpy="0 0 4.72" xyz="1.705 -1.84 0"/>
    <parent link="urdf_offset"/>
    <child link="work_surface_right:work_surface_right:table_origin"/>
  </joint>
  <joint name="work_surface_right:work_surface_right:center_joint" type="fixed">
    <origin rpy="0 0 0" xyz="0.34 0.32 0.84"/>
    <parent link="work_surface_right:work_surface_right:table_origin"/>
    <child link="work_surface_right:work_surface_right:table_center"/>
  </joint>
  <joint name="work_surface_right:work_surface_right:table_front_edge_center_joint" type="fixed">
    <origin rpy="0 0 0" xyz="0 0.32 0.84"/>
    <parent link="work_surface_right:work_surface_right:table_origin"/>
    <child link="work_surface_right:work_surface_right:table_front_edge_center"/>
  </joint>
  <!-- LINKS -->
  <link name="refrigerator:refrigerator:table_center">
    <visual>
      <material name="table_grey"/>
      <origin rpy="0 0 0" xyz="0 0 -0.755"/>
      <geometry>
        <box size="0.68 0.595 1.51"/>
      </geometry>
    </visual>
    <collision>
      <origin rpy="0 0 0" xyz="0 0 -0.755"/>
      <geometry>
        <box size="0.68 0.595 1.51"/>
      </geometry>
    </collision>
    <inertial>
      <origin rpy="0 0 0" xyz="0 0 0"/>
      <mass value="1.0"/>
      <inertia ixx="0.1" ixy="0.0" ixz="0.0" iyy="0.1" iyz="0.0" izz="0.1"/>
    </inertial>
  </link>
  <link name="refrigerator:refrigerator:table_origin"/>
  <link name="refrigerator:refrigerator:table_front_edge_center"/>
  <!-- JOINTS -->
  <joint name="refrigerator:refrigerator:table_origin_joint" type="fixed">
    <origin rpy="0 0 4.72" xyz="1.11 -1.84 0"/>
    <parent link="urdf_offset"/>
    <child link="refrigerator:refrigerator:table_origin"/>
  </joint>
  <joint name="refrigerator:refrigerator:center_joint" type="fixed">
    <origin rpy="0 0 0" xyz="0.34 0.2975 1.51"/>
    <parent link="refrigerator:refrigerator:table_origin"/>
    <child link="refrigerator:refrigerator:table_center"/>
  </joint>
  <joint name="refrigerator:refrigerator:table_front_edge_center_joint" type="fixed">
    <origin rpy="0 0 0" xyz="0 0.2975 1.51"/>
    <parent link="refrigerator:refrigerator:table_origin"/>
    <child link="refrigerator:refrigerator:table_front_edge_center"/>
  </joint>
  <!-- LINKS -->
  <!-- Center of the couch, should not have a collision/visual to not overlap with the other two links -->
  <link name="suturo_couch:couch:place1">
    <!-- <visual> -->
    <!--   <material name="color_grey"/> -->
    <!--   <origin xyz="0 0 ${size_z/2}" rpy="0 0 0" /> -->
    <!--   <geometry> -->
    <!--     <box size="${size_x} ${size_y} ${size_z}" /> -->
    <!--   </geometry> -->
    <!-- </visual> -->
    <!-- <collision> -->
    <!--   <origin xyz="0 0 0" rpy="0 0 0" /> -->
    <!--   <geometry> -->
    <!--     <box size="${size_x} ${size_y} ${size_z}" /> -->
    <!--   </geometry> -->
    <!-- </collision> -->
    <!-- <inertial> -->
    <!--   <origin xyz="0 0 0" rpy="0 0 0"/> -->
    <!--   <mass value="1.0"/> -->
    <!--   <inertia ixx="0.1" ixy="0.0" ixz="0.0" iyy="0.1" iyz="0.0" izz="0.1"/> -->
    <!-- </inertial> -->
  </link>
  <link name="suturo_couch:couch:place2">
    <visual>
      <material name="color_red"/>
      <origin rpy="0 0 0" xyz="0 0 0"/>
      <geometry>
        <box size="0.75 0.85 0.3"/>
      </geometry>
    </visual>
    <collision>
      <origin rpy="0 0 0" xyz="0 0 0"/>
      <geometry>
        <box size="0.75 0.85 0.3"/>
      </geometry>
    </collision>
    <inertial>
      <origin rpy="0 0 0" xyz="0 0 0"/>
      <mass value="1.0"/>
      <inertia ixx="0.1" ixy="0.0" ixz="0.0" iyy="0.1" iyz="0.0" izz="0.1"/>
    </inertial>
  </link>
  <link name="suturo_couch:couch:place3">
    <visual>
      <material name="color_blue"/>
      <origin rpy="0 0 0" xyz="0 0 0"/>
      <geometry>
        <box size="0.75 0.85 0.3"/>
      </geometry>
    </visual>
    <collision>
      <origin rpy="0 0 0" xyz="0 0 0"/>
      <geometry>
        <box size="0.75 0.85 0.3"/>
      </geometry>
    </collision>
    <inertial>
      <origin rpy="0 0 0" xyz="0 0 0"/>
      <mass value="1.0"/>
      <inertia ixx="0.1" ixy="0.0" ixz="0.0" iyy="0.1" iyz="0.0" izz="0.1"/>
    </inertial>
  </link>
  <!-- JOINTS -->
  <joint name="suturo_couch:couch:couch_origin_joint" type="fixed">
    <origin rpy="0 0 1.57" xyz="4.2 1.31 0"/>
    <parent link="urdf_offset"/>
    <child link="suturo_couch:couch:place1"/>
  </joint>
  <joint name="suturo_couch:couch:couch_left_joint" type="fixed">
    <origin rpy="0 0 0" xyz="0 -0.425 0.15"/>
    <parent link="suturo_couch:couch:place1"/>
    <child link="suturo_couch:couch:place2"/>
  </joint>
  <joint name="suturo_couch:couch:couch_right_joint" type="fixed">
    <origin rpy="0 0 0" xyz="0 0.425 0.15"/>
    <parent link="suturo_couch:couch:place1"/>
    <child link="suturo_couch:couch:place3"/>
  </joint>
  <!-- General conveinience links -->
  <link name="shelf:shelf:shelf_origin"/>
  <link name="shelf:shelf:shelf_center"/>
  <link name="shelf:shelf:shelf_base_center"/>
  <joint name="shelf:shelf:shelf_origin_joint" type="fixed">
    <origin rpy="0 0 0" xyz="5.11 4.42 0"/>
    <parent link="urdf_offset"/>
    <child link="shelf:shelf:shelf_origin"/>
  </joint>
  <joint name="shelf:shelf:shelf_center_joint" type="fixed">
    <origin rpy="0 0 0" xyz="0.17 0.52 0.6775"/>
    <parent link="shelf:shelf:shelf_origin"/>
    <child link="shelf:shelf:shelf_center"/>
  </joint>
  <joint name="shelf:shelf:shelf_base_center_joint" type="fixed">
    <origin rpy="0 0 0" xyz="0.17 0.52 0.0"/>
    <parent link="shelf:shelf:shelf_origin"/>
    <child link="shelf:shelf:shelf_base_center"/>
  </joint>
  <!-- <joint name="${name}:shelf_left_side" type="fixed" -->
  <!--        size_x="${size_x}" size_y="0.01" size_z="${size_z}"> -->
  <!--   <origin xyz="${size_x/2} ${size_y} ${size_z/2}" rpy="0 0 0"/> -->
  <!--   <parent link="${name}:shelf_origin"/> -->
  <!--   <child link="${name}:shelf_door_left"/> -->
  <!-- </joint>  -->
  <!-- LINK -->
  <link name="shelf:shelf:shelf_back">
    <visual>
      <material name="shelf_blue"/>
      <origin rpy="0 0 0" xyz="0 0 0.0"/>
      <geometry>
        <box size="0.01 1.04 1.355"/>
      </geometry>
    </visual>
    <collision>
      <origin rpy="0 0 0" xyz="0 0 0.0"/>
      <geometry>
        <box size="0.01 1.04 1.355"/>
      </geometry>
    </collision>
    <inertial>
      <origin rpy="0 0 0" xyz="0 0 0"/>
      <mass value="1.0"/>
      <inertia ixx="0.1" ixy="0.0" ixz="0.0" iyy="0.1" iyz="0.0" izz="0.1"/>
    </inertial>
  </link>
  <!-- JOINT -->
  <joint name="shelf:shelf:shelf_back:joint" type="fixed">
    <origin rpy="0 0 0" xyz="0.34 0.52 0.6775"/>
    <parent link="shelf:shelf:shelf_origin"/>
    <child link="shelf:shelf:shelf_back"/>
  </joint>
  <!-- LINK -->
  <link name="shelf:shelf:shelf_right_side">
    <visual>
      <material name="shelf_blue"/>
      <origin rpy="0 0 0" xyz="0 0 0.0"/>
      <geometry>
        <box size="0.34 0.01 1.355"/>
      </geometry>
    </visual>
    <collision>
      <origin rpy="0 0 0" xyz="0 0 0.0"/>
      <geometry>
        <box size="0.34 0.01 1.355"/>
      </geometry>
    </collision>
    <inertial>
      <origin rpy="0 0 0" xyz="0 0 0"/>
      <mass value="1.0"/>
      <inertia ixx="0.1" ixy="0.0" ixz="0.0" iyy="0.1" iyz="0.0" izz="0.1"/>
    </inertial>
  </link>
  <!-- JOINT -->
  <joint name="shelf:shelf:shelf_right_side:joint" type="fixed">
    <origin rpy="0 0 0" xyz="0.17 0.0 0.6775"/>
    <parent link="shelf:shelf:shelf_origin"/>
    <child link="shelf:shelf:shelf_right_side"/>
  </joint>
  <!-- LINK -->
  <link name="shelf:shelf:shelf_left_side">
    <visual>
      <material name="shelf_blue"/>
      <origin rpy="0 0 0" xyz="0 0 0.0"/>
      <geometry>
        <box size="0.34 0.01 1.355"/>
      </geometry>
    </visual>
    <collision>
      <origin rpy="0 0 0" xyz="0 0 0.0"/>
      <geometry>
        <box size="0.34 0.01 1.355"/>
      </geometry>
    </collision>
    <inertial>
      <origin rpy="0 0 0" xyz="0 0 0"/>
      <mass value="1.0"/>
      <inertia ixx="0.1" ixy="0.0" ixz="0.0" iyy="0.1" iyz="0.0" izz="0.1"/>
    </inertial>
  </link>
  <!-- JOINT -->
  <joint name="shelf:shelf:shelf_left_side:joint" type="fixed">
    <origin rpy="0 0 0" xyz="0.17 1.04 0.6775"/>
    <parent link="shelf:shelf:shelf_origin"/>
    <child link="shelf:shelf:shelf_left_side"/>
  </joint>
  <!-- LINK -->
  <link name="shelf:shelf:shelf_floor_0">
    <visual>
      <material name="shelf_blue"/>
      <origin rpy="0 0 0" xyz="0 0 -0.02"/>
      <geometry>
        <box size="0.34 1.04 0.04"/>
      </geometry>
    </visual>
    <collision>
      <origin rpy="0 0 0" xyz="0 0 -0.02"/>
      <geometry>
        <box size="0.34 1.04 0.04"/>
      </geometry>
    </collision>
    <inertial>
      <origin rpy="0 0 0" xyz="0 0 0"/>
      <mass value="1.0"/>
      <inertia ixx="0.1" ixy="0.0" ixz="0.0" iyy="0.1" iyz="0.0" izz="0.1"/>
    </inertial>
  </link>
  <!-- JOINT -->
  <joint name="shelf:shelf:shelf_floor_0:joint" type="fixed">
    <origin rpy="0 0 0" xyz="0.0 0.0 0.077"/>
    <parent link="shelf:shelf:shelf_base_center"/>
    <child link="shelf:shelf:shelf_floor_0"/>
  </joint>
  <!-- LINK -->
  <link name="shelf:shelf:shelf_floor_1">
    <visual>
      <material name="shelf_blue"/>
      <origin rpy="0 0 0" xyz="0 0 -0.02"/>
      <geometry>
        <box size="0.34 1.04 0.04"/>
      </geometry>
    </visual>
    <collision>
      <origin rpy="0 0 0" xyz="0 0 -0.02"/>
      <geometry>
        <box size="0.34 1.04 0.04"/>
      </geometry>
    </collision>
    <inertial>
      <origin rpy="0 0 0" xyz="0 0 0"/>
      <mass value="1.0"/>
      <inertia ixx="0.1" ixy="0.0" ixz="0.0" iyy="0.1" iyz="0.0" izz="0.1"/>
    </inertial>
  </link>
  <!-- JOINT -->
  <joint name="shelf:shelf:shelf_floor_1:joint" type="fixed">
    <origin rpy="0 0 0" xyz="0.0 0.0 0.371"/>
    <parent link="shelf:shelf:shelf_base_center"/>
    <child link="shelf:shelf:shelf_floor_1"/>
  </joint>
  <!-- LINK -->
  <link name="shelf:shelf:shelf_floor_2">
    <visual>
      <material name="shelf_blue"/>
      <origin rpy="0 0 0" xyz="0 0 -0.02"/>
      <geometry>
        <box size="0.34 1.04 0.04"/>
      </geometry>
    </visual>
    <collision>
      <origin rpy="0 0 0" xyz="0 0 -0.02"/>
      <geometry>
        <box size="0.34 1.04 0.04"/>
      </geometry>
    </collision>
    <inertial>
      <origin rpy="0 0 0" xyz="0 0 0"/>
      <mass value="1.0"/>
      <inertia ixx="0.1" ixy="0.0" ixz="0.0" iyy="0.1" iyz="0.0" izz="0.1"/>
    </inertial>
  </link>
  <!-- JOINT -->
  <joint name="shelf:shelf:shelf_floor_2:joint" type="fixed">
    <origin rpy="0 0 0" xyz="0.0 0.0 0.716"/>
    <parent link="shelf:shelf:shelf_base_center"/>
    <child link="shelf:shelf:shelf_floor_2"/>
  </joint>
  <joint name="world_iai_kitchen:kitchen:room_joint" type="fixed">
    <origin rpy="0 0 0" xyz="2.825 -1 -0.05 "/>
    <parent link="urdf_offset"/>
    <child link="iai_kitchen:kitchen:room_center_link"/>
  </joint>
  <link name="iai_kitchen:kitchen:room_center_link">
    <visual>
      <geometry>
        <box size="5.25 3 0.01"/>
      </geometry>
      <material name="iai_kitchen:kitchen:color">
        <color rgba="0 0 1 0.1"/>
      </material>
    </visual>
  </link>
  <joint name="room_kitchen_entry_exit:entry_exit:connection_joint" type="fixed">
    <origin rpy="0 0 0" xyz="-2.225 1.09 0 "/>
    <parent link="iai_kitchen:kitchen:room_center_link"/>
    <child link="kitchen_entry_exit:entry_exit:link"/>
  </joint>
  <link name="kitchen_entry_exit:entry_exit:link"/>
  <joint name="world_arena:arena:room_joint" type="fixed">
    <origin rpy="0 0 0" xyz="3 2.05 -0.05 "/>
    <parent link="urdf_offset"/>
    <child link="arena:arena:room_center_link"/>
  </joint>
  <link name="arena:arena:room_center_link">
    <visual>
      <geometry>
        <box size="5.2 9.1 0.01"/>
      </geometry>
      <material name="arena:arena:color">
        <color rgba="1 0 0 0.0"/>
      </material>
    </visual>
  </link>
  <joint name="room_arena_entry:entry:connection_joint" type="fixed">
    <origin rpy="0 0 0" xyz="-2.33 -2.05 0 "/>
    <parent link="arena:arena:room_center_link"/>
    <child link="arena_entry:entry:link"/>
  </joint>
  <link name="arena_entry:entry:link"/>
  <joint name="room_arena_exit:exit:connection_joint" type="fixed">
    <origin rpy="0 0 0" xyz="-2.33 1.75 0 "/>
    <parent link="arena:arena:room_center_link"/>
    <child link="arena_exit:exit:link"/>
  </joint>
  <link name="arena_exit:exit:link"/>
  <joint name="world_living_room:living_room:room_joint" type="fixed">
    <origin rpy="0 0 0" xyz="2.825 2.2 -0.05 "/>
    <parent link="urdf_offset"/>
    <child link="living_room:living_room:room_center_link"/>
  </joint>
  <link name="living_room:living_room:room_center_link">
    <visual>
      <geometry>
        <box size="5.25 3.4 0.01"/>
      </geometry>
      <material name="living_room:living_room:color">
        <color rgba="0 1 0 0.1"/>
      </material>
    </visual>
  </link>
  <joint name="room_living_room_entry_exit:entry_exit:connection_joint" type="fixed">
    <origin rpy="0 0 0" xyz="-2.5650000000000004 1.6099999999999999 0 "/>
    <parent link="living_room:living_room:room_center_link"/>
    <child link="living_room_entry_exit:entry_exit:link"/>
  </joint>
  <link name="living_room_entry_exit:entry_exit:link"/>
  <joint name="world_dining_room:dining_room:room_joint" type="fixed">
    <origin rpy="0 0 0" xyz="2.825 5.25 -0.05 "/>
    <parent link="urdf_offset"/>
    <child link="dining_room:dining_room:room_center_link"/>
  </joint>
  <link name="dining_room:dining_room:room_center_link">
    <visual>
      <geometry>
        <box size="5.25 2.7 0.01"/>
      </geometry>
      <material name="dining_room:dining_room:color">
        <color rgba="1 0 0 0.1"/>
      </material>
    </visual>
  </link>
  <joint name="room_dining_room_entry_exit:entry_exit:connection_joint" type="fixed">
    <origin rpy="0 0 0" xyz="-0.7250000000000001 -1.35 0 "/>
    <parent link="dining_room:dining_room:room_center_link"/>
    <child link="dining_room_entry_exit:entry_exit:link"/>
  </joint>
  <link name="dining_room_entry_exit:entry_exit:link"/>
  <!-- LINKS -->
  <!-- TODO: Remove gravity for door -->
  <link name="iai_kitchen:arena:door_center">
    <visual>
      <material name="door_green"/>
      <origin rpy="0 0 0" xyz="0.4275 0 0"/>
      <geometry>
        <box size="0.855 0.04 2"/>
      </geometry>
    </visual>
    <collision>
      <origin rpy="0 0 0" xyz="0.4275 0 0"/>
      <geometry>
        <box size="0.855 0.04 2"/>
      </geometry>
    </collision>
    <inertial>
      <origin rpy="0 0 0" xyz="0 0 0"/>
      <mass value="1.0"/>
      <inertia ixx="0.1" ixy="0.0" ixz="0.0" iyy="0.1" iyz="0.0" izz="0.1"/>
    </inertial>
  </link>
  <link name="iai_kitchen:arena:door_hinge">
    <visual>
      <material name="hinge_red"/>
      <origin rpy="0 0 0" xyz="0 0 0"/>
      <geometry>
        <box size="0.05 0.05 2"/>
      </geometry>
    </visual>
    <collision>
      <origin rpy="0 0 0" xyz="0 0 0"/>
      <geometry>
        <box size="0.05 0.05 2"/>
      </geometry>
    </collision>
    <inertial>
      <origin rpy="0 0 0" xyz="0 0 0"/>
      <mass value="1.0"/>
      <inertia ixx="0.1" ixy="0.0" ixz="0.0" iyy="0.1" iyz="0.0" izz="0.1"/>
    </inertial>
  </link>
  <link name="iai_kitchen:arena:door_handle_link">
    <visual>
      <origin rpy="0 0 0" xyz="0.0 0.0 0.0"/>
      <geometry name="handle_blue">
        <cylinder length="0.10" radius="0.013"/>
      </geometry>
    </visual>
    <collision>
      <origin rpy="0 0 0" xyz="0.0 0.0 0.0"/>
      <geometry name="handle_collision_geom">
        <cylinder length="0.10" radius="0.013"/>
      </geometry>
    </collision>
    <inertial>
      <origin rpy="0 0 0" xyz="0 0 0"/>
      <mass value="1.0"/>
      <inertia ixx="0.1" ixy="0.0" ixz="0.0" iyy="0.1" iyz="0.0" izz="0.1"/>
    </inertial>
  </link>
  <link name="iai_kitchen:arena:door_handle_outside">
    <sphere_inertia mass="0" radius="0"/>
    <visual>
      <material name="handle_blue"/>
      <origin rpy="0 0 0" xyz="0 0 0"/>
      <geometry>
        <box size="0.015 0.15 0.01"/>
      </geometry>
    </visual>
    <collision>
      <origin rpy="0 0 0" xyz="0 0 0"/>
      <geometry>
        <box size="0.015 0.15 0.01"/>
      </geometry>
    </collision>
    <inertial>
      <origin rpy="0 0 0" xyz="0 0 0"/>
      <mass value="1.0"/>
      <inertia ixx="0.1" ixy="0.0" ixz="0.0" iyy="0.1" iyz="0.0" izz="0.1"/>
    </inertial>
  </link>
  <link name="iai_kitchen:arena:door_handle_inside">
    <sphere_inertia mass="0" radius="0"/>
    <visual>
      <material name="handle_blue"/>
      <origin rpy="0 0 0" xyz="0 0 0"/>
      <geometry>
        <box size="0.015 0.15 0.01"/>
      </geometry>
    </visual>
    <collision>
      <origin rpy="0 0 0" xyz="0 0 0"/>
      <geometry>
        <box size="0.015 0.15 0.01"/>
      </geometry>
    </collision>
    <inertial>
      <origin rpy="0 0 0" xyz="0 0 0"/>
      <mass value="1.0"/>
      <inertia ixx="0.1" ixy="0.0" ixz="0.0" iyy="0.1" iyz="0.0" izz="0.1"/>
    </inertial>
  </link>
  <!-- JOINTS -->
  <joint name="iai_kitchen:arena:door_origin_revolute_joint" type="revolute">
    <axis xyz="0 0 1"/>
    <limit effort="100" lower="-1.4" upper="0" velocity="10"/>
    <origin rpy="0 0 1.57" xyz="0 0 0"/>
    <parent link="iai_kitchen:arena:door_hinge"/>
    <child link="iai_kitchen:arena:door_center"/>
  </joint>
  <joint name="iai_kitchen:arena:door_hinge_joint" type="fixed">
    <axis xyz="0 0 0"/>
    <limit effort="1" lower="0" upper="1.5708" velocity="1"/>
    <origin rpy="0 0 0" xyz="0.58 -0.44 1.04"/>
    <parent link="urdf_offset"/>
    <child link="iai_kitchen:arena:door_hinge"/>
  </joint>
  <joint name="iai_kitchen:arena:door_handle_joint" type="revolute">
    <axis xyz="0 0 1"/>
    <limit effort="1" lower="0" upper="0.6283185307179586" velocity="1"/>
    <origin rpy="1.5707963267948966 0 0" xyz="0.82 0 0.02"/>
    <parent link="iai_kitchen:arena:door_center"/>
    <child link="iai_kitchen:arena:door_handle_link"/>
  </joint>
  <gazebo reference="iai_kitchen:arena:door_handle_joint">
    <springReference>-3.141592653589793</springReference>
    <springStiffness>1</springStiffness>
  </gazebo>
  <joint name="iai_kitchen:arena:door_handle_inside_joint" type="fixed">
    <origin rpy="0 0 1.5707963267948966" xyz="-0.04 0 0.06"/>
    <parent link="iai_kitchen:arena:door_handle_link"/>
    <child link="iai_kitchen:arena:door_handle_inside"/>
  </joint>
  <joint name="iai_kitchen:arena:door_handle_outside_joint" type="fixed">
    <origin rpy="0 0 -1.5707963267948966" xyz="-0.075 0 -0.05"/>
    <parent link="iai_kitchen:arena:door_handle_link"/>
    <child link="iai_kitchen:arena:door_handle_outside"/>
  </joint>
  <!-- LINKS -->
  <!-- TODO: Remove gravity for door -->
  <link name="living_room:arena:door_center">
    <visual>
      <material name="door_green"/>
      <origin rpy="0 0 0" xyz="0.4275 0 0"/>
      <geometry>
        <box size="0.855 0.04 2"/>
      </geometry>
    </visual>
    <collision>
      <origin rpy="0 0 0" xyz="0.4275 0 0"/>
      <geometry>
        <box size="0.855 0.04 2"/>
      </geometry>
    </collision>
    <inertial>
      <origin rpy="0 0 0" xyz="0 0 0"/>
      <mass value="1.0"/>
      <inertia ixx="0.1" ixy="0.0" ixz="0.0" iyy="0.1" iyz="0.0" izz="0.1"/>
    </inertial>
  </link>
  <link name="living_room:arena:door_hinge">
    <visual>
      <material name="hinge_red"/>
      <origin rpy="0 0 0" xyz="0 0 0"/>
      <geometry>
        <box size="0.05 0.05 2"/>
      </geometry>
    </visual>
    <collision>
      <origin rpy="0 0 0" xyz="0 0 0"/>
      <geometry>
        <box size="0.05 0.05 2"/>
      </geometry>
    </collision>
    <inertial>
      <origin rpy="0 0 0" xyz="0 0 0"/>
      <mass value="1.0"/>
      <inertia ixx="0.1" ixy="0.0" ixz="0.0" iyy="0.1" iyz="0.0" izz="0.1"/>
    </inertial>
  </link>
  <link name="living_room:arena:door_handle_link">
    <visual>
      <origin rpy="0 0 0" xyz="0.0 0.0 0.0"/>
      <geometry name="handle_blue">
        <cylinder length="0.10" radius="0.013"/>
      </geometry>
    </visual>
    <collision>
      <origin rpy="0 0 0" xyz="0.0 0.0 0.0"/>
      <geometry name="handle_collision_geom">
        <cylinder length="0.10" radius="0.013"/>
      </geometry>
    </collision>
    <inertial>
      <origin rpy="0 0 0" xyz="0 0 0"/>
      <mass value="1.0"/>
      <inertia ixx="0.1" ixy="0.0" ixz="0.0" iyy="0.1" iyz="0.0" izz="0.1"/>
    </inertial>
  </link>
  <link name="living_room:arena:door_handle_outside">
    <sphere_inertia mass="0" radius="0"/>
    <visual>
      <material name="handle_blue"/>
      <origin rpy="0 0 0" xyz="0 0 0"/>
      <geometry>
        <box size="0.015 0.15 0.01"/>
      </geometry>
    </visual>
    <collision>
      <origin rpy="0 0 0" xyz="0 0 0"/>
      <geometry>
        <box size="0.015 0.15 0.01"/>
      </geometry>
    </collision>
    <inertial>
      <origin rpy="0 0 0" xyz="0 0 0"/>
      <mass value="1.0"/>
      <inertia ixx="0.1" ixy="0.0" ixz="0.0" iyy="0.1" iyz="0.0" izz="0.1"/>
    </inertial>
  </link>
  <link name="living_room:arena:door_handle_inside">
    <sphere_inertia mass="0" radius="0"/>
    <visual>
      <material name="handle_blue"/>
      <origin rpy="0 0 0" xyz="0 0 0"/>
      <geometry>
        <box size="0.015 0.15 0.01"/>
      </geometry>
    </visual>
    <collision>
      <origin rpy="0 0 0" xyz="0 0 0"/>
      <geometry>
        <box size="0.015 0.15 0.01"/>
      </geometry>
    </collision>
    <inertial>
      <origin rpy="0 0 0" xyz="0 0 0"/>
      <mass value="1.0"/>
      <inertia ixx="0.1" ixy="0.0" ixz="0.0" iyy="0.1" iyz="0.0" izz="0.1"/>
    </inertial>
  </link>
  <!-- JOINTS -->
  <joint name="living_room:arena:door_origin_revolute_joint" type="revolute">
    <axis xyz="0 0 1"/>
    <limit effort="100" lower="-1.4" upper="0" velocity="10"/>
    <origin rpy="0 0 1.57" xyz="0 0 0"/>
    <parent link="living_room:arena:door_hinge"/>
    <child link="living_room:arena:door_center"/>
  </joint>
  <joint name="living_room:arena:door_hinge_joint" type="fixed">
    <axis xyz="0 0 0"/>
    <limit effort="1" lower="0" upper="1.5708" velocity="1"/>
    <origin rpy="0 0 0" xyz="0.28 3.37 1.04"/>
    <parent link="urdf_offset"/>
    <child link="living_room:arena:door_hinge"/>
  </joint>
  <joint name="living_room:arena:door_handle_joint" type="revolute">
    <axis xyz="0 0 1"/>
    <limit effort="1" lower="0" upper="0.6283185307179586" velocity="1"/>
    <origin rpy="1.5707963267948966 0 0" xyz="0.79 0 0.02"/>
    <parent link="living_room:arena:door_center"/>
    <child link="living_room:arena:door_handle_link"/>
  </joint>
  <gazebo reference="living_room:arena:door_handle_joint">
    <springReference>-3.141592653589793</springReference>
    <springStiffness>1</springStiffness>
  </gazebo>
  <joint name="living_room:arena:door_handle_inside_joint" type="fixed">
    <origin rpy="0 0 1.5707963267948966" xyz="-0.04 0 0.06"/>
    <parent link="living_room:arena:door_handle_link"/>
    <child link="living_room:arena:door_handle_inside"/>
  </joint>
  <joint name="living_room:arena:door_handle_outside_joint" type="fixed">
    <origin rpy="0 0 -1.5707963267948966" xyz="-0.075 0 -0.05"/>
    <parent link="living_room:arena:door_handle_link"/>
    <child link="living_room:arena:door_handle_outside"/>
  </joint>
  <link name="dishwasher_main">
    <inertial>
      <origin rpy="0 0 0" xyz="0.0 0.0 0.0"/>
      <mass value="1"/>
      <inertia ixx="1" ixy="0.0" ixz="0.0" iyy="1" iyz="0.0" izz="1"/>
    </inertial>
  </link>
  <joint name="dishwasher_main" type="fixed">
    <origin rpy="0 0 1.57" xyz="1.86 -2.2 0.0"/>
    <parent link="urdf_offset"/>
    <child link="dishwasher_main"/>
  </joint>
  <!-- Below there is another joint connecting these two links,
		 which breaks giskards ability to work with this -->
  <!-- <joint name="dishwasher_main_joint" type="fixed"> -->
  <!--   <xacro:insert_block name="origin" /> -->
  <!--   <parent link="dishwasher_main"/> -->
  <!--   <child link="sink_area_dish_washer_main"/> -->
  <!-- </joint> -->
  <link name="sink_area_dish_washer_main">
    <inertial>
      <origin rpy="0 0 0" xyz="0.0 0.0 0.0"/>
      <mass value="1"/>
      <inertia ixx="1" ixy="0.0" ixz="0.0" iyy="1" iyz="0.0" izz="1"/>
    </inertial>
    <visual>
      <origin rpy="0 0 0" xyz="0 0 0"/>
      <geometry>
        <mesh filename="package://iai_kitchen/meshes/misc/DishWasher.obj"/>
      </geometry>
    </visual>
    <collision>
      <origin rpy="0 0 0" xyz="0 0 0"/>
      <geometry>
        <mesh filename="package://iai_kitchen/meshes/misc/DishWasher.obj"/>
      </geometry>
    </collision>
  </link>
  <link name="sink_area_dish_washer_door">
    <inertial>
      <origin rpy="0 0 0" xyz="0.0 0.0 0.0"/>
      <mass value="1"/>
      <inertia ixx="0.03" ixy="0.0" ixz="0.0" iyy="0.07" iyz="0.0" izz="0.041"/>
    </inertial>
    <visual>
      <origin rpy="1.57079632679 0 0" xyz="0 0 0"/>
      <geometry>
        <mesh filename="package://iai_kitchen/meshes/misc/DishWasherDoor.obj"/>
      </geometry>
    </visual>
    <collision>
      <origin rpy="1.57079632679 0 0" xyz="0 0 0"/>
      <geometry>
        <mesh filename="package://iai_kitchen/meshes/misc/DishWasherDoor.obj"/>
      </geometry>
    </collision>
  </link>
  <gazebo reference="sink_area_dish_washer_door">
    <gravity>false</gravity>
    <dampingFactor>0.01</dampingFactor>
  </gazebo>
  <link name="sink_area_dish_washer_door_handle">
    <inertial>
      <origin rpy="0 0 0" xyz="0.0 0.0 0.0"/>
      <mass value="0.1"/>
      <inertia ixx="0.0025" ixy="0.0" ixz="0.0" iyy="0.0025" iyz="0.0" izz="0.000125"/>
    </inertial>
    <visual>
      <origin rpy="0 0 0" xyz="0 0 0"/>
      <geometry>
        <mesh filename="package://iai_kitchen/meshes/handles/Handle60.obj"/>
      </geometry>
    </visual>
    <collision>
      <origin rpy="0 0 0" xyz="0 0 0"/>
      <geometry>
        <mesh filename="package://iai_kitchen/meshes/handles/Handle60.obj"/>
      </geometry>
    </collision>
  </link>
  <gazebo reference="sink_area_dish_washer_door_handle">
    <gravity>false</gravity>
    <dampingFactor>0.01</dampingFactor>
  </gazebo>
  <link name="dishwasher_tab"/>
  <link name="dishwasher_table:d_table:table_origin"/>
  <link name="dishwasher_table:d_table:table_front_edge_center"/>
  <link name="dishwasher_table:d_table:table_center">
    <visual>
      <material name="dishwasher_table_color"/>
      <origin rpy="0 0 0" xyz="0 0 0"/>
      <geometry>
        <box size="0.6 0.6 0.02"/>
      </geometry>
    </visual>
    <collision>
      <origin rpy="0 0 0" xyz="0 0 0"/>
      <geometry>
        <box size="0.6 0.6 0.02"/>
      </geometry>
    </collision>
  </link>
  <!--
    <xacro:if value="simulated"/>
    -->
  <joint name="dishwasher_tab_joint" type="fixed">
    <origin rpy="0 0 0" xyz="-0.1 0.1 0.15"/>
    <parent link="sink_area_dish_washer_door_handle"/>
    <child link="dishwasher_tab"/>
  </joint>
  <joint name="sink_area_dish_washer_main_joint" type="fixed">
    <!-- was revolute before, changed to fixed -->
    <axis xyz="1 0 0"/>
    <!-- <limit effort="300" lower="0" upper="0" velocity="10"/> -->
    <origin rpy="0 0 0" xyz="0.08 -0.78 0.44 "/>
    <parent link="dishwasher_main"/>
    <child link="sink_area_dish_washer_main"/>
  </joint>
  <joint name="sink_area_dish_washer_door_joint" type="revolute">
    <origin rpy="-1.57079632679 0.03 0" xyz="0.27 0. -0.325"/>
    <parent link="sink_area_dish_washer_main"/>
    <child link="sink_area_dish_washer_door"/>
    <axis xyz="0 0 1"/>
    <!-- FIXME make closed position stable instead of forbidding opening... -->
    <!-- TODO Fix Limits to be able to open dishwasher-->
    <limit effort="300" lower="0.0" upper="1.57079632679" velocity="10"/>
  </joint>
  <joint name="sink_area_dish_washer_door_handle_joint" type="fixed">
    <origin rpy="-1.57079632679 0 0" xyz="0.0625 -0.6325 0."/>
    <parent link="sink_area_dish_washer_door"/>
    <child link="sink_area_dish_washer_door_handle"/>
  </joint>
  <!-- from here for dishwasher_table -->
  <joint name="dish_washer_table_main_joint" type="fixed">
    <origin rpy="0.0 0 0" xyz="0.0 0.0 0.39"/>
    <parent link="sink_area_dish_washer_main"/>
    <child link="dishwasher_table:d_table:table_origin"/>
  </joint>
  <joint name="dish_washer_table_center_joint" type="fixed">
    <origin rpy="0 0 0" xyz="0.3 0 0"/>
    <parent link="dishwasher_table:d_table:table_origin"/>
    <child link="dishwasher_table:d_table:table_front_edge_center"/>
  </joint>
  <joint name="dish_washer_table_edge_joint" type="fixed">
    <origin rpy="0 0 0" xyz="0 0 0"/>
    <parent link="dishwasher_table:d_table:table_origin"/>
    <child link="dishwasher_table:d_table:table_center"/>
  </joint>
  <!-- LINKS -->
  <link name="chair:chair:chair_center">
    <visual>
      <material name="chair_color"/>
      <origin rpy="0 0 0" xyz="0 0 0"/>
      <geometry>
        <box size="0.3 0.3 0.5"/>
      </geometry>
    </visual>
    <collision>
      <origin rpy="0 0 0" xyz="0 0 0"/>
      <geometry>
        <box size="0.3 0.3 0.5"/>
      </geometry>
    </collision>
  </link>
  <link name="chair:chair:chair_backrest">
    <visual>
      <material name="chair_color"/>
      <origin rpy="0 0 0" xyz="0 0 0"/>
      <geometry>
        <box size="0.3 0.05  0.5"/>
      </geometry>
    </visual>
    <collision>
      <origin rpy="0 0 0" xyz="0 0 0"/>
      <geometry>
        <box size="0.3 0.05 0.5"/>
      </geometry>
    </collision>
  </link>
  <link name="chair:chair:chair_origin"/>
  <link name="chair:chair:chair_front_edge_center"/>
  <!-- JOINTS -->
  <joint name="chair:chair:chair_origin_joint" type="fixed">
    <origin rpy="0 0 0" xyz="2.8 1.3 0"/>
    <parent link="urdf_offset"/>
    <child link="chair:chair:chair_origin"/>
  </joint>
  <joint name="chair:chair:center_joint" type="fixed">
    <origin rpy="0 0 0" xyz="0 0 0.25"/>
    <parent link="chair:chair:chair_origin"/>
    <child link="chair:chair:chair_center"/>
  </joint>
  <joint name="chair:chair:chair_front_edge_center_joint" type="fixed">
    <origin rpy="0 0 0" xyz="0 0.15 0.5"/>
    <parent link="chair:chair:chair_origin"/>
    <child link="chair:chair:chair_front_edge_center"/>
  </joint>
  <joint name="chair:chair:chair_backrest_joint" type="fixed">
    <origin rpy="0 0 0" xyz="0 -0.12 0.25"/>
    <parent link="chair:chair:chair_center"/>
    <child link="chair:chair:chair_backrest"/>
  </joint>
  <!-- General conveinience links -->
  <link name="shelf_billy:shelf_billy:shelf_origin"/>
  <link name="shelf_billy:shelf_billy:shelf_center"/>
  <link name="shelf_billy:shelf_billy:shelf_base_center"/>
  <joint name="shelf_billy:shelf_billy:shelf_origin_joint" type="fixed">
    <origin rpy="0 0 0" xyz="5.1 -1.5 0"/>
    <parent link="urdf_offset"/>
    <child link="shelf_billy:shelf_billy:shelf_origin"/>
  </joint>
  <joint name="shelf_billy:shelf_billy:shelf_center_joint" type="fixed">
    <origin rpy="0 0 0" xyz="0.195 0.4 1.01"/>
    <parent link="shelf_billy:shelf_billy:shelf_origin"/>
    <child link="shelf_billy:shelf_billy:shelf_center"/>
  </joint>
  <joint name="shelf_billy:shelf_billy:shelf_base_center_joint" type="fixed">
    <origin rpy="0 0 0" xyz="0.195 0.4 0.0"/>
    <parent link="shelf_billy:shelf_billy:shelf_origin"/>
    <child link="shelf_billy:shelf_billy:shelf_base_center"/>
  </joint>
  <!-- LINK -->
  <link name="shelf_billy:shelf_billy:shelf_back">
    <visual>
      <material name="shelf_blue"/>
      <origin rpy="0 0 0" xyz="0 0 0.0"/>
      <geometry>
        <box size="0.02 0.8 2.02"/>
      </geometry>
    </visual>
    <collision>
      <origin rpy="0 0 0" xyz="0 0 0.0"/>
      <geometry>
        <box size="0.02 0.8 2.02"/>
      </geometry>
    </collision>
    <inertial>
      <origin rpy="0 0 0" xyz="0 0 0"/>
      <mass value="1.0"/>
      <inertia ixx="0.1" ixy="0.0" ixz="0.0" iyy="0.1" iyz="0.0" izz="0.1"/>
    </inertial>
  </link>
  <!-- JOINT -->
  <joint name="shelf_billy:shelf_billy:shelf_back:joint" type="fixed">
    <origin rpy="0 0 0" xyz="0.39 0.4 1.01"/>
    <parent link="shelf_billy:shelf_billy:shelf_origin"/>
    <child link="shelf_billy:shelf_billy:shelf_back"/>
  </joint>
  <!-- LINK -->
  <link name="shelf_billy:shelf_billy:shelf_right_side">
    <visual>
      <material name="shelf_blue"/>
      <origin rpy="0 0 0" xyz="0 0 0.0"/>
      <geometry>
        <box size="0.39 0.02 2.02"/>
      </geometry>
    </visual>
    <collision>
      <origin rpy="0 0 0" xyz="0 0 0.0"/>
      <geometry>
        <box size="0.39 0.02 2.02"/>
      </geometry>
    </collision>
    <inertial>
      <origin rpy="0 0 0" xyz="0 0 0"/>
      <mass value="1.0"/>
      <inertia ixx="0.1" ixy="0.0" ixz="0.0" iyy="0.1" iyz="0.0" izz="0.1"/>
    </inertial>
  </link>
  <!-- JOINT -->
  <joint name="shelf_billy:shelf_billy:shelf_right_side:joint" type="fixed">
    <origin rpy="0 0 0" xyz="0.195 0.01 1.01"/>
    <parent link="shelf_billy:shelf_billy:shelf_origin"/>
    <child link="shelf_billy:shelf_billy:shelf_right_side"/>
  </joint>
  <!-- LINK -->
  <link name="shelf_billy:shelf_billy:shelf_left_side">
    <visual>
      <material name="shelf_blue"/>
      <origin rpy="0 0 0" xyz="0 0 0.0"/>
      <geometry>
        <box size="0.39 0.02 2.02"/>
      </geometry>
    </visual>
    <collision>
      <origin rpy="0 0 0" xyz="0 0 0.0"/>
      <geometry>
        <box size="0.39 0.02 2.02"/>
      </geometry>
    </collision>
    <inertial>
      <origin rpy="0 0 0" xyz="0 0 0"/>
      <mass value="1.0"/>
      <inertia ixx="0.1" ixy="0.0" ixz="0.0" iyy="0.1" iyz="0.0" izz="0.1"/>
    </inertial>
  </link>
  <!-- JOINT -->
  <joint name="shelf_billy:shelf_billy:shelf_left_side:joint" type="fixed">
    <origin rpy="0 0 0" xyz="0.195 0.79 1.01"/>
    <parent link="shelf_billy:shelf_billy:shelf_origin"/>
    <child link="shelf_billy:shelf_billy:shelf_left_side"/>
  </joint>
  <!-- LINK -->
  <link name="shelf_billy:shelf_billy:shelf_floor_0">
    <visual>
      <material name="shelf_blue"/>
      <origin rpy="0 0 0" xyz="0 0 -0.02"/>
      <geometry>
        <box size="0.39 0.8 0.04"/>
      </geometry>
    </visual>
    <collision>
      <origin rpy="0 0 0" xyz="0 0 -0.02"/>
      <geometry>
        <box size="0.39 0.8 0.04"/>
      </geometry>
    </collision>
    <inertial>
      <origin rpy="0 0 0" xyz="0 0 0"/>
      <mass value="1.0"/>
      <inertia ixx="0.1" ixy="0.0" ixz="0.0" iyy="0.1" iyz="0.0" izz="0.1"/>
    </inertial>
  </link>
  <!-- JOINT -->
  <joint name="shelf_billy:shelf_billy:shelf_floor_0:joint" type="fixed">
    <origin rpy="0 0 0" xyz="0.0 0.0 0.1"/>
    <parent link="shelf_billy:shelf_billy:shelf_base_center"/>
    <child link="shelf_billy:shelf_billy:shelf_floor_0"/>
  </joint>
  <!-- LINK -->
  <link name="shelf_billy:shelf_billy:shelf_floor_1">
    <visual>
      <material name="shelf_blue"/>
      <origin rpy="0 0 0" xyz="0 0 -0.02"/>
      <geometry>
        <box size="0.39 0.8 0.04"/>
      </geometry>
    </visual>
    <collision>
      <origin rpy="0 0 0" xyz="0 0 -0.02"/>
      <geometry>
        <box size="0.39 0.8 0.04"/>
      </geometry>
    </collision>
    <inertial>
      <origin rpy="0 0 0" xyz="0 0 0"/>
      <mass value="1.0"/>
      <inertia ixx="0.1" ixy="0.0" ixz="0.0" iyy="0.1" iyz="0.0" izz="0.1"/>
    </inertial>
  </link>
  <!-- JOINT -->
  <joint name="shelf_billy:shelf_billy:shelf_floor_1:joint" type="fixed">
    <origin rpy="0 0 0" xyz="0.0 0.0 0.54"/>
    <parent link="shelf_billy:shelf_billy:shelf_base_center"/>
    <child link="shelf_billy:shelf_billy:shelf_floor_1"/>
  </joint>
  <!-- LINK -->
  <link name="shelf_billy:shelf_billy:shelf_floor_2">
    <visual>
      <material name="shelf_blue"/>
      <origin rpy="0 0 0" xyz="0 0 -0.02"/>
      <geometry>
        <box size="0.39 0.8 0.04"/>
      </geometry>
    </visual>
    <collision>
      <origin rpy="0 0 0" xyz="0 0 -0.02"/>
      <geometry>
        <box size="0.39 0.8 0.04"/>
      </geometry>
    </collision>
    <inertial>
      <origin rpy="0 0 0" xyz="0 0 0"/>
      <mass value="1.0"/>
      <inertia ixx="0.1" ixy="0.0" ixz="0.0" iyy="0.1" iyz="0.0" izz="0.1"/>
    </inertial>
  </link>
  <!-- JOINT -->
  <joint name="shelf_billy:shelf_billy:shelf_floor_2:joint" type="fixed">
    <origin rpy="0 0 0" xyz="0.0 0.0 1.055"/>
    <parent link="shelf_billy:shelf_billy:shelf_base_center"/>
    <child link="shelf_billy:shelf_billy:shelf_floor_2"/>
  </joint>
  <!-- LINK -->
  <link name="shelf_billy:shelf_billy:shelf_floor_3">
    <visual>
      <material name="shelf_blue"/>
      <origin rpy="0 0 0" xyz="0 0 -0.02"/>
      <geometry>
        <box size="0.39 0.8 0.04"/>
      </geometry>
    </visual>
    <collision>
      <origin rpy="0 0 0" xyz="0 0 -0.02"/>
      <geometry>
        <box size="0.39 0.8 0.04"/>
      </geometry>
    </collision>
    <inertial>
      <origin rpy="0 0 0" xyz="0 0 0"/>
      <mass value="1.0"/>
      <inertia ixx="0.1" ixy="0.0" ixz="0.0" iyy="0.1" iyz="0.0" izz="0.1"/>
    </inertial>
  </link>
  <!-- JOINT -->
  <joint name="shelf_billy:shelf_billy:shelf_floor_3:joint" type="fixed">
    <origin rpy="0 0 0" xyz="0.0 0.0 2.02"/>
    <parent link="shelf_billy:shelf_billy:shelf_base_center"/>
    <child link="shelf_billy:shelf_billy:shelf_floor_3"/>
  </joint>
  <link name="shelf_billy:shelf_billy:shelf_door_left">
    <visual>
      <material name="shelf_door_green"/>
      <origin rpy="0 0 0" xyz="0 -0.19 0"/>
      <geometry>
        <box size="0.02 0.4 0.97"/>
      </geometry>
    </visual>
    <collision>
      <origin rpy="0 0 0" xyz="0 -0.19 0"/>
      <geometry>
        <box size="0.02 0.4 0.97"/>
      </geometry>
    </collision>
    <inertial>
      <origin rpy="0 0 0" xyz="0 0 0"/>
      <mass value="1.0"/>
      <inertia ixx="0.1" ixy="0.0" ixz="0.0" iyy="0.1" iyz="0.0" izz="0.1"/>
    </inertial>
  </link>
  <link name="shelf_billy:shelf_billy:shelf_door_left:handle">
    <visual>
      <material name="shelf_billy_handle_red"/>
      <origin rpy="0 0 0" xyz="0 0 0"/>
      <geometry>
        <cylinder length="0.02" radius="0.0075"/>
      </geometry>
    </visual>
    <collision>
      <origin rpy="0 0 0" xyz="0 0 0"/>
      <geometry>
        <cylinder length="0.02" radius="0.0075"/>
      </geometry>
    </collision>
    <inertial>
      <origin rpy="0 0 0" xyz="0 0 0"/>
      <mass value="1.0"/>
      <inertia ixx="0.1" ixy="0.0" ixz="0.0" iyy="0.1" iyz="0.0" izz="0.1"/>
    </inertial>
  </link>
  <joint name="shelf_billy:shelf_billy:shelf_door_left:handle_joint" type="fixed">
    <origin rpy="0 1.5707963267948966 0" xyz="-0.03 -0.3825 0.0075"/>
    <axis xyz="0 0 1"/>
    <parent link="shelf_billy:shelf_billy:shelf_door_left"/>
    <child link="shelf_billy:shelf_billy:shelf_door_left:handle"/>
  </joint>
  <joint name="shelf_billy:shelf_billy:shelf_door_left:joint" type="revolute">
    <origin rpy="0 0 0" xyz="-0.215 0 -0.44"/>
    <axis xyz="0 0 1"/>
    <parent link="shelf_billy:shelf_billy:shelf_left_side"/>
    <child link="shelf_billy:shelf_billy:shelf_door_left"/>
    <limit effort="30" lower="-1.7" upper="0.0" velocity="1.0"/>
  </joint>
  <link name="urdf_main"/>
  <joint name="map_urdf_joint" type="fixed">
    <origin rpy="0 0 0.0" xyz="0 0 0 "/>
    <parent link="urdf_main"/>
    <child link="urdf_offset"/>
  </joint>
  <link name="urdf_offset"/>
</robot>


