<?xml version="1.0" ?>
<!-- =================================================================================== -->
<!-- |    This document was autogenerated by xacro from suturo_shelf_hohc.urdf.xacro   | -->
<!-- |    EDITING THIS FILE BY HAND IS NOT RECOMMENDED                                 | -->
<!-- =================================================================================== -->
<robot name="iai-kitchen">
  <!--<material name="table_grey">
    <color rgba="0.8 0.8 0.8 1"/>
  </material>
  -->
  <material name="table_grey">
    <color rgba="0.255 0.62 0.223 1"/>
  </material>
  <material name="round_table_grey">
    <color rgba="0.8 0.8 0.8 1"/>
  </material>
  <material name="wall_pink">
    <color rgba="0.95 0.43 0.96 1"/>
  </material>
  <material name="shelf_blue">
    <color rgba="0.59 0.88 0.9 1"/>
  </material>
  <material name="shelf_door_green">
    <color rgba="0.64 0.87 0.82 1"/>
  </material>
  <material name="shelf_openable_handle_red">
    <color rgba="0.74 0.25 0.25 1"/>
  </material>
  <!-- <xacro:macro name="suturo_shelf_right_door_openable" params="name parent *origin size_x size_y size_z shelf_x_size"> -->
  <!--   <link name="${name}:shelf_link"> -->
  <!--     <visual> -->
  <!--       <material name="shelf_door_green"/> -->
  <!--       <origin xyz="0 0 0" rpy="0 0 0" /> -->
  <!--       <geometry> -->
  <!--         <box size="${size_x} ${size_y} ${size_z}" /> -->
  <!--       </geometry> -->
  <!--     </visual> -->
  <!--     <collision> -->
  <!--       <origin xyz="0 0 0" rpy="0 0 0" /> -->
  <!--       <geometry> -->
  <!--         <box size="${size_x} ${size_y} ${size_z}" /> -->
  <!--       </geometry> -->
  <!--     </collision> -->
  <!--   </link> -->
  <!--   <joint name="${name}:shelf_joint" type="revolute"> -->
  <!--     <origin xyz="${shelf_x_size/-2} ${size_y/2} 0" rpy="0 0 -3.1416"/> -->
  <!--     <axis xyz="0 0 1" /> -->
  <!--     <parent link="${parent}:shelf_piece"/> -->
  <!--     <child link="${name}:shelf_link"/> -->
  <!--     <limit effort="30" velocity="1.0" lower="0.0" upper="1.91986" /> -->
  <!--   </joint> -->
  <!-- </xacro:macro> -->
  <material name="shelf_hohc_handle_red">
    <color rgba="0.74 0.25 0.25 1"/>
  </material>
  <!-- <xacro:macro name="suturo_shelf_right_door_openable" params="name parent *origin size_x size_y size_z shelf_x_size"> -->
  <!--   <link name="${name}:shelf_link"> -->
  <!--     <visual> -->
  <!--       <material name="shelf_door_green"/> -->
  <!--       <origin xyz="0 0 0" rpy="0 0 0" /> -->
  <!--       <geometry> -->
  <!--         <box size="${size_x} ${size_y} ${size_z}" /> -->
  <!--       </geometry> -->
  <!--     </visual> -->
  <!--     <collision> -->
  <!--       <origin xyz="0 0 0" rpy="0 0 0" /> -->
  <!--       <geometry> -->
  <!--         <box size="${size_x} ${size_y} ${size_z}" /> -->
  <!--       </geometry> -->
  <!--     </collision> -->
  <!--   </link> -->
  <!--   <joint name="${name}:shelf_joint" type="revolute"> -->
  <!--     <origin xyz="${shelf_x_size/-2} ${size_y/2} 0" rpy="0 0 -3.1416"/> -->
  <!--     <axis xyz="0 0 1" /> -->
  <!--     <parent link="${parent}:shelf_piece"/> -->
  <!--     <child link="${name}:shelf_link"/> -->
  <!--     <limit effort="30" velocity="1.0" lower="0.0" upper="1.91986" /> -->
  <!--   </joint> -->
  <!-- </xacro:macro> -->
  <gazebo>
    <gravity>0</gravity>
  </gazebo>
  <material name="door_green">
    <color rgba="0 0.31 0.22 1"/>
  </material>
  <material name="hinge_red">
    <color rgba="0.74 0.25 0.25 1"/>
  </material>
  <material name="handle_blue">
    <color rgba="0.3 0.5 0.78 1"/>
  </material>
  <material name="bucket_grey">
    <color rgba="0.8 0.8 0.8 1"/>
  </material>
  <material name="white">
    <color rgba="1 1 1 1"/>
  </material>
  <material name="orange">
    <color rgba="1 0.7 0 1"/>
  </material>
  <material name="handle_white">
    <color rgba="1 1 1 1"/>
  </material>
  <material name="bottom_white">
    <color rgba="1 1 1 1"/>
  </material>
  <material name="frame_wood">
    <color rgba="0.68 0.63 0.47 1"/>
  </material>
  <material name="handle_grey">
    <color rgba="0.7 0.7 0.7 1"/>
  </material>
  <material name="dishwasher_table_color">
    <color rgba="0.255 0.62 0.223 1"/>
  </material>
  <material name="color_grey">
    <color rgba="0.8 0.8 0.8 1"/>
  </material>
  <material name="color_red">
    <color rgba="1 0 0 1"/>
  </material>
  <material name="color_blue">
    <color rgba="0 0 1 1"/>
  </material>
  <material name="simple_couch_color_grey">
    <color rgba="0.8 0.8 0.8 1"/>
  </material>
  <material name="simple_couch_color_red">
    <color rgba="1 0 0 1"/>
  </material>
  <material name="simple_couch_color_blue">
    <color rgba="0 0 1 1"/>
  </material>
  <!--<material name="table_grey">
    <color rgba="0.8 0.8 0.8 1"/>
  </material>
  -->
  <material name="chair_color">
    <color rgba="0 0 0.5 1"/>
  </material>
  <!-- General conveinience links -->
  <link name="shelf_hohc:shelf_hohc:shelf_origin"/>
  <link name="shelf_hohc:shelf_hohc:shelf_center"/>
  <link name="shelf_hohc:shelf_hohc:shelf_base_center"/>
  <joint name="shelf_hohc:shelf_hohc:shelf_origin_joint" type="fixed">
    <origin rpy="0 0 1.57" xyz="3.4 3.4 0"/>
    <parent link="urdf_offset"/>
    <child link="shelf_hohc:shelf_hohc:shelf_origin"/>
  </joint>
  <joint name="shelf_hohc:shelf_hohc:shelf_center_joint" type="fixed">
    <origin rpy="0 0 0" xyz="0.2 0.4 1.01"/>
    <parent link="shelf_hohc:shelf_hohc:shelf_origin"/>
    <child link="shelf_hohc:shelf_hohc:shelf_center"/>
  </joint>
  <joint name="shelf_hohc:shelf_hohc:shelf_base_center_joint" type="fixed">
    <origin rpy="0 0 0" xyz="0.2 0.4 0.0"/>
    <parent link="shelf_hohc:shelf_hohc:shelf_origin"/>
    <child link="shelf_hohc:shelf_hohc:shelf_base_center"/>
  </joint>
  <!-- LINK -->
  <link name="shelf_hohc:shelf_hohc:shelf_back">
    <visual>
      <material name="shelf_blue"/>
      <origin rpy="0 0 0" xyz="0 0 0.0"/>
      <geometry>
        <box size="0.02 0.8 2.02"/>
      </geometry>
    </visual>
    <collision>
      <origin rpy="0 0 0" xyz="0 0 0.0"/>
      <geometry>
        <box size="0.02 0.8 2.02"/>
      </geometry>
    </collision>
    <inertial>
      <origin rpy="0 0 0" xyz="0 0 0"/>
      <mass value="1.0"/>
      <inertia ixx="0.1" ixy="0.0" ixz="0.0" iyy="0.1" iyz="0.0" izz="0.1"/>
    </inertial>
  </link>
  <!-- JOINT -->
  <joint name="shelf_hohc:shelf_hohc:shelf_back:joint" type="fixed">
    <origin rpy="0 0 0" xyz="0.4 0.4 1.01"/>
    <parent link="shelf_hohc:shelf_hohc:shelf_origin"/>
    <child link="shelf_hohc:shelf_hohc:shelf_back"/>
  </joint>
  <!-- LINK -->
  <link name="shelf_hohc:shelf_hohc:shelf_right_side">
    <visual>
      <material name="shelf_blue"/>
      <origin rpy="0 0 0" xyz="0 0 0.0"/>
      <geometry>
        <box size="0.4 0.02 2.02"/>
      </geometry>
    </visual>
    <collision>
      <origin rpy="0 0 0" xyz="0 0 0.0"/>
      <geometry>
        <box size="0.4 0.02 2.02"/>
      </geometry>
    </collision>
    <inertial>
      <origin rpy="0 0 0" xyz="0 0 0"/>
      <mass value="1.0"/>
      <inertia ixx="0.1" ixy="0.0" ixz="0.0" iyy="0.1" iyz="0.0" izz="0.1"/>
    </inertial>
  </link>
  <!-- JOINT -->
  <joint name="shelf_hohc:shelf_hohc:shelf_right_side:joint" type="fixed">
    <origin rpy="0 0 0" xyz="0.2 0.01 1.01"/>
    <parent link="shelf_hohc:shelf_hohc:shelf_origin"/>
    <child link="shelf_hohc:shelf_hohc:shelf_right_side"/>
  </joint>
  <!-- LINK -->
  <link name="shelf_hohc:shelf_hohc:shelf_left_side">
    <visual>
      <material name="shelf_blue"/>
      <origin rpy="0 0 0" xyz="0 0 0.0"/>
      <geometry>
        <box size="0.4 0.02 2.02"/>
      </geometry>
    </visual>
    <collision>
      <origin rpy="0 0 0" xyz="0 0 0.0"/>
      <geometry>
        <box size="0.4 0.02 2.02"/>
      </geometry>
    </collision>
    <inertial>
      <origin rpy="0 0 0" xyz="0 0 0"/>
      <mass value="1.0"/>
      <inertia ixx="0.1" ixy="0.0" ixz="0.0" iyy="0.1" iyz="0.0" izz="0.1"/>
    </inertial>
  </link>
  <!-- JOINT -->
  <joint name="shelf_hohc:shelf_hohc:shelf_left_side:joint" type="fixed">
    <origin rpy="0 0 0" xyz="0.2 0.79 1.01"/>
    <parent link="shelf_hohc:shelf_hohc:shelf_origin"/>
    <child link="shelf_hohc:shelf_hohc:shelf_left_side"/>
  </joint>
  <!-- LINK -->
  <link name="shelf_hohc:shelf_hohc:shelf_floor_0">
    <visual>
      <material name="shelf_blue"/>
      <origin rpy="0 0 0" xyz="0 0 -0.02"/>
      <geometry>
        <box size="0.4 0.8 0.04"/>
      </geometry>
    </visual>
    <collision>
      <origin rpy="0 0 0" xyz="0 0 -0.02"/>
      <geometry>
        <box size="0.4 0.8 0.04"/>
      </geometry>
    </collision>
    <inertial>
      <origin rpy="0 0 0" xyz="0 0 0"/>
      <mass value="1.0"/>
      <inertia ixx="0.1" ixy="0.0" ixz="0.0" iyy="0.1" iyz="0.0" izz="0.1"/>
    </inertial>
  </link>
  <!-- JOINT -->
  <joint name="shelf_hohc:shelf_hohc:shelf_floor_0:joint" type="fixed">
    <origin rpy="0 0 0" xyz="0.0 0.0 0.1"/>
    <parent link="shelf_hohc:shelf_hohc:shelf_base_center"/>
    <child link="shelf_hohc:shelf_hohc:shelf_floor_0"/>
  </joint>
  <!-- LINK -->
  <link name="shelf_hohc:shelf_hohc:shelf_floor_1">
    <visual>
      <material name="shelf_blue"/>
      <origin rpy="0 0 0" xyz="0 0 -0.02"/>
      <geometry>
        <box size="0.4 0.8 0.04"/>
      </geometry>
    </visual>
    <collision>
      <origin rpy="0 0 0" xyz="0 0 -0.02"/>
      <geometry>
        <box size="0.4 0.8 0.04"/>
      </geometry>
    </collision>
    <inertial>
      <origin rpy="0 0 0" xyz="0 0 0"/>
      <mass value="1.0"/>
      <inertia ixx="0.1" ixy="0.0" ixz="0.0" iyy="0.1" iyz="0.0" izz="0.1"/>
    </inertial>
  </link>
  <!-- JOINT -->
  <joint name="shelf_hohc:shelf_hohc:shelf_floor_1:joint" type="fixed">
    <origin rpy="0 0 0" xyz="0.0 0.0 0.54"/>
    <parent link="shelf_hohc:shelf_hohc:shelf_base_center"/>
    <child link="shelf_hohc:shelf_hohc:shelf_floor_1"/>
  </joint>
  <!-- LINK -->
  <link name="shelf_hohc:shelf_hohc:shelf_floor_2">
    <visual>
      <material name="shelf_blue"/>
      <origin rpy="0 0 0" xyz="0 0 -0.02"/>
      <geometry>
        <box size="0.4 0.8 0.04"/>
      </geometry>
    </visual>
    <collision>
      <origin rpy="0 0 0" xyz="0 0 -0.02"/>
      <geometry>
        <box size="0.4 0.8 0.04"/>
      </geometry>
    </collision>
    <inertial>
      <origin rpy="0 0 0" xyz="0 0 0"/>
      <mass value="1.0"/>
      <inertia ixx="0.1" ixy="0.0" ixz="0.0" iyy="0.1" iyz="0.0" izz="0.1"/>
    </inertial>
  </link>
  <!-- JOINT -->
  <joint name="shelf_hohc:shelf_hohc:shelf_floor_2:joint" type="fixed">
    <origin rpy="0 0 0" xyz="0.0 0.0 1.055"/>
    <parent link="shelf_hohc:shelf_hohc:shelf_base_center"/>
    <child link="shelf_hohc:shelf_hohc:shelf_floor_2"/>
  </joint>
  <!-- LINK -->
  <link name="shelf_hohc:shelf_hohc:shelf_floor_3">
    <visual>
      <material name="shelf_blue"/>
      <origin rpy="0 0 0" xyz="0 0 -0.02"/>
      <geometry>
        <box size="0.4 0.8 0.04"/>
      </geometry>
    </visual>
    <collision>
      <origin rpy="0 0 0" xyz="0 0 -0.02"/>
      <geometry>
        <box size="0.4 0.8 0.04"/>
      </geometry>
    </collision>
    <inertial>
      <origin rpy="0 0 0" xyz="0 0 0"/>
      <mass value="1.0"/>
      <inertia ixx="0.1" ixy="0.0" ixz="0.0" iyy="0.1" iyz="0.0" izz="0.1"/>
    </inertial>
  </link>
  <!-- JOINT -->
  <joint name="shelf_hohc:shelf_hohc:shelf_floor_3:joint" type="fixed">
    <origin rpy="0 0 0" xyz="0.0 0.0 2.02"/>
    <parent link="shelf_hohc:shelf_hohc:shelf_base_center"/>
    <child link="shelf_hohc:shelf_hohc:shelf_floor_3"/>
  </joint>
  <link name="shelf_hohc:shelf_hohc:shelf_door_right">
    <visual>
      <material name="shelf_door_green"/>
      <origin rpy="0 0 0" xyz="0 0.18 0"/>
      <geometry>
        <box size="0.02 0.38 0.97"/>
      </geometry>
    </visual>
    <collision>
      <origin rpy="0 0 0" xyz="0 0.18 0"/>
      <geometry>
        <box size="0.02 0.38 0.97"/>
      </geometry>
    </collision>
    <inertial>
      <origin rpy="0 0 0" xyz="0 0 0"/>
      <mass value="1.0"/>
      <inertia ixx="0.1" ixy="0.0" ixz="0.0" iyy="0.1" iyz="0.0" izz="0.1"/>
    </inertial>
  </link>
  <link name="shelf_hohc:shelf_hohc:shelf_door_right:handle">
    <visual>
      <material name="shelf_hohc_handle_red"/>
      <origin rpy="0 0 0" xyz="0 0 0"/>
      <geometry>
        <box size="0.02 0.015 0.015"/>
      </geometry>
    </visual>
    <collision>
      <origin rpy="0 0 0" xyz="0 0 0"/>
      <geometry>
        <box size="0.02 0.015 0.015"/>
      </geometry>
    </collision>
    <inertial>
      <origin rpy="0 0 0" xyz="0 0 0"/>
      <mass value="1.0"/>
      <inertia ixx="0.1" ixy="0.0" ixz="0.0" iyy="0.1" iyz="0.0" izz="0.1"/>
    </inertial>
  </link>
  <joint name="shelf_hohc:shelf_hohc:shelf_door_right:handle_joint" type="fixed">
    <origin rpy="0 0 0" xyz="-0.03 0.3575 0.09249999999999997"/>
    <axis xyz="0 0 1"/>
    <parent link="shelf_hohc:shelf_hohc:shelf_door_right"/>
    <child link="shelf_hohc:shelf_hohc:shelf_door_right:handle"/>
  </joint>
  <joint name="shelf_hohc:shelf_hohc:shelf_door_right:joint" type="revolute">
    <origin rpy="0 0 0" xyz="-0.19 0.02 -0.48"/>
    <axis xyz="0 0 1"/>
    <parent link="shelf_hohc:shelf_hohc:shelf_right_side"/>
    <child link="shelf_hohc:shelf_hohc:shelf_door_right"/>
    <limit effort="30" lower="0.0" upper="1.7" velocity="1.0"/>
  </joint>
  <link name="shelf_hohc:shelf_hohc:shelf_door_left">
    <visual>
      <material name="shelf_door_green"/>
      <origin rpy="0 0 0" xyz="0 -0.18 0"/>
      <geometry>
        <box size="0.02 0.38 0.97"/>
      </geometry>
    </visual>
    <collision>
      <origin rpy="0 0 0" xyz="0 -0.18 0"/>
      <geometry>
        <box size="0.02 0.38 0.97"/>
      </geometry>
    </collision>
    <inertial>
      <origin rpy="0 0 0" xyz="0 0 0"/>
      <mass value="1.0"/>
      <inertia ixx="0.1" ixy="0.0" ixz="0.0" iyy="0.1" iyz="0.0" izz="0.1"/>
    </inertial>
  </link>
  <link name="shelf_hohc:shelf_hohc:shelf_door_left:handle">
    <visual>
      <material name="shelf_hohc_handle_red"/>
      <origin rpy="0 0 0" xyz="0 0 0"/>
      <geometry>
        <box size="0.02 0.015 0.015"/>
      </geometry>
    </visual>
    <collision>
      <origin rpy="0 0 0" xyz="0 0 0"/>
      <geometry>
        <box size="0.02 0.015 0.015"/>
      </geometry>
    </collision>
    <inertial>
      <origin rpy="0 0 0" xyz="0 0 0"/>
      <mass value="1.0"/>
      <inertia ixx="0.1" ixy="0.0" ixz="0.0" iyy="0.1" iyz="0.0" izz="0.1"/>
    </inertial>
  </link>
  <joint name="shelf_hohc:shelf_hohc:shelf_door_left:handle_joint" type="fixed">
    <origin rpy="0 0 0" xyz="-0.03 -0.3575 0.09249999999999997"/>
    <axis xyz="0 0 1"/>
    <parent link="shelf_hohc:shelf_hohc:shelf_door_left"/>
    <child link="shelf_hohc:shelf_hohc:shelf_door_left:handle"/>
  </joint>
  <joint name="shelf_hohc:shelf_hohc:shelf_door_left:joint" type="revolute">
    <origin rpy="0 0 0" xyz="-0.19 -0.02 -0.48"/>
    <axis xyz="0 0 1"/>
    <parent link="shelf_hohc:shelf_hohc:shelf_left_side"/>
    <child link="shelf_hohc:shelf_hohc:shelf_door_left"/>
    <limit effort="30" lower="-1.7" upper="0.0" velocity="1.0"/>
  </joint>
  <link name="urdf_main"/>
  <joint name="map_urdf_joint" type="fixed">
    <origin rpy="0 0 0.0" xyz="0 0 0 "/>
    <parent link="urdf_main"/>
    <child link="urdf_offset"/>
  </joint>
  <link name="urdf_offset"/>
</robot>
