<sdf version='1.6'>
  <world name='default'>
    <physics name='default_physics' default='0' type='ode'>
      <max_step_size>0.001</max_step_size>
      <real_time_factor>1</real_time_factor>
      <real_time_update_rate>1000</real_time_update_rate>
    </physics>
    <light name='sun' type='directional'>
      <cast_shadows>1</cast_shadows>
      <pose frame=''>0 0 10 0 -0 0</pose>
      <diffuse>0.8 0.8 0.8 1</diffuse>
      <specular>0.1 0.1 0.1 1</specular>
      <attenuation>
        <range>1000</range>
        <constant>0.9</constant>
        <linear>0.01</linear>
        <quadratic>0.001</quadratic>
      </attenuation>
      <direction>-0.5 0.5 -1</direction>
    </light>
    <model name='ground_plane'>
      <static>1</static>
      <link name='link'>
        <collision name='collision'>
          <geometry>
            <plane>
              <normal>0 0 1</normal>
              <size>100 100</size>
            </plane>
          </geometry>
          <surface>
            <friction>
              <ode>
                <mu>100</mu>
                <mu2>50</mu2>
              </ode>
              <torsional>
                <ode/>
              </torsional>
            </friction>
            <contact>
              <ode/>
            </contact>
            <bounce/>
          </surface>
          <max_contacts>10</max_contacts>
        </collision>
        <visual name='visual'>
          <cast_shadows>0</cast_shadows>
          <geometry>
            <plane>
              <normal>0 0 1</normal>
              <size>100 100</size>
            </plane>
          </geometry>
          <material>
            <script>
              <uri>file://media/materials/scripts/gazebo.material</uri>
              <name>Gazebo/Grey</name>
            </script>
          </material>
        </visual>
        <self_collide>0</self_collide>
        <kinematic>0</kinematic>
        <gravity>1</gravity>
      </link>
    </model>
    <gravity>0 0 -9.8</gravity>
    <magnetic_field>6e-06 2.3e-05 -4.2e-05</magnetic_field>
    <atmosphere type='adiabatic'/>
    <scene>
      <ambient>0.4 0.4 0.4 1</ambient>
      <background>0.7 0.7 0.7 1</background>
      <shadows>1</shadows>
    </scene>
    <spherical_coordinates>
      <surface_model>EARTH_WGS84</surface_model>
      <latitude_deg>0</latitude_deg>
      <longitude_deg>0</longitude_deg>
      <elevation>0</elevation>
      <heading_deg>0</heading_deg>
    </spherical_coordinates>
    <model name='hsrb'>
      <link name='base_footprint'>
        <pose frame=''>0 0 0 0 -0 0</pose>
        <inertial>
          <pose frame=''>-0.025934 -0.00547 0.176333 0 -0 0</pose>
          <mass>50.02</mass>
          <inertia>
            <ixx>0.376384</ixx>
            <ixy>0.000387825</ixy>
            <ixz>0.0308632</ixz>
            <iyy>0.345982</iyy>
            <iyz>0.0177433</iyz>
            <izz>0.153464</izz>
          </inertia>
        </inertial>
        <collision name='base_footprint_fixed_joint_lump__base_link_collision'>
          <pose frame=''>0 0 0 0 -0 0</pose>
          <geometry>
            <mesh>
              <scale>1 1 1</scale>
              <uri>/opt/ros/kinetic/share/hsrb_description/meshes/base_v2/base.stl</uri>
            </mesh>
          </geometry>
          <surface>
            <contact>
              <ode/>
            </contact>
            <friction>
              <ode>
                <mu>0.9</mu>
                <mu2>0.9</mu2>
              </ode>
              <torsional>
                <ode/>
              </torsional>
            </friction>
            <bounce/>
          </surface>
          <max_contacts>10</max_contacts>
        </collision>
        <collision name='base_footprint_fixed_joint_lump__base_range_sensor_link_collision_1'>
          <pose frame=''>0.1675 0 0.1844 0 -0 0</pose>
          <geometry>
            <mesh>
              <scale>1 1 1</scale>
              <uri>/opt/ros/kinetic/share/hsrb_parts_description/meshes/sensors/laser.stl</uri>
            </mesh>
          </geometry>
          <surface>
            <contact>
              <ode/>
            </contact>
            <friction>
              <ode>
                <mu>0.9</mu>
                <mu2>0.9</mu2>
              </ode>
              <torsional>
                <ode/>
              </torsional>
            </friction>
            <bounce/>
          </surface>
          <max_contacts>10</max_contacts>
        </collision>
        <visual name='base_footprint_fixed_joint_lump__base_link_visual'>
          <pose frame=''>0 0 0 0 -0 0</pose>
          <geometry>
            <mesh>
              <scale>1 1 1</scale>
              <uri>/opt/ros/kinetic/share/hsrb_description/meshes/base_v2/base_light.dae</uri>
            </mesh>
          </geometry>
          <material>
            <script>
              <uri>__default__</uri>
              <name>__default__</name>
            </script>
          </material>
        </visual>
        <visual name='base_footprint_fixed_joint_lump__base_link_visual_1'>
          <pose frame=''>0 0 0 0 -0 0</pose>
          <geometry>
            <mesh>
              <scale>1 1 1</scale>
              <uri>/opt/ros/kinetic/share/hsrb_description/meshes/base_v2/body_light.dae</uri>
            </mesh>
          </geometry>
          <material>
            <script>
              <uri>__default__</uri>
              <name>__default__</name>
            </script>
          </material>
        </visual>
        <visual name='base_footprint_fixed_joint_lump__base_link_visual_2'>
          <pose frame=''>0 0 0 0 -0 0</pose>
          <geometry>
            <mesh>
              <scale>1 1 1</scale>
              <uri>/opt/ros/kinetic/share/hsrb_description/meshes/base_v2/torso_base.dae</uri>
            </mesh>
          </geometry>
          <material>
            <script>
              <uri>__default__</uri>
              <name>__default__</name>
            </script>
          </material>
        </visual>
        <visual name='base_footprint_fixed_joint_lump__base_range_sensor_link_visual_3'>
          <pose frame=''>0.1675 0 0.1844 0 -0 0</pose>
          <geometry>
            <mesh>
              <scale>1 1 1</scale>
              <uri>/opt/ros/kinetic/share/hsrb_parts_description/meshes/sensors/laser.dae</uri>
            </mesh>
          </geometry>
          <material>
            <script>
              <uri>__default__</uri>
              <name>__default__</name>
            </script>
          </material>
        </visual>
        <velocity_decay/>
        <velocity_decay/>
        <sensor name='base_imu' type='imu'>
          <update_rate>10</update_rate>
          <plugin name='base_imu_plugin' filename='libgazebo_ros_imu_sensor.so'>
            <updateRateHZ>50.0</updateRateHZ>
            <bodyName>base_link</bodyName>
            <topicName>hsrb/base_imu/data</topicName>
            <frameName>base_imu_frame</frameName>
            <gaussianNoise>0.0</gaussianNoise>
            <xyzOffset>0.0 0.0 0.0</xyzOffset>
            <rpyOffset>0.0 -0.0 0.0</rpyOffset>
            <robotNamespace>/</robotNamespace>
          </plugin>
          <imu>
            <angular_velocity>
              <x>
                <noise type='gaussian'>
                  <mean>0</mean>
                  <stddev>0.0002</stddev>
                  <bias_mean>7.5e-06</bias_mean>
                  <bias_stddev>8e-07</bias_stddev>
                </noise>
              </x>
              <y>
                <noise type='gaussian'>
                  <mean>0</mean>
                  <stddev>0.0002</stddev>
                  <bias_mean>7.5e-06</bias_mean>
                  <bias_stddev>8e-07</bias_stddev>
                </noise>
              </y>
              <z>
                <noise type='gaussian'>
                  <mean>0</mean>
                  <stddev>0.0002</stddev>
                  <bias_mean>7.5e-06</bias_mean>
                  <bias_stddev>8e-07</bias_stddev>
                </noise>
              </z>
            </angular_velocity>
            <linear_acceleration>
              <x>
                <noise type='gaussian'>
                  <mean>0</mean>
                  <stddev>0.017</stddev>
                  <bias_mean>0.1</bias_mean>
                  <bias_stddev>0.001</bias_stddev>
                </noise>
              </x>
              <y>
                <noise type='gaussian'>
                  <mean>0</mean>
                  <stddev>0.017</stddev>
                  <bias_mean>0.1</bias_mean>
                  <bias_stddev>0.001</bias_stddev>
                </noise>
              </y>
              <z>
                <noise type='gaussian'>
                  <mean>0</mean>
                  <stddev>0.017</stddev>
                  <bias_mean>0.1</bias_mean>
                  <bias_stddev>0.001</bias_stddev>
                </noise>
              </z>
            </linear_acceleration>
          </imu>
          <pose frame=''>0.0005 0.1296 0.181 0 -0 0</pose>
        </sensor>
        <velocity_decay/>
        <gravity>1</gravity>
        <gravity>1</gravity>
        <velocity_decay/>
        <sensor name='base_range_sensor' type='ray'>
          <update_rate>30</update_rate>
          <visualize>0</visualize>
          <ray>
            <scan>
              <horizontal>
                <samples>721</samples>
                <resolution>1</resolution>
                <min_angle>-2.1</min_angle>
                <max_angle>2.1</max_angle>
              </horizontal>
              <vertical>
                <samples>1</samples>
                <min_angle>0</min_angle>
                <max_angle>0</max_angle>
              </vertical>
            </scan>
            <range>
              <min>0.05</min>
              <max>60</max>
              <resolution>0.001</resolution>
            </range>
          </ray>
          <plugin name='hokuyo_laser' filename='libgazebo_ros_laser.so'>
            <topicName>hsrb/base_scan</topicName>
            <frameName>base_range_sensor_link</frameName>
            <robotNamespace>/</robotNamespace>
          </plugin>
          <pose frame=''>0.1675 0 0.1844 0 -0 0</pose>
        </sensor>
        <gravity>1</gravity>
        <velocity_decay/>
        <self_collide>0</self_collide>
        <gravity>1</gravity>
        <kinematic>0</kinematic>
      </link>
      <link name='arm_lift_link'>
        <pose frame=''>0 0 0.34 0 -0 0</pose>
        <inertial>
          <pose frame=''>0.051549 0.042438 -0.064145 0 -0 0</pose>
          <mass>1.27582</mass>
          <inertia>
            <ixx>0.004633</ixx>
            <ixy>0.000475273</ixy>
            <ixz>-0.002403</ixz>
            <iyy>0.008065</iyy>
            <iyz>-0.000100269</iyz>
            <izz>0.007672</izz>
          </inertia>
        </inertial>
        <collision name='arm_lift_link_collision'>
          <pose frame=''>0 0 0 0 -0 0</pose>
          <geometry>
            <mesh>
              <scale>1 1 1</scale>
              <uri>/opt/ros/kinetic/share/hsrb_description/meshes/arm_v0/shoulder.stl</uri>
            </mesh>
          </geometry>
          <surface>
            <contact>
              <ode/>
            </contact>
            <friction>
              <ode>
                <mu>0.9</mu>
                <mu2>0.9</mu2>
              </ode>
              <torsional>
                <ode/>
              </torsional>
            </friction>
            <bounce/>
          </surface>
          <max_contacts>10</max_contacts>
        </collision>
        <visual name='arm_lift_link_visual'>
          <pose frame=''>0 0 0 0 -0 0</pose>
          <geometry>
            <mesh>
              <scale>1 1 1</scale>
              <uri>/opt/ros/kinetic/share/hsrb_description/meshes/arm_v0/shoulder.dae</uri>
            </mesh>
          </geometry>
          <material>
            <script>
              <uri>__default__</uri>
              <name>__default__</name>
            </script>
          </material>
        </visual>
        <gravity>1</gravity>
        <velocity_decay/>
        <self_collide>0</self_collide>
        <gravity>1</gravity>
        <kinematic>0</kinematic>
      </link>
      <joint name='arm_lift_joint' type='prismatic'>
        <child>arm_lift_link</child>
        <parent>base_footprint</parent>
        <axis>
          <xyz>0 0 1</xyz>
          <limit>
            <lower>0</lower>
            <upper>0.69</upper>
            <effort>300</effort>
            <velocity>0.2</velocity>
          </limit>
          <dynamics>
            <damping>1</damping>
            <friction>0</friction>
            <spring_reference>0</spring_reference>
            <spring_stiffness>0</spring_stiffness>
          </dynamics>
          <use_parent_model_frame>1</use_parent_model_frame>
        </axis>
        <physics>
          <ode>
            <limit>
              <cfm>0</cfm>
              <erp>0.2</erp>
            </limit>
          </ode>
        </physics>
      </joint>
      <link name='arm_flex_link'>
        <pose frame=''>0.141 0.078 0.34 0 -0 0</pose>
        <inertial>
          <pose frame=''>0.000632 0.006404 0.118529 0 -0 0</pose>
          <mass>1.33929</mass>
          <inertia>
            <ixx>7.528</ixx>
            <ixy>-2.02842e-05</ixy>
            <ixz>-2.29472e-05</ixz>
            <iyy>0.007102</iyy>
            <iyz>-9.17961e-05</iyz>
            <izz>0.001552</izz>
          </inertia>
        </inertial>
        <collision name='arm_flex_link_collision'>
          <pose frame=''>0 0 0 0 -0 0</pose>
          <geometry>
            <mesh>
              <scale>1 1 1</scale>
              <uri>/opt/ros/kinetic/share/hsrb_description/meshes/arm_v0/arm_flex.stl</uri>
            </mesh>
          </geometry>
          <surface>
            <contact>
              <ode/>
            </contact>
            <friction>
              <ode>
                <mu>0.9</mu>
                <mu2>0.9</mu2>
              </ode>
              <torsional>
                <ode/>
              </torsional>
            </friction>
            <bounce/>
          </surface>
          <max_contacts>10</max_contacts>
        </collision>
        <visual name='arm_flex_link_visual'>
          <pose frame=''>0 0 0 0 -0 0</pose>
          <geometry>
            <mesh>
              <scale>1 1 1</scale>
              <uri>/opt/ros/kinetic/share/hsrb_description/meshes/arm_v0/arm_flex_light.dae</uri>
            </mesh>
          </geometry>
          <material>
            <script>
              <uri>__default__</uri>
              <name>__default__</name>
            </script>
          </material>
        </visual>
        <gravity>1</gravity>
        <velocity_decay/>
        <self_collide>0</self_collide>
        <gravity>1</gravity>
        <kinematic>0</kinematic>
      </link>
      <joint name='arm_flex_joint' type='revolute'>
        <child>arm_flex_link</child>
        <parent>arm_lift_link</parent>
        <axis>
          <xyz>0 -1 0</xyz>
          <limit>
            <lower>-2.62</lower>
            <upper>0</upper>
            <effort>100</effort>
            <velocity>1.2</velocity>
          </limit>
          <dynamics>
            <damping>1</damping>
            <friction>0</friction>
            <spring_reference>0</spring_reference>
            <spring_stiffness>0</spring_stiffness>
          </dynamics>
          <use_parent_model_frame>1</use_parent_model_frame>
        </axis>
        <physics>
          <ode>
            <limit>
              <cfm>0</cfm>
              <erp>0.2</erp>
            </limit>
          </ode>
        </physics>
      </joint>
      <link name='arm_roll_link'>
        <pose frame=''>0.146 0.078 0.685 0 -0 0</pose>
        <inertial>
          <pose frame=''>-0.006927 0.002039 -0.064837 0 -0 0</pose>
          <mass>0.247936</mass>
          <inertia>
            <ixx>0.004267</ixx>
            <ixy>-1.83222e-05</ixy>
            <ixz>1.79845e-05</ixz>
            <iyy>0.000780924</iyy>
            <iyz>-1.39233e-05</iyz>
            <izz>0.00412</izz>
          </inertia>
        </inertial>
        <collision name='arm_roll_link_collision'>
          <pose frame=''>0 0 0 0 -0 0</pose>
          <geometry>
            <mesh>
              <scale>1 1 1</scale>
              <uri>/opt/ros/kinetic/share/hsrb_description/meshes/arm_v0/arm_roll.stl</uri>
            </mesh>
          </geometry>
          <surface>
            <contact>
              <ode/>
            </contact>
            <friction>
              <ode>
                <mu>0.9</mu>
                <mu2>0.9</mu2>
              </ode>
              <torsional>
                <ode/>
              </torsional>
            </friction>
            <bounce/>
          </surface>
          <max_contacts>10</max_contacts>
        </collision>
        <visual name='arm_roll_link_visual'>
          <pose frame=''>0 0 0 0 -0 0</pose>
          <geometry>
            <mesh>
              <scale>1 1 1</scale>
              <uri>/opt/ros/kinetic/share/hsrb_description/meshes/arm_v0/arm_roll_light.dae</uri>
            </mesh>
          </geometry>
          <material>
            <script>
              <uri>__default__</uri>
              <name>__default__</name>
            </script>
          </material>
        </visual>
        <gravity>1</gravity>
        <velocity_decay/>
        <self_collide>0</self_collide>
        <gravity>1</gravity>
        <kinematic>0</kinematic>
      </link>
      <joint name='arm_roll_joint' type='revolute'>
        <child>arm_roll_link</child>
        <parent>arm_flex_link</parent>
        <axis>
          <xyz>0 0 1</xyz>
          <limit>
            <lower>-2.09</lower>
            <upper>3.84</upper>
            <effort>100</effort>
            <velocity>2</velocity>
          </limit>
          <dynamics>
            <damping>0.1</damping>
            <friction>0</friction>
            <spring_reference>0</spring_reference>
            <spring_stiffness>0</spring_stiffness>
          </dynamics>
          <use_parent_model_frame>1</use_parent_model_frame>
        </axis>
        <physics>
          <ode>
            <limit>
              <cfm>0</cfm>
              <erp>0.2</erp>
            </limit>
          </ode>
        </physics>
      </joint>
      <link name='wrist_flex_link'>
        <pose frame=''>0.146 0.078 0.685 0 -0 0</pose>
        <inertial>
          <pose frame=''>0.000131 -0.003929 0.00217 0 -0 0</pose>
          <mass>0.681225</mass>
          <inertia>
            <ixx>7.43536e-05</ixx>
            <ixy>4.94515e-07</ixy>
            <ixz>2.2937e-08</ixz>
            <iyy>3.84329e-05</iyy>
            <iyz>-2.55576e-06</iyz>
            <izz>6.46809e-05</izz>
          </inertia>
        </inertial>
        <collision name='wrist_flex_link_collision'>
          <pose frame=''>0 0 0.03 0 -0 0</pose>
          <geometry>
            <cylinder>
              <length>0.04</length>
              <radius>0.017</radius>
            </cylinder>
          </geometry>
          <surface>
            <contact>
              <ode/>
            </contact>
            <friction>
              <ode>
                <mu>0.9</mu>
                <mu2>0.9</mu2>
              </ode>
              <torsional>
                <ode/>
              </torsional>
            </friction>
            <bounce/>
          </surface>
          <max_contacts>10</max_contacts>
        </collision>
        <visual name='wrist_flex_link_visual'>
          <pose frame=''>0 0 0 0 -0 0</pose>
          <geometry>
            <mesh>
              <scale>1 1 1</scale>
              <uri>/opt/ros/kinetic/share/hsrb_description/meshes/wrist_v0/wrist_flex.dae</uri>
            </mesh>
          </geometry>
          <material>
            <script>
              <uri>__default__</uri>
              <name>__default__</name>
            </script>
          </material>
        </visual>
        <visual name='wrist_flex_link_visual_1'>
          <pose frame=''>0 0 0.04 0 -0 0</pose>
          <geometry>
            <cylinder>
              <length>0.02</length>
              <radius>0.017</radius>
            </cylinder>
          </geometry>
          <material>
            <script>
              <uri>__default__</uri>
              <name>__default__</name>
            </script>
          </material>
        </visual>
        <gravity>1</gravity>
        <velocity_decay/>
        <self_collide>0</self_collide>
        <gravity>1</gravity>
        <kinematic>0</kinematic>
      </link>
      <joint name='wrist_flex_joint' type='revolute'>
        <child>wrist_flex_link</child>
        <parent>arm_roll_link</parent>
        <axis>
          <xyz>0 -1 0</xyz>
          <limit>
            <lower>-1.92</lower>
            <upper>1.22</upper>
            <effort>100</effort>
            <velocity>1.5</velocity>
          </limit>
          <dynamics>
            <damping>1</damping>
            <friction>0</friction>
            <spring_reference>0</spring_reference>
            <spring_stiffness>0</spring_stiffness>
          </dynamics>
          <use_parent_model_frame>1</use_parent_model_frame>
        </axis>
        <physics>
          <ode>
            <limit>
              <cfm>0</cfm>
              <erp>0.2</erp>
            </limit>
          </ode>
        </physics>
      </joint>
      <link name='wrist_ft_sensor_mount_link'>
        <pose frame=''>0.146 0.078 0.685 0 -0 0</pose>
        <inertial>
          <pose frame=''>0 0 0 0 -0 0</pose>
          <mass>0.01</mass>
          <inertia>
            <ixx>0.001</ixx>
            <ixy>0</ixy>
            <ixz>0</ixz>
            <iyy>0.001</iyy>
            <iyz>0</iyz>
            <izz>0.001</izz>
          </inertia>
        </inertial>
        <self_collide>0</self_collide>
        <kinematic>0</kinematic>
        <gravity>1</gravity>
      </link>
      <joint name='wrist_roll_joint' type='revolute'>
        <child>wrist_ft_sensor_mount_link</child>
        <parent>wrist_flex_link</parent>
        <axis>
          <xyz>0 0 1</xyz>
          <limit>
            <lower>-1.92</lower>
            <upper>3.67</upper>
            <effort>100</effort>
            <velocity>1.5</velocity>
          </limit>
          <dynamics>
            <damping>1</damping>
            <friction>0</friction>
            <spring_reference>0</spring_reference>
            <spring_stiffness>0</spring_stiffness>
          </dynamics>
          <use_parent_model_frame>1</use_parent_model_frame>
        </axis>
        <physics>
          <ode>
            <limit>
              <cfm>0</cfm>
              <erp>0.2</erp>
            </limit>
          </ode>
        </physics>
      </joint>
      <link name='wrist_ft_sensor_frame'>
        <pose frame=''>0.146 0.078 0.7585 -3.14159 -0 0</pose>
        <inertial>
          <pose frame=''>0.000193 0.001251 -0.018623 0 -0 0</pose>
          <mass>0.941692</mass>
          <inertia>
            <ixx>0.0192819</ixx>
            <ixy>1.63273e-05</ixy>
            <ixz>4.64339e-05</ixz>
            <iyy>0.0192817</iyy>
            <iyz>1.0165e-05</iyz>
            <izz>0.0184914</izz>
          </inertia>
        </inertial>
        <collision name='wrist_ft_sensor_frame_fixed_joint_lump__wrist_roll_link_collision'>
          <pose frame=''>0 0 0.0735 3.14159 -0 0</pose>
          <geometry>
            <mesh>
              <scale>1 1 1</scale>
              <uri>/opt/ros/kinetic/share/hsrb_description/meshes/wrist_v0/wrist_roll.stl</uri>
            </mesh>
          </geometry>
          <surface>
            <contact>
              <ode/>
            </contact>
            <friction>
              <ode>
                <mu>0.9</mu>
                <mu2>0.9</mu2>
              </ode>
              <torsional>
                <ode/>
              </torsional>
            </friction>
            <bounce/>
          </surface>
          <max_contacts>10</max_contacts>
        </collision>
        <collision name='wrist_ft_sensor_frame_fixed_joint_lump__hand_palm_link_collision_1'>
          <pose frame=''>0.012 -0 -0.067 -3.14159 -0 3.14159</pose>
          <geometry>
            <mesh>
              <scale>1 1 1</scale>
              <uri>/opt/ros/kinetic/share/hsrb_description/meshes/hand_v0/palm.stl</uri>
            </mesh>
          </geometry>
          <surface>
            <contact>
              <ode/>
            </contact>
            <friction>
              <ode>
                <mu>0.9</mu>
                <mu2>0.9</mu2>
              </ode>
              <torsional>
                <ode/>
              </torsional>
            </friction>
            <bounce/>
          </surface>
          <max_contacts>10</max_contacts>
        </collision>
        <visual name='wrist_ft_sensor_frame_fixed_joint_lump__wrist_roll_link_visual'>
          <pose frame=''>0 0 0.0735 3.14159 -0 0</pose>
          <geometry>
            <mesh>
              <scale>1 1 1</scale>
              <uri>/opt/ros/kinetic/share/hsrb_description/meshes/wrist_v0/wrist_roll.dae</uri>
            </mesh>
          </geometry>
          <material>
            <script>
              <uri>__default__</uri>
              <name>__default__</name>
            </script>
          </material>
        </visual>
        <visual name='wrist_ft_sensor_frame_fixed_joint_lump__hand_palm_link_visual_1'>
          <pose frame=''>0.012 -0 -0.067 -3.14159 -0 3.14159</pose>
          <geometry>
            <mesh>
              <scale>1 1 1</scale>
              <uri>/opt/ros/kinetic/share/hsrb_description/meshes/hand_v0/palm_light.dae</uri>
            </mesh>
          </geometry>
          <material>
            <script>
              <uri>__default__</uri>
              <name>__default__</name>
            </script>
          </material>
        </visual>
        <velocity_decay/>
        <velocity_decay/>
        <gravity>1</gravity>
        <velocity_decay/>
        <gravity>1</gravity>
        <gravity>1</gravity>
        <velocity_decay/>
        <gravity>0</gravity>
        <gravity>1</gravity>
        <velocity_decay/>
        <self_collide>0</self_collide>
        <sensor name='hand_camera' type='camera'>
          <update_rate>10</update_rate>
          <camera name='hand_camera'>
            <horizontal_fov>2</horizontal_fov>
            <image>
              <width>640</width>
              <height>480</height>
              <format>R8G8B8</format>
            </image>
            <clip>
              <near>0.01</near>
              <far>100</far>
            </clip>
            <noise>
              <type>gaussian</type>
              <mean>0</mean>
              <stddev>0.007</stddev>
            </noise>
          </camera>
          <plugin name='camera_controller' filename='libhsrb_gazebo_ros_camera.so'>
            <robotNamespace>hsrb</robotNamespace>
            <alwaysOn>0</alwaysOn>
            <updateRate>0.0</updateRate>
            <cameraName>hand_camera</cameraName>
            <imageTopicName>image_raw</imageTopicName>
            <cameraInfoTopicName>camera_info</cameraInfoTopicName>
            <frameName>hand_camera_frame</frameName>
            <hackBaseline>0.07</hackBaseline>
            <distortionK1>0.0</distortionK1>
            <distortionK2>0.0</distortionK2>
            <distortionK3>0.0</distortionK3>
            <distortionT1>0.0</distortionT1>
            <distortionT2>0.0</distortionT2>
          </plugin>
          <pose frame=''>-0.027 -0 -0.0625 -3.14159 1.57079 1.57079</pose>
        </sensor>
        <kinematic>0</kinematic>
      </link>
      <joint name='wrist_ft_sensor_frame_joint' type='revolute'>
        <child>wrist_ft_sensor_frame</child>
        <parent>wrist_ft_sensor_mount_link</parent>
        <axis>
          <xyz>1 0 0</xyz>
          <limit>
            <lower>0</lower>
            <upper>0</upper>
            <effort>100</effort>
            <velocity>1.5</velocity>
          </limit>
          <dynamics>
            <spring_reference>0</spring_reference>
            <spring_stiffness>0</spring_stiffness>
          </dynamics>
          <use_parent_model_frame>1</use_parent_model_frame>
        </axis>
        <physics>
          <provide_feedback>1</provide_feedback>
          <ode>
            <provide_feedback>1</provide_feedback>
            <limit>
              <cfm>0</cfm>
              <erp>0.2</erp>
            </limit>
          </ode>
        </physics>
      </joint>
      <link name='hand_l_proximal_link'>
        <pose frame=''>0.17475 0.1025 0.808 0 -0 -3.14159</pose>
        <inertial>
          <pose frame=''>0 0 0 0 -0 0</pose>
          <mass>0.01</mass>
          <inertia>
            <ixx>0.0015</ixx>
            <ixy>0</ixy>
            <ixz>0</ixz>
            <iyy>0.0015</iyy>
            <iyz>0</iyz>
            <izz>0.0015</izz>
          </inertia>
        </inertial>
        <gravity>1</gravity>
        <velocity_decay/>
        <self_collide>0</self_collide>
        <gravity>1</gravity>
        <kinematic>0</kinematic>
      </link>
      <joint name='hand_l_proximal_joint' type='revolute'>
        <child>hand_l_proximal_link</child>
        <parent>wrist_ft_sensor_frame</parent>
        <axis>
          <xyz>-1 0 0</xyz>
          <limit>
            <lower>-0.798</lower>
            <upper>1.24</upper>
            <effort>100</effort>
            <velocity>1</velocity>
          </limit>
          <dynamics>
            <damping>0.0001</damping>
            <friction>0</friction>
            <spring_reference>0</spring_reference>
            <spring_stiffness>0</spring_stiffness>
          </dynamics>
          <use_parent_model_frame>1</use_parent_model_frame>
        </axis>
        <physics>
          <ode>
            <limit>
              <cfm>0</cfm>
              <erp>0.2</erp>
            </limit>
          </ode>
        </physics>
      </joint>
      <link name='hand_l_spring_proximal_link'>
        <pose frame=''>0.17475 0.1025 0.808 0 -0 -3.14159</pose>
        <inertial>
          <pose frame=''>0.021418 0.00248 0.022688 0 -0 0</pose>
          <mass>0.043589</mass>
          <inertia>
            <ixx>2.60339e-05</ixx>
            <ixy>-1.44078e-07</ixy>
            <ixz>-1.98241e-06</ixz>
            <iyy>2.88248e-05</iyy>
            <iyz>-1.26842e-06</iyz>
            <izz>5.13592e-06</izz>
          </inertia>
        </inertial>
        <collision name='hand_l_spring_proximal_link_collision'>
          <pose frame=''>0 0 0 0 -0 0</pose>
          <geometry>
            <mesh>
              <scale>1 1 1</scale>
              <uri>/opt/ros/kinetic/share/hsrb_description/meshes/hand_v0/l_proximal.stl</uri>
            </mesh>
          </geometry>
          <surface>
            <contact>
              <ode/>
            </contact>
            <friction>
              <ode>
                <mu>1</mu>
                <mu2>1</mu2>
              </ode>
              <torsional>
                <ode/>
              </torsional>
            </friction>
            <bounce/>
          </surface>
          <max_contacts>10</max_contacts>
        </collision>
        <visual name='hand_l_spring_proximal_link_visual'>
          <pose frame=''>0 0 0 0 -0 0</pose>
          <geometry>
            <mesh>
              <scale>1 1 1</scale>
              <uri>/opt/ros/kinetic/share/hsrb_description/meshes/hand_v0/l_proximal.dae</uri>
            </mesh>
          </geometry>
          <material>
            <script>
              <uri>__default__</uri>
              <name>__default__</name>
            </script>
          </material>
        </visual>
        <gravity>1</gravity>
        <velocity_decay/>
        <self_collide>0</self_collide>
        <gravity>1</gravity>
        <kinematic>0</kinematic>
      </link>
      <joint name='hand_l_spring_proximal_joint' type='revolute'>
        <child>hand_l_spring_proximal_link</child>
        <parent>hand_l_proximal_link</parent>
        <axis>
          <xyz>-1 0 0</xyz>
          <limit>
            <lower>0</lower>
            <upper>0.698</upper>
            <effort>10</effort>
            <velocity>1</velocity>
          </limit>
          <dynamics>
            <damping>0.0001</damping>
            <friction>0</friction>
            <spring_reference>0</spring_reference>
            <spring_stiffness>0</spring_stiffness>
          </dynamics>
          <use_parent_model_frame>1</use_parent_model_frame>
        </axis>
        <physics>
          <ode>
            <limit>
              <cfm>0</cfm>
              <erp>0.2</erp>
            </limit>
          </ode>
        </physics>
      </joint>
      <link name='hand_l_mimic_distal_link'>
        <pose frame=''>0.17475 0.1025 0.878 0 -0 -3.14159</pose>
        <inertial>
          <pose frame=''>0 0 0 0 -0 0</pose>
          <mass>0.01</mass>
          <inertia>
            <ixx>0.0015</ixx>
            <ixy>0</ixy>
            <ixz>0</ixz>
            <iyy>0.0015</iyy>
            <iyz>0</iyz>
            <izz>0.0015</izz>
          </inertia>
        </inertial>
        <gravity>1</gravity>
        <velocity_decay/>
        <self_collide>0</self_collide>
        <gravity>1</gravity>
        <kinematic>0</kinematic>
      </link>
      <joint name='hand_l_mimic_distal_joint' type='revolute'>
        <child>hand_l_mimic_distal_link</child>
        <parent>hand_l_spring_proximal_link</parent>
        <axis>
          <xyz>-1 0 0</xyz>
          <limit>
            <lower>-0.698</lower>
            <upper>-0</upper>
            <effort>100</effort>
            <velocity>1</velocity>
          </limit>
          <dynamics>
            <damping>0.0001</damping>
            <friction>0</friction>
            <spring_reference>0</spring_reference>
            <spring_stiffness>0</spring_stiffness>
          </dynamics>
          <use_parent_model_frame>1</use_parent_model_frame>
        </axis>
        <physics>
          <ode>
            <limit>
              <cfm>0</cfm>
              <erp>0.2</erp>
            </limit>
          </ode>
        </physics>
      </joint>
      <link name='hand_l_distal_link'>
        <pose frame=''>0.17475 0.1025 0.878 0 -0 -3.14159</pose>
        <inertial>
          <pose frame=''>0.010963 0.004789 0.026131 0 -0 0</pose>
          <mass>0.047731</mass>
          <inertia>
            <ixx>0.00301442</ixx>
            <ixy>-2.43794e-06</ixy>
            <ixz>1.08454e-08</ixz>
            <iyy>0.00300659</iyy>
            <iyz>-1.38829e-06</iyz>
            <izz>0.00300979</izz>
          </inertia>
        </inertial>
        <collision name='hand_l_distal_link_collision'>
          <pose frame=''>0 0 0 0 -0 0</pose>
          <geometry>
            <mesh>
              <scale>1 1 1</scale>
              <uri>/opt/ros/kinetic/share/hsrb_description/meshes/hand_v0/l_distal.stl</uri>
            </mesh>
          </geometry>
          <surface>
            <contact>
              <ode/>
            </contact>
            <friction>
              <ode>
                <mu>1</mu>
                <mu2>1</mu2>
              </ode>
              <torsional>
                <ode/>
              </torsional>
            </friction>
            <bounce/>
          </surface>
          <max_contacts>10</max_contacts>
        </collision>
        <visual name='hand_l_distal_link_visual'>
          <pose frame=''>0 0 0 0 -0 0</pose>
          <geometry>
            <mesh>
              <scale>1 1 1</scale>
              <uri>/opt/ros/kinetic/share/hsrb_description/meshes/hand_v0/l_distal.dae</uri>
            </mesh>
          </geometry>
          <material>
            <script>
              <uri>__default__</uri>
              <name>__default__</name>
            </script>
          </material>
        </visual>
        <visual name='hand_l_distal_link_fixed_joint_lump__hand_l_finger_vacuum_frame_visual_1'>
          <pose frame=''>0.00475 -0.004468 0.026149 0.785398 -0 0</pose>
          <geometry>
            <box>
              <size>0.008 0.008 0.02</size>
            </box>
          </geometry>
          <material>
            <script>
              <uri>__default__</uri>
              <name>__default__</name>
            </script>
          </material>
        </visual>
        <velocity_decay/>
        <gravity>1</gravity>
        <velocity_decay/>
        <gravity>0</gravity>
        <gravity>1</gravity>
        <velocity_decay/>
        <self_collide>0</self_collide>
        <gravity>0</gravity>
        <kinematic>0</kinematic>
      </link>
      <joint name='hand_l_distal_joint' type='revolute'>
        <child>hand_l_distal_link</child>
        <parent>hand_l_mimic_distal_link</parent>
        <axis>
          <xyz>-1 0 0</xyz>
          <limit>
            <lower>-1.24</lower>
            <upper>0.798</upper>
            <effort>100</effort>
            <velocity>1</velocity>
          </limit>
          <dynamics>
            <damping>0.0001</damping>
            <friction>0</friction>
            <spring_reference>0</spring_reference>
            <spring_stiffness>0</spring_stiffness>
          </dynamics>
          <use_parent_model_frame>1</use_parent_model_frame>
        </axis>
        <physics>
          <ode>
            <limit>
              <cfm>0</cfm>
              <erp>0.2</erp>
            </limit>
          </ode>
        </physics>
      </joint>
      <link name='hand_motor_dummy_link'>
        <pose frame=''>0.158 0.078 0.8255 0 -0 -3.14159</pose>
        <inertial>
          <pose frame=''>0 0 0 0 -0 0</pose>
          <mass>0.01</mass>
          <inertia>
            <ixx>0.0015</ixx>
            <ixy>0</ixy>
            <ixz>0</ixz>
            <iyy>0.0015</iyy>
            <iyz>0</iyz>
            <izz>0.0015</izz>
          </inertia>
        </inertial>
        <self_collide>0</self_collide>
        <kinematic>0</kinematic>
        <gravity>1</gravity>
      </link>
      <joint name='hand_motor_joint' type='revolute'>
        <child>hand_motor_dummy_link</child>
        <parent>wrist_ft_sensor_frame</parent>
        <axis>
          <xyz>-1 0 0</xyz>
          <limit>
            <lower>-0.798</lower>
            <upper>1.24</upper>
            <effort>100</effort>
            <velocity>1</velocity>
          </limit>
          <dynamics>
            <damping>0.0001</damping>
            <friction>0</friction>
            <spring_reference>0</spring_reference>
            <spring_stiffness>0</spring_stiffness>
          </dynamics>
          <use_parent_model_frame>1</use_parent_model_frame>
        </axis>
        <physics>
          <ode>
            <limit>
              <cfm>0</cfm>
              <erp>0.2</erp>
            </limit>
          </ode>
        </physics>
      </joint>
      <link name='hand_r_proximal_link'>
        <pose frame=''>0.17475 0.0535 0.808 0 -0 -3.14159</pose>
        <inertial>
          <pose frame=''>0 0 0 0 -0 0</pose>
          <mass>0.01</mass>
          <inertia>
            <ixx>0.0015</ixx>
            <ixy>0</ixy>
            <ixz>0</ixz>
            <iyy>0.0015</iyy>
            <iyz>0</iyz>
            <izz>0.0015</izz>
          </inertia>
        </inertial>
        <gravity>1</gravity>
        <velocity_decay/>
        <self_collide>0</self_collide>
        <gravity>1</gravity>
        <kinematic>0</kinematic>
      </link>
      <joint name='hand_r_proximal_joint' type='revolute'>
        <child>hand_r_proximal_link</child>
        <parent>wrist_ft_sensor_frame</parent>
        <axis>
          <xyz>1 0 0</xyz>
          <limit>
            <lower>-0.798</lower>
            <upper>1.24</upper>
            <effort>100</effort>
            <velocity>1</velocity>
          </limit>
          <dynamics>
            <damping>0.0001</damping>
            <friction>0</friction>
            <spring_reference>0</spring_reference>
            <spring_stiffness>0</spring_stiffness>
          </dynamics>
          <use_parent_model_frame>1</use_parent_model_frame>
        </axis>
        <physics>
          <ode>
            <limit>
              <cfm>0</cfm>
              <erp>0.2</erp>
            </limit>
          </ode>
        </physics>
      </joint>
      <link name='hand_r_spring_proximal_link'>
        <pose frame=''>0.17475 0.0535 0.808 0 -0 -3.14159</pose>
        <inertial>
          <pose frame=''>0.013203 0.002096 0.023311 0 -0 0</pose>
          <mass>0.043956</mass>
          <inertia>
            <ixx>2.62366e-05</ixx>
            <ixy>1.631e-08</ixy>
            <ixz>1.28184e-06</ixz>
            <iyy>2.88382e-05</iyy>
            <iyz>-1.62171e-06</iyz>
            <izz>4.95715e-06</izz>
          </inertia>
        </inertial>
        <collision name='hand_r_spring_proximal_link_collision'>
          <pose frame=''>0 0 0 0 -0 0</pose>
          <geometry>
            <mesh>
              <scale>1 1 1</scale>
              <uri>/opt/ros/kinetic/share/hsrb_description/meshes/hand_v0/r_proximal.stl</uri>
            </mesh>
          </geometry>
          <surface>
            <contact>
              <ode/>
            </contact>
            <friction>
              <ode>
                <mu>1</mu>
                <mu2>1</mu2>
              </ode>
              <torsional>
                <ode/>
              </torsional>
            </friction>
            <bounce/>
          </surface>
          <max_contacts>10</max_contacts>
        </collision>
        <visual name='hand_r_spring_proximal_link_visual'>
          <pose frame=''>0 0 0 0 -0 0</pose>
          <geometry>
            <mesh>
              <scale>1 1 1</scale>
              <uri>/opt/ros/kinetic/share/hsrb_description/meshes/hand_v0/r_proximal.dae</uri>
            </mesh>
          </geometry>
          <material>
            <script>
              <uri>__default__</uri>
              <name>__default__</name>
            </script>
          </material>
        </visual>
        <gravity>1</gravity>
        <velocity_decay/>
        <self_collide>0</self_collide>
        <gravity>1</gravity>
        <kinematic>0</kinematic>
      </link>
      <joint name='hand_r_spring_proximal_joint' type='revolute'>
        <child>hand_r_spring_proximal_link</child>
        <parent>hand_r_proximal_link</parent>
        <axis>
          <xyz>1 0 0</xyz>
          <limit>
            <lower>0</lower>
            <upper>0.698</upper>
            <effort>10</effort>
            <velocity>1</velocity>
          </limit>
          <dynamics>
            <damping>0.0001</damping>
            <friction>0</friction>
            <spring_reference>0</spring_reference>
            <spring_stiffness>0</spring_stiffness>
          </dynamics>
          <use_parent_model_frame>1</use_parent_model_frame>
        </axis>
        <physics>
          <ode>
            <limit>
              <cfm>0</cfm>
              <erp>0.2</erp>
            </limit>
          </ode>
        </physics>
      </joint>
      <link name='hand_r_mimic_distal_link'>
        <pose frame=''>0.17475 0.0535 0.878 0 -0 -3.14159</pose>
        <inertial>
          <pose frame=''>0 0 0 0 -0 0</pose>
          <mass>0.01</mass>
          <inertia>
            <ixx>0.0015</ixx>
            <ixy>0</ixy>
            <ixz>0</ixz>
            <iyy>0.0015</iyy>
            <iyz>0</iyz>
            <izz>0.0015</izz>
          </inertia>
        </inertial>
        <gravity>1</gravity>
        <velocity_decay/>
        <self_collide>0</self_collide>
        <gravity>1</gravity>
        <kinematic>0</kinematic>
      </link>
      <joint name='hand_r_mimic_distal_joint' type='revolute'>
        <child>hand_r_mimic_distal_link</child>
        <parent>hand_r_spring_proximal_link</parent>
        <axis>
          <xyz>1 0 0</xyz>
          <limit>
            <lower>-0.698</lower>
            <upper>-0</upper>
            <effort>100</effort>
            <velocity>1</velocity>
          </limit>
          <dynamics>
            <damping>0.0001</damping>
            <friction>0</friction>
            <spring_reference>0</spring_reference>
            <spring_stiffness>0</spring_stiffness>
          </dynamics>
          <use_parent_model_frame>1</use_parent_model_frame>
        </axis>
        <physics>
          <ode>
            <limit>
              <cfm>0</cfm>
              <erp>0.2</erp>
            </limit>
          </ode>
        </physics>
      </joint>
      <link name='hand_r_distal_link'>
        <pose frame=''>0.17475 0.0535 0.878 0 -0 -3.14159</pose>
        <inertial>
          <pose frame=''>0.015062 -0.011661 0.024418 0 -0 0</pose>
          <mass>0.030927</mass>
          <inertia>
            <ixx>0.00150884</ixx>
            <ixy>1.24771e-07</ixy>
            <ixz>-4.51213e-07</ixz>
            <iyy>0.00150916</iyy>
            <iyz>2.75163e-06</iyz>
            <izz>0.00150357</izz>
          </inertia>
        </inertial>
        <collision name='hand_r_distal_link_collision'>
          <pose frame=''>0 0 0 0 -0 0</pose>
          <geometry>
            <mesh>
              <scale>1 1 1</scale>
              <uri>/opt/ros/kinetic/share/hsrb_description/meshes/hand_v0/r_distal.stl</uri>
            </mesh>
          </geometry>
          <surface>
            <contact>
              <ode/>
            </contact>
            <friction>
              <ode>
                <mu>1</mu>
                <mu2>1</mu2>
              </ode>
              <torsional>
                <ode/>
              </torsional>
            </friction>
            <bounce/>
          </surface>
          <max_contacts>10</max_contacts>
        </collision>
        <visual name='hand_r_distal_link_visual'>
          <pose frame=''>0 0 0 0 -0 0</pose>
          <geometry>
            <mesh>
              <scale>1 1 1</scale>
              <uri>/opt/ros/kinetic/share/hsrb_description/meshes/hand_v0/r_distal.dae</uri>
            </mesh>
          </geometry>
          <material>
            <script>
              <uri>__default__</uri>
              <name>__default__</name>
            </script>
          </material>
        </visual>
        <velocity_decay/>
        <gravity>0</gravity>
        <gravity>1</gravity>
        <velocity_decay/>
        <self_collide>0</self_collide>
        <gravity>0</gravity>
        <kinematic>0</kinematic>
      </link>
      <joint name='hand_r_distal_joint' type='revolute'>
        <child>hand_r_distal_link</child>
        <parent>hand_r_mimic_distal_link</parent>
        <axis>
          <xyz>1 0 0</xyz>
          <limit>
            <lower>-1.24</lower>
            <upper>0.798</upper>
            <effort>100</effort>
            <velocity>1</velocity>
          </limit>
          <dynamics>
            <damping>0.0001</damping>
            <friction>0</friction>
            <spring_reference>0</spring_reference>
            <spring_stiffness>0</spring_stiffness>
          </dynamics>
          <use_parent_model_frame>1</use_parent_model_frame>
        </axis>
        <physics>
          <ode>
            <limit>
              <cfm>0</cfm>
              <erp>0.2</erp>
            </limit>
          </ode>
        </physics>
      </joint>
      <link name='base_b_bumper_link'>
        <pose frame=''>0 0.0013 0 0 -0 -3.14159</pose>
        <inertial>
          <pose frame=''>0 0 0 0 -0 0</pose>
          <mass>0.06</mass>
          <inertia>
            <ixx>0.001437</ixx>
            <ixy>0</ixy>
            <ixz>0</ixz>
            <iyy>0.001437</iyy>
            <iyz>0</iyz>
            <izz>0.002875</izz>
          </inertia>
        </inertial>
        <collision name='base_b_bumper_link_collision'>
          <pose frame=''>0 0 0 0 -0 0</pose>
          <geometry>
            <mesh>
              <scale>1 1 1</scale>
              <uri>/opt/ros/kinetic/share/hsrb_description/meshes/base_v2/bumper.stl</uri>
            </mesh>
          </geometry>
          <surface>
            <contact>
              <ode/>
            </contact>
            <friction>
              <ode>
                <mu>0.9</mu>
                <mu2>0.9</mu2>
              </ode>
              <torsional>
                <ode/>
              </torsional>
            </friction>
            <bounce/>
          </surface>
          <max_contacts>10</max_contacts>
        </collision>
        <visual name='base_b_bumper_link_visual'>
          <pose frame=''>0 0 0 0 -0 0</pose>
          <geometry>
            <mesh>
              <scale>1 1 1</scale>
              <uri>/opt/ros/kinetic/share/hsrb_description/meshes/base_v2/bumper.dae</uri>
            </mesh>
          </geometry>
          <material>
            <script>
              <uri>__default__</uri>
              <name>__default__</name>
            </script>
          </material>
        </visual>
        <gravity>1</gravity>
        <velocity_decay/>
        <self_collide>0</self_collide>
        <gravity>1</gravity>
        <sensor name='base_b_bumper_contact' type='contact'>
          <always_on>1</always_on>
          <update_rate>10</update_rate>
          <contact>
            <collision>base_b_bumper_link_collision</collision>
            <topic>__default_topic__</topic>
          </contact>
          <plugin name='hsrb_gazebo_ros_bumper_controller' filename='libhsrb_gazebo_ros_bumper.so'>
            <robotNamespace>hsrb</robotNamespace>
            <bumperTopicName>base_b_bumper_sensor</bumperTopicName>
            <frameName>base_b_bumper_link</frameName>
          </plugin>
        </sensor>
        <kinematic>0</kinematic>
      </link>
      <joint name='base_b_bumper_joint' type='revolute'>
        <child>base_b_bumper_link</child>
        <parent>base_footprint</parent>
        <axis>
          <xyz>-1 0 0</xyz>
          <limit>
            <lower>0</lower>
            <upper>0</upper>
            <effort>0</effort>
            <velocity>0</velocity>
          </limit>
          <dynamics>
            <spring_reference>0</spring_reference>
            <spring_stiffness>0</spring_stiffness>
          </dynamics>
          <use_parent_model_frame>1</use_parent_model_frame>
        </axis>
      </joint>
      <link name='base_f_bumper_link'>
        <pose frame=''>0 0 0 0 -0 0</pose>
        <inertial>
          <pose frame=''>0 0 0 0 -0 0</pose>
          <mass>0.06</mass>
          <inertia>
            <ixx>0.001437</ixx>
            <ixy>0</ixy>
            <ixz>0</ixz>
            <iyy>0.001437</iyy>
            <iyz>0</iyz>
            <izz>0.002875</izz>
          </inertia>
        </inertial>
        <collision name='base_f_bumper_link_collision'>
          <pose frame=''>0 0 0 0 -0 0</pose>
          <geometry>
            <mesh>
              <scale>1 1 1</scale>
              <uri>/opt/ros/kinetic/share/hsrb_description/meshes/base_v2/bumper.stl</uri>
            </mesh>
          </geometry>
          <surface>
            <contact>
              <ode/>
            </contact>
            <friction>
              <ode>
                <mu>0.9</mu>
                <mu2>0.9</mu2>
              </ode>
              <torsional>
                <ode/>
              </torsional>
            </friction>
            <bounce/>
          </surface>
          <max_contacts>10</max_contacts>
        </collision>
        <visual name='base_f_bumper_link_visual'>
          <pose frame=''>0 0 0 0 -0 0</pose>
          <geometry>
            <mesh>
              <scale>1 1 1</scale>
              <uri>/opt/ros/kinetic/share/hsrb_description/meshes/base_v2/bumper.dae</uri>
            </mesh>
          </geometry>
          <material>
            <script>
              <uri>__default__</uri>
              <name>__default__</name>
            </script>
          </material>
        </visual>
        <gravity>1</gravity>
        <velocity_decay/>
        <self_collide>0</self_collide>
        <gravity>1</gravity>
        <sensor name='base_f_bumper_contact' type='contact'>
          <always_on>1</always_on>
          <update_rate>10</update_rate>
          <contact>
            <collision>base_f_bumper_link_collision</collision>
            <topic>__default_topic__</topic>
          </contact>
          <plugin name='hsrb_gazebo_ros_bumper_controller' filename='libhsrb_gazebo_ros_bumper.so'>
            <robotNamespace>hsrb</robotNamespace>
            <bumperTopicName>base_f_bumper_sensor</bumperTopicName>
            <frameName>base_f_bumper_link</frameName>
          </plugin>
        </sensor>
        <kinematic>0</kinematic>
      </link>
      <joint name='base_f_bumper_joint' type='revolute'>
        <child>base_f_bumper_link</child>
        <parent>base_footprint</parent>
        <axis>
          <xyz>1 0 0</xyz>
          <limit>
            <lower>0</lower>
            <upper>0</upper>
            <effort>0</effort>
            <velocity>0</velocity>
          </limit>
          <dynamics>
            <spring_reference>0</spring_reference>
            <spring_stiffness>0</spring_stiffness>
          </dynamics>
          <use_parent_model_frame>1</use_parent_model_frame>
        </axis>
      </joint>
      <link name='base_roll_link'>
        <pose frame=''>0 0 0 0 -0 0</pose>
        <inertial>
          <pose frame=''>-0.019482 0.002191 0.071013 0 -0 0</pose>
          <mass>10.2394</mass>
          <inertia>
            <ixx>0.07671</ixx>
            <ixy>-0.01005</ixy>
            <ixz>0.001749</ixz>
            <iyy>0.09057</iyy>
            <iyz>0.001549</iyz>
            <izz>0.145</izz>
          </inertia>
        </inertial>
        <gravity>1</gravity>
        <velocity_decay/>
        <self_collide>0</self_collide>
        <gravity>1</gravity>
        <kinematic>0</kinematic>
      </link>
      <joint name='base_roll_joint' type='revolute'>
        <child>base_roll_link</child>
        <parent>base_footprint</parent>
        <axis>
          <xyz>0 0 1</xyz>
          <limit>
            <lower>-1e+16</lower>
            <upper>1e+16</upper>
          </limit>
          <dynamics>
            <damping>0.7</damping>
            <friction>0</friction>
            <spring_reference>0</spring_reference>
            <spring_stiffness>0</spring_stiffness>
          </dynamics>
          <use_parent_model_frame>1</use_parent_model_frame>
        </axis>
      </joint>
      <link name='base_l_drive_wheel_link'>
        <pose frame=''>-0.11 0.133 0.04 0 -0 0</pose>
        <inertial>
          <pose frame=''>0 0 0 0 -0 0</pose>
          <mass>0.2</mass>
          <inertia>
            <ixx>0.015</ixx>
            <ixy>0</ixy>
            <ixz>0</ixz>
            <iyy>0.015</iyy>
            <iyz>0</iyz>
            <izz>0.015</izz>
          </inertia>
        </inertial>
        <collision name='base_l_drive_wheel_link_collision'>
          <pose frame=''>0 0 0 1.5708 -0 0</pose>
          <geometry>
            <cylinder>
              <length>0.03</length>
              <radius>0.04</radius>
            </cylinder>
          </geometry>
          <surface>
            <contact>
              <ode>
                <kp>1e+06</kp>
                <kd>10</kd>
                <max_vel>1</max_vel>
                <min_depth>0</min_depth>
              </ode>
            </contact>
            <friction>
              <ode>
                <mu>1</mu>
                <mu2>1</mu2>
              </ode>
              <torsional>
                <ode/>
              </torsional>
            </friction>
            <bounce/>
          </surface>
          <max_contacts>10</max_contacts>
        </collision>
        <visual name='base_l_drive_wheel_link_visual'>
          <pose frame=''>0 0 0 1.5708 -0 0</pose>
          <geometry>
            <cylinder>
              <length>0.03</length>
              <radius>0.04</radius>
            </cylinder>
          </geometry>
          <material>
            <script>
              <name>Gazebo/FlatBlack</name>
              <uri>file://media/materials/scripts/gazebo.material</uri>
            </script>
          </material>
        </visual>
        <gravity>1</gravity>
        <velocity_decay/>
        <self_collide>0</self_collide>
        <gravity>1</gravity>
        <kinematic>0</kinematic>
      </link>
      <joint name='base_l_drive_wheel_joint' type='revolute'>
        <child>base_l_drive_wheel_link</child>
        <parent>base_roll_link</parent>
        <axis>
          <xyz>0 1 0</xyz>
          <limit>
            <lower>-1e+16</lower>
            <upper>1e+16</upper>
          </limit>
          <dynamics>
            <damping>1</damping>
            <friction>0</friction>
            <spring_reference>0</spring_reference>
            <spring_stiffness>0</spring_stiffness>
          </dynamics>
          <use_parent_model_frame>1</use_parent_model_frame>
        </axis>
      </joint>
      <link name='base_l_passive_wheel_x_frame'>
        <pose frame=''>0.1495 0.055 0.03 0 -0 0</pose>
        <inertial>
          <pose frame=''>0 0 0 0 -0 0</pose>
          <mass>0.2</mass>
          <inertia>
            <ixx>0.015</ixx>
            <ixy>0</ixy>
            <ixz>0</ixz>
            <iyy>0.015</iyy>
            <iyz>0</iyz>
            <izz>0.015</izz>
          </inertia>
        </inertial>
        <self_collide>0</self_collide>
        <kinematic>0</kinematic>
        <gravity>1</gravity>
      </link>
      <joint name='base_l_passive_wheel_x_frame_joint' type='revolute'>
        <child>base_l_passive_wheel_x_frame</child>
        <parent>base_roll_link</parent>
        <axis>
          <xyz>1 0 0</xyz>
          <limit>
            <lower>-1e+16</lower>
            <upper>1e+16</upper>
          </limit>
          <dynamics>
            <damping>1</damping>
            <friction>0</friction>
            <spring_reference>0</spring_reference>
            <spring_stiffness>0</spring_stiffness>
          </dynamics>
          <use_parent_model_frame>1</use_parent_model_frame>
        </axis>
      </joint>
      <link name='base_l_passive_wheel_y_frame'>
        <pose frame=''>0.1495 0.055 0.03 0 -0 0</pose>
        <inertial>
          <pose frame=''>0 0 0 0 -0 0</pose>
          <mass>0.2</mass>
          <inertia>
            <ixx>0.015</ixx>
            <ixy>0</ixy>
            <ixz>0</ixz>
            <iyy>0.015</iyy>
            <iyz>0</iyz>
            <izz>0.015</izz>
          </inertia>
        </inertial>
        <self_collide>0</self_collide>
        <kinematic>0</kinematic>
        <gravity>1</gravity>
      </link>
      <joint name='base_l_passive_wheel_y_frame_joint' type='revolute'>
        <child>base_l_passive_wheel_y_frame</child>
        <parent>base_l_passive_wheel_x_frame</parent>
        <axis>
          <xyz>0 1 0</xyz>
          <limit>
            <lower>-1e+16</lower>
            <upper>1e+16</upper>
          </limit>
          <dynamics>
            <spring_reference>0</spring_reference>
            <spring_stiffness>0</spring_stiffness>
          </dynamics>
          <use_parent_model_frame>1</use_parent_model_frame>
        </axis>
      </joint>
      <link name='base_l_passive_wheel_z_link'>
        <pose frame=''>0.1495 0.055 0.03 0 -0 0</pose>
        <inertial>
          <pose frame=''>0 0 0 0 -0 0</pose>
          <mass>0.2</mass>
          <inertia>
            <ixx>0.015</ixx>
            <ixy>0</ixy>
            <ixz>0</ixz>
            <iyy>0.015</iyy>
            <iyz>0</iyz>
            <izz>0.015</izz>
          </inertia>
        </inertial>
        <collision name='base_l_passive_wheel_z_link_collision'>
          <pose frame=''>0 0 0 0 -0 0</pose>
          <geometry>
            <sphere>
              <radius>0.03</radius>
            </sphere>
          </geometry>
          <surface>
            <contact>
              <ode>
                <max_vel>1</max_vel>
              </ode>
            </contact>
            <friction>
              <ode>
                <mu>0.1</mu>
                <mu2>0.1</mu2>
              </ode>
              <torsional>
                <ode/>
              </torsional>
            </friction>
            <bounce/>
          </surface>
          <max_contacts>10</max_contacts>
        </collision>
        <visual name='base_l_passive_wheel_z_link_visual'>
          <pose frame=''>0 0 0 0 -0 0</pose>
          <geometry>
            <sphere>
              <radius>0.03</radius>
            </sphere>
          </geometry>
          <material>
            <script>
              <name>Gazebo/FlatBlack</name>
              <uri>file://media/materials/scripts/gazebo.material</uri>
            </script>
          </material>
        </visual>
        <gravity>1</gravity>
        <velocity_decay/>
        <self_collide>0</self_collide>
        <gravity>1</gravity>
        <kinematic>0</kinematic>
      </link>
      <joint name='base_l_passive_wheel_z_joint' type='revolute'>
        <child>base_l_passive_wheel_z_link</child>
        <parent>base_l_passive_wheel_y_frame</parent>
        <axis>
          <xyz>0 0 1</xyz>
          <limit>
            <lower>-1e+16</lower>
            <upper>1e+16</upper>
          </limit>
          <dynamics>
            <spring_reference>0</spring_reference>
            <spring_stiffness>0</spring_stiffness>
          </dynamics>
          <use_parent_model_frame>1</use_parent_model_frame>
        </axis>
      </joint>
      <link name='base_r_drive_wheel_link'>
        <pose frame=''>-0.11 -0.133 0.04 0 -0 0</pose>
        <inertial>
          <pose frame=''>0 0 0 0 -0 0</pose>
          <mass>0.2</mass>
          <inertia>
            <ixx>0.015</ixx>
            <ixy>0</ixy>
            <ixz>0</ixz>
            <iyy>0.015</iyy>
            <iyz>0</iyz>
            <izz>0.015</izz>
          </inertia>
        </inertial>
        <collision name='base_r_drive_wheel_link_collision'>
          <pose frame=''>0 0 0 1.5708 -0 0</pose>
          <geometry>
            <cylinder>
              <length>0.03</length>
              <radius>0.04</radius>
            </cylinder>
          </geometry>
          <surface>
            <contact>
              <ode>
                <kp>1e+06</kp>
                <kd>10</kd>
                <max_vel>1</max_vel>
                <min_depth>0</min_depth>
              </ode>
            </contact>
            <friction>
              <ode>
                <mu>1</mu>
                <mu2>1</mu2>
              </ode>
              <torsional>
                <ode/>
              </torsional>
            </friction>
            <bounce/>
          </surface>
          <max_contacts>10</max_contacts>
        </collision>
        <visual name='base_r_drive_wheel_link_visual'>
          <pose frame=''>0 0 0 1.5708 -0 0</pose>
          <geometry>
            <cylinder>
              <length>0.03</length>
              <radius>0.04</radius>
            </cylinder>
          </geometry>
          <material>
            <script>
              <name>Gazebo/FlatBlack</name>
              <uri>file://media/materials/scripts/gazebo.material</uri>
            </script>
          </material>
        </visual>
        <gravity>1</gravity>
        <velocity_decay/>
        <self_collide>0</self_collide>
        <gravity>1</gravity>
        <kinematic>0</kinematic>
      </link>
      <joint name='base_r_drive_wheel_joint' type='revolute'>
        <child>base_r_drive_wheel_link</child>
        <parent>base_roll_link</parent>
        <axis>
          <xyz>0 1 0</xyz>
          <limit>
            <lower>-1e+16</lower>
            <upper>1e+16</upper>
          </limit>
          <dynamics>
            <damping>1</damping>
            <friction>0</friction>
            <spring_reference>0</spring_reference>
            <spring_stiffness>0</spring_stiffness>
          </dynamics>
          <use_parent_model_frame>1</use_parent_model_frame>
        </axis>
      </joint>
      <link name='base_r_passive_wheel_x_frame'>
        <pose frame=''>0.1495 -0.055 0.03 0 -0 0</pose>
        <inertial>
          <pose frame=''>0 0 0 0 -0 0</pose>
          <mass>0.2</mass>
          <inertia>
            <ixx>0.015</ixx>
            <ixy>0</ixy>
            <ixz>0</ixz>
            <iyy>0.015</iyy>
            <iyz>0</iyz>
            <izz>0.015</izz>
          </inertia>
        </inertial>
        <self_collide>0</self_collide>
        <kinematic>0</kinematic>
        <gravity>1</gravity>
      </link>
      <joint name='base_r_passive_wheel_x_frame_joint' type='revolute'>
        <child>base_r_passive_wheel_x_frame</child>
        <parent>base_roll_link</parent>
        <axis>
          <xyz>1 0 0</xyz>
          <limit>
            <lower>-1e+16</lower>
            <upper>1e+16</upper>
          </limit>
          <dynamics>
            <damping>1</damping>
            <friction>0</friction>
            <spring_reference>0</spring_reference>
            <spring_stiffness>0</spring_stiffness>
          </dynamics>
          <use_parent_model_frame>1</use_parent_model_frame>
        </axis>
      </joint>
      <link name='base_r_passive_wheel_y_frame'>
        <pose frame=''>0.1495 -0.055 0.03 0 -0 0</pose>
        <inertial>
          <pose frame=''>0 0 0 0 -0 0</pose>
          <mass>0.2</mass>
          <inertia>
            <ixx>0.015</ixx>
            <ixy>0</ixy>
            <ixz>0</ixz>
            <iyy>0.015</iyy>
            <iyz>0</iyz>
            <izz>0.015</izz>
          </inertia>
        </inertial>
        <self_collide>0</self_collide>
        <kinematic>0</kinematic>
        <gravity>1</gravity>
      </link>
      <joint name='base_r_passive_wheel_y_frame_joint' type='revolute'>
        <child>base_r_passive_wheel_y_frame</child>
        <parent>base_r_passive_wheel_x_frame</parent>
        <axis>
          <xyz>0 1 0</xyz>
          <limit>
            <lower>-1e+16</lower>
            <upper>1e+16</upper>
          </limit>
          <dynamics>
            <spring_reference>0</spring_reference>
            <spring_stiffness>0</spring_stiffness>
          </dynamics>
          <use_parent_model_frame>1</use_parent_model_frame>
        </axis>
      </joint>
      <link name='base_r_passive_wheel_z_link'>
        <pose frame=''>0.1495 -0.055 0.03 0 -0 0</pose>
        <inertial>
          <pose frame=''>0 0 0 0 -0 0</pose>
          <mass>0.2</mass>
          <inertia>
            <ixx>0.015</ixx>
            <ixy>0</ixy>
            <ixz>0</ixz>
            <iyy>0.015</iyy>
            <iyz>0</iyz>
            <izz>0.015</izz>
          </inertia>
        </inertial>
        <collision name='base_r_passive_wheel_z_link_collision'>
          <pose frame=''>0 0 0 0 -0 0</pose>
          <geometry>
            <sphere>
              <radius>0.03</radius>
            </sphere>
          </geometry>
          <surface>
            <contact>
              <ode>
                <max_vel>1</max_vel>
              </ode>
            </contact>
            <friction>
              <ode>
                <mu>0.1</mu>
                <mu2>0.1</mu2>
              </ode>
              <torsional>
                <ode/>
              </torsional>
            </friction>
            <bounce/>
          </surface>
          <max_contacts>10</max_contacts>
        </collision>
        <visual name='base_r_passive_wheel_z_link_visual'>
          <pose frame=''>0 0 0 0 -0 0</pose>
          <geometry>
            <sphere>
              <radius>0.03</radius>
            </sphere>
          </geometry>
          <material>
            <script>
              <name>Gazebo/FlatBlack</name>
              <uri>file://media/materials/scripts/gazebo.material</uri>
            </script>
          </material>
        </visual>
        <gravity>1</gravity>
        <velocity_decay/>
        <self_collide>0</self_collide>
        <gravity>1</gravity>
        <kinematic>0</kinematic>
      </link>
      <joint name='base_r_passive_wheel_z_joint' type='revolute'>
        <child>base_r_passive_wheel_z_link</child>
        <parent>base_r_passive_wheel_y_frame</parent>
        <axis>
          <xyz>0 0 1</xyz>
          <limit>
            <lower>-1e+16</lower>
            <upper>1e+16</upper>
          </limit>
          <dynamics>
            <spring_reference>0</spring_reference>
            <spring_stiffness>0</spring_stiffness>
          </dynamics>
          <use_parent_model_frame>1</use_parent_model_frame>
        </axis>
      </joint>
      <link name='torso_lift_link'>
        <pose frame=''>0 0 0.752 0 -0 0</pose>
        <inertial>
          <pose frame=''>-0.051142 0.003454 -0.2905 0 -0 0</pose>
          <mass>3.42078</mass>
          <inertia>
            <ixx>0.1045</ixx>
            <ixy>-0.000460885</ixy>
            <ixz>0.00010113</ixz>
            <iyy>0.105</iyy>
            <iyz>0.002941</iyz>
            <izz>0.01284</izz>
          </inertia>
        </inertial>
        <collision name='torso_lift_link_collision'>
          <pose frame=''>0 0 0 0 -0 0</pose>
          <geometry>
            <mesh>
              <scale>1 1 1</scale>
              <uri>/opt/ros/kinetic/share/hsrb_description/meshes/torso_v0/torso.stl</uri>
            </mesh>
          </geometry>
          <surface>
            <contact>
              <ode/>
            </contact>
            <friction>
              <ode>
                <mu>0.9</mu>
                <mu2>0.9</mu2>
              </ode>
              <torsional>
                <ode/>
              </torsional>
            </friction>
            <bounce/>
          </surface>
          <max_contacts>10</max_contacts>
        </collision>
        <visual name='torso_lift_link_visual'>
          <pose frame=''>0 0 0 0 -0 0</pose>
          <geometry>
            <mesh>
              <scale>1 1 1</scale>
              <uri>/opt/ros/kinetic/share/hsrb_description/meshes/torso_v0/torso_light.dae</uri>
            </mesh>
          </geometry>
          <material>
            <script>
              <uri>__default__</uri>
              <name>__default__</name>
            </script>
          </material>
        </visual>
        <gravity>1</gravity>
        <velocity_decay/>
        <self_collide>0</self_collide>
        <gravity>1</gravity>
        <kinematic>0</kinematic>
      </link>
      <joint name='torso_lift_joint' type='prismatic'>
        <child>torso_lift_link</child>
        <parent>base_footprint</parent>
        <axis>
          <xyz>0 0 1</xyz>
          <limit>
            <lower>0</lower>
            <upper>0.345</upper>
            <effort>300</effort>
            <velocity>0.1</velocity>
          </limit>
          <dynamics>
            <damping>500</damping>
            <friction>0</friction>
            <spring_reference>0</spring_reference>
            <spring_stiffness>0</spring_stiffness>
          </dynamics>
          <use_parent_model_frame>1</use_parent_model_frame>
        </axis>
        <physics>
          <ode>
            <limit>
              <cfm>0</cfm>
              <erp>0.2</erp>
            </limit>
          </ode>
        </physics>
      </joint>
      <link name='head_pan_link'>
        <pose frame=''>0 0 0.752 0 -0 0</pose>
        <inertial>
          <pose frame=''>0.001724 -0.001969 -0.028886 0 -0 0</pose>
          <mass>0.571903</mass>
          <inertia>
            <ixx>0.000971142</ixx>
            <ixy>6.17949e-05</ixy>
            <ixz>-0.000113923</ixz>
            <iyy>0.000653355</iyy>
            <iyz>6.90363e-05</iyz>
            <izz>0.000765203</izz>
          </inertia>
        </inertial>
        <collision name='head_pan_link_collision'>
          <pose frame=''>0 0 0 0 -0 0</pose>
          <geometry>
            <mesh>
              <scale>1 1 1</scale>
              <uri>/opt/ros/kinetic/share/hsrb_description/meshes/head_v1/head_pan.stl</uri>
            </mesh>
          </geometry>
          <surface>
            <contact>
              <ode/>
            </contact>
            <friction>
              <ode>
                <mu>0.9</mu>
                <mu2>0.9</mu2>
              </ode>
              <torsional>
                <ode/>
              </torsional>
            </friction>
            <bounce/>
          </surface>
          <max_contacts>10</max_contacts>
        </collision>
        <visual name='head_pan_link_visual'>
          <pose frame=''>0 0 0 0 -0 0</pose>
          <geometry>
            <mesh>
              <scale>1 1 1</scale>
              <uri>/opt/ros/kinetic/share/hsrb_description/meshes/head_v1/head_pan.dae</uri>
            </mesh>
          </geometry>
          <material>
            <script>
              <uri>__default__</uri>
              <name>__default__</name>
            </script>
          </material>
        </visual>
        <gravity>1</gravity>
        <velocity_decay/>
        <self_collide>0</self_collide>
        <gravity>1</gravity>
        <kinematic>0</kinematic>
      </link>
      <joint name='head_pan_joint' type='revolute'>
        <child>head_pan_link</child>
        <parent>torso_lift_link</parent>
        <axis>
          <xyz>0 0 1</xyz>
          <limit>
            <lower>-3.84</lower>
            <upper>1.75</upper>
            <effort>100</effort>
            <velocity>1</velocity>
          </limit>
          <dynamics>
            <damping>1</damping>
            <friction>0</friction>
            <spring_reference>0</spring_reference>
            <spring_stiffness>0</spring_stiffness>
          </dynamics>
          <use_parent_model_frame>1</use_parent_model_frame>
        </axis>
        <physics>
          <ode>
            <limit>
              <cfm>0</cfm>
              <erp>0.2</erp>
            </limit>
          </ode>
        </physics>
      </joint>
      <link name='head_tilt_link'>
        <pose frame=''>0.02 0 0.752 0 -0 0</pose>
        <inertial>
          <pose frame=''>-0.05355 -0.002148 0.117073 0 -0 0</pose>
          <mass>2.2038</mass>
          <inertia>
            <ixx>0.0280002</ixx>
            <ixy>-0.00013599</ixy>
            <ixz>0.00533594</ixz>
            <iyy>0.023706</iyy>
            <iyz>4.7745e-05</iyz>
            <izz>0.0202221</izz>
          </inertia>
        </inertial>
        <collision name='head_tilt_link_collision'>
          <pose frame=''>0 0 0 0 -0 0</pose>
          <geometry>
            <mesh>
              <scale>1 1 1</scale>
              <uri>/opt/ros/kinetic/share/hsrb_description/meshes/head_v1/head.stl</uri>
            </mesh>
          </geometry>
          <surface>
            <contact>
              <ode/>
            </contact>
            <friction>
              <ode>
                <mu>0.9</mu>
                <mu2>0.9</mu2>
              </ode>
              <torsional>
                <ode/>
              </torsional>
            </friction>
            <bounce/>
          </surface>
          <max_contacts>10</max_contacts>
        </collision>
        <collision name='head_tilt_link_collision_1'>
          <pose frame=''>0 0 0 0 -0 0</pose>
          <geometry>
            <mesh>
              <scale>1 1 1</scale>
              <uri>/opt/ros/kinetic/share/hsrb_description/meshes/head_v1/tablet.stl</uri>
            </mesh>
          </geometry>
          <surface>
            <contact>
              <ode/>
            </contact>
            <friction>
              <ode>
                <mu>0.9</mu>
                <mu2>0.9</mu2>
              </ode>
              <torsional>
                <ode/>
              </torsional>
            </friction>
            <bounce/>
          </surface>
          <max_contacts>10</max_contacts>
        </collision>
        <collision name='head_tilt_link_fixed_joint_lump__head_rgbd_sensor_link_collision_2'>
          <pose frame=''>-0.079796 0.022 0.215172 -1.5708 -0 -1.5708</pose>
          <geometry>
            <mesh>
              <scale>1 1 1</scale>
              <uri>/opt/ros/kinetic/share/hsrb_parts_description/meshes/sensors/xtion.stl</uri>
            </mesh>
          </geometry>
          <surface>
            <contact>
              <ode/>
            </contact>
            <friction>
              <ode>
                <mu>0.9</mu>
                <mu2>0.9</mu2>
              </ode>
              <torsional>
                <ode/>
              </torsional>
            </friction>
            <bounce/>
          </surface>
          <max_contacts>10</max_contacts>
        </collision>
        <visual name='head_tilt_link_visual'>
          <pose frame=''>0 0 0 0 -0 0</pose>
          <geometry>
            <mesh>
              <scale>1 1 1</scale>
              <uri>/opt/ros/kinetic/share/hsrb_description/meshes/head_v1/head_upper.dae</uri>
            </mesh>
          </geometry>
          <material>
            <script>
              <uri>__default__</uri>
              <name>__default__</name>
            </script>
          </material>
        </visual>
        <visual name='head_tilt_link_visual_1'>
          <pose frame=''>0 0 0 0 -0 0</pose>
          <geometry>
            <mesh>
              <scale>1 1 1</scale>
              <uri>/opt/ros/kinetic/share/hsrb_description/meshes/head_v1/head_tilt.dae</uri>
            </mesh>
          </geometry>
          <material>
            <script>
              <uri>__default__</uri>
              <name>__default__</name>
            </script>
          </material>
        </visual>
        <visual name='head_tilt_link_visual_2'>
          <pose frame=''>0 0 0 0 -0 0</pose>
          <geometry>
            <mesh>
              <scale>1 1 1</scale>
              <uri>/opt/ros/kinetic/share/hsrb_description/meshes/head_v1/tablet_base.dae</uri>
            </mesh>
          </geometry>
          <material>
            <script>
              <uri>__default__</uri>
              <name>__default__</name>
            </script>
          </material>
        </visual>
        <visual name='head_tilt_link_fixed_joint_lump__head_l_stereo_camera_link_visual_3'>
          <pose frame=''>0.02 0.07 0.061 -1.5708 -0 -1.5708</pose>
          <geometry>
            <mesh>
              <scale>1 1 1</scale>
              <uri>/opt/ros/kinetic/share/hsrb_parts_description/meshes/sensors/head_camera.dae</uri>
            </mesh>
          </geometry>
          <material>
            <script>
              <uri>__default__</uri>
              <name>__default__</name>
            </script>
          </material>
        </visual>
        <visual name='head_tilt_link_fixed_joint_lump__head_r_stereo_camera_link_visual_4'>
          <pose frame=''>0.02 -0.07 0.061 -1.5708 -0 -1.5708</pose>
          <geometry>
            <mesh>
              <scale>1 1 1</scale>
              <uri>/opt/ros/kinetic/share/hsrb_parts_description/meshes/sensors/head_camera.dae</uri>
            </mesh>
          </geometry>
          <material>
            <script>
              <uri>__default__</uri>
              <name>__default__</name>
            </script>
          </material>
        </visual>
        <visual name='head_tilt_link_fixed_joint_lump__head_rgbd_sensor_link_visual_5'>
          <pose frame=''>-0.079796 0.022 0.215172 -1.5708 -0 -1.5708</pose>
          <geometry>
            <mesh>
              <scale>1 1 1</scale>
              <uri>/opt/ros/kinetic/share/hsrb_parts_description/meshes/sensors/xtion.dae</uri>
            </mesh>
          </geometry>
          <material>
            <script>
              <uri>__default__</uri>
              <name>__default__</name>
            </script>
          </material>
        </visual>
        <velocity_decay/>
        <velocity_decay/>
        <velocity_decay/>
        <sensor name='head_center_camera' type='camera'>
          <update_rate>10</update_rate>
          <camera name='head_center_camera'>
            <horizontal_fov>2</horizontal_fov>
            <image>
              <width>640</width>
              <height>480</height>
              <format>R8G8B8</format>
            </image>
            <clip>
              <near>0.01</near>
              <far>100</far>
            </clip>
            <noise>
              <type>gaussian</type>
              <mean>0</mean>
              <stddev>0.007</stddev>
            </noise>
          </camera>
          <plugin name='camera_controller' filename='libhsrb_gazebo_ros_camera.so'>
            <robotNamespace>hsrb</robotNamespace>
            <alwaysOn>0</alwaysOn>
            <updateRate>0.0</updateRate>
            <cameraName>head_center_camera</cameraName>
            <imageTopicName>image_raw</imageTopicName>
            <cameraInfoTopicName>camera_info</cameraInfoTopicName>
            <frameName>head_center_camera_frame</frameName>
            <hackBaseline>0.07</hackBaseline>
            <distortionK1>0.0</distortionK1>
            <distortionK2>0.0</distortionK2>
            <distortionK3>0.0</distortionK3>
            <distortionT1>0.0</distortionT1>
            <distortionT2>0.0</distortionT2>
          </plugin>
          <pose frame=''>0.0195 0 0.061 0 -0 0</pose>
        </sensor>
        <velocity_decay/>
        <velocity_decay/>
        <sensor name='head_l_stereo_camera' type='camera'>
          <update_rate>4</update_rate>
          <camera name='head_l_stereo_camera'>
            <horizontal_fov>1.16763</horizontal_fov>
            <image>
              <width>1280</width>
              <height>960</height>
              <format>R8G8B8</format>
            </image>
            <clip>
              <near>0.05</near>
              <far>100</far>
            </clip>
            <noise>
              <type>gaussian</type>
              <mean>0</mean>
              <stddev>0.007</stddev>
            </noise>
          </camera>
          <plugin name='camera_controller' filename='libhsrb_gazebo_ros_camera.so'>
            <alwaysOn>0</alwaysOn>
            <updateRate>0.0</updateRate>
            <cameraName>head_l_stereo_camera</cameraName>
            <imageTopicName>image_rect_color</imageTopicName>
            <cameraInfoTopicName>camera_info</cameraInfoTopicName>
            <frameName>head_l_stereo_camera_frame</frameName>
            <robotNamespace>hsrb</robotNamespace>
            <hackBaseline>0.0</hackBaseline>
            <distortionK1>0.0</distortionK1>
            <distortionK2>0.0</distortionK2>
            <distortionK3>0.0</distortionK3>
            <distortionT1>0.0</distortionT1>
            <distortionT2>0.0</distortionT2>
          </plugin>
          <pose frame=''>0.02 0.07 0.061 0 -0 0</pose>
        </sensor>
        <gravity>1</gravity>
        <velocity_decay/>
        <gravity>1</gravity>
        <gravity>1</gravity>
        <velocity_decay/>
        <sensor name='head_r_stereo_camera' type='camera'>
          <update_rate>4</update_rate>
          <camera name='head_r_stereo_camera'>
            <horizontal_fov>1.16763</horizontal_fov>
            <image>
              <width>1280</width>
              <height>960</height>
              <format>R8G8B8</format>
            </image>
            <clip>
              <near>0.05</near>
              <far>100</far>
            </clip>
            <noise>
              <type>gaussian</type>
              <mean>0</mean>
              <stddev>0.007</stddev>
            </noise>
          </camera>
          <plugin name='camera_controller' filename='libhsrb_gazebo_ros_camera.so'>
            <alwaysOn>0</alwaysOn>
            <updateRate>0.0</updateRate>
            <cameraName>head_r_stereo_camera</cameraName>
            <imageTopicName>image_rect_color</imageTopicName>
            <cameraInfoTopicName>camera_info</cameraInfoTopicName>
            <frameName>head_r_stereo_camera_frame</frameName>
            <robotNamespace>hsrb</robotNamespace>
            <hackBaseline>0.14</hackBaseline>
            <distortionK1>0.0</distortionK1>
            <distortionK2>0.0</distortionK2>
            <distortionK3>0.0</distortionK3>
            <distortionT1>0.0</distortionT1>
            <distortionT2>0.0</distortionT2>
          </plugin>
          <pose frame=''>0.02 -0.07 0.061 0 -0 0</pose>
        </sensor>
        <gravity>1</gravity>
        <velocity_decay/>
        <gravity>1</gravity>
        <gravity>1</gravity>
        <velocity_decay/>
        <self_collide>0</self_collide>
        <sensor name='openni_camera_camera' type='depth'>
          <always_on>0</always_on>
          <update_rate>30</update_rate>
          <visualize>1</visualize>
          <camera name='__default__'>
            <horizontal_fov>1.047</horizontal_fov>
            <image>
              <width>640</width>
              <height>480</height>
              <format>B8G8R8</format>
            </image>
            <depth_camera>
              <output>depths</output>
            </depth_camera>
            <clip>
              <near>0.1</near>
              <far>100</far>
            </clip>
          </camera>
          <plugin name='head_rgbd_sensor_controller' filename='libhsrb_gazebo_ros_openni_kinect.so'>
            <alwaysOn>true</alwaysOn>
            <baseline>0.2</baseline>
            <updateRate>1.0</updateRate>
            <cameraName>head_rgbd_sensor</cameraName>
            <frameName>head_rgbd_sensor_rgb_frame</frameName>
            <imageTopicName>/hsrb/head_rgbd_sensor/rgb/image_rect_color</imageTopicName>
            <cameraInfoTopicName>/hsrb/head_rgbd_sensor/rgb/camera_info</cameraInfoTopicName>
            <depthImageTopicName>/hsrb/head_rgbd_sensor/depth_registered/image_rect_raw</depthImageTopicName>
            <pointCloudTopicName>/hsrb/head_rgbd_sensor/depth_registered/rectified_points</pointCloudTopicName>
            <depthImageCameraInfoTopicName>/hsrb/head_rgbd_sensor/depth_registered/camera_info</depthImageCameraInfoTopicName>
            <pointCloudCutoff>0.5</pointCloudCutoff>
            <pointCloudCutoffMax>9.2</pointCloudCutoffMax>
            <distortionK1>0.0</distortionK1>
            <distortionK2>0.0</distortionK2>
            <distortionK3>0.0</distortionK3>
            <distortionT1>0.0</distortionT1>
            <distortionT2>0.0</distortionT2>
            <CxPrime>0.0</CxPrime>
            <Cx>0.0</Cx>
            <Cy>0.0</Cy>
            <focalLength>0.0</focalLength>
            <hackBaseline>0</hackBaseline>
            <encoding>16UC1</encoding>
            <robotNamespace>/</robotNamespace>
          </plugin>
          <pose frame=''>-0.079796 0.022 0.215172 0 -0 0</pose>
        </sensor>
        <kinematic>0</kinematic>
      </link>
      <joint name='head_tilt_joint' type='revolute'>
        <child>head_tilt_link</child>
        <parent>head_pan_link</parent>
        <axis>
          <xyz>0 -1 0</xyz>
          <limit>
            <lower>-1.57</lower>
            <upper>0.52</upper>
            <effort>100</effort>
            <velocity>1</velocity>
          </limit>
          <dynamics>
            <damping>10</damping>
            <friction>0</friction>
            <spring_reference>0</spring_reference>
            <spring_stiffness>0</spring_stiffness>
          </dynamics>
          <use_parent_model_frame>1</use_parent_model_frame>
        </axis>
        <physics>
          <ode>
            <limit>
              <cfm>0</cfm>
              <erp>0.2</erp>
            </limit>
          </ode>
        </physics>
      </joint>
      <plugin name='torso_mimic_plugin' filename='libtmc_gazebo_mimic_plugin.so'>
        <joint>torso_lift_joint</joint>
        <mimicJoint>arm_lift_joint</mimicJoint>
        <multiplier>0.5</multiplier>
        <robotNamespace>/</robotNamespace>
      </plugin>
      <plugin name='ft_sensor' filename='libgazebo_ros_ft_sensor.so'>
        <updateRate>30.0</updateRate>
        <topicName>wrist_wrench/raw</topicName>
        <jointName>wrist_ft_sensor_frame_joint</jointName>
        <robotNamespace>hsrb</robotNamespace>
      </plugin>
      <plugin name='hsrb_hrh_gripper_plugin' filename='libtmc_gazebo_hrh_gripper.so'>
        <sensitiveness>0.05</sensitiveness>
        <update_rate>1000.0</update_rate>
        <max_torque>8.0</max_torque>
        <error_tolerance>0.0872</error_tolerance>
        <stall_timeout>2.0</stall_timeout>
        <robotNamespace>/</robotNamespace>
      </plugin>
      <plugin name='hsrb_grasp_hack_plugin' filename='libhsrb_grasp_hack.so'>
        <grasp_check>
          <attach_steps>1</attach_steps>
          <detach_steps>2</detach_steps>
          <min_contact_count>1</min_contact_count>
          <max_attach_weight>1.2</max_attach_weight>
        </grasp_check>
        <gripper_link>hand_r_distal_link</gripper_link>
        <gripper_link>hand_l_distal_link</gripper_link>
        <gripper_link>hand_r_spring_proximal_link</gripper_link>
        <gripper_link>hand_l_spring_proximal_link</gripper_link>
        <palm_link>wrist_ft_sensor_frame</palm_link>
        <robotNamespace>/</robotNamespace>
      </plugin>
      <static>0</static>
      <plugin name='hsrb_ros_control' filename='libhsrb_gazebo_ros_control.so'>
        <robotNamespace>hsrb</robotNamespace>
        <legacyModeNS>true</legacyModeNS>
      </plugin>
      <plugin name='hsrb_p3d_ground_truth' filename='libgazebo_ros_p3d.so'>
        <robotNamespace>hsrb</robotNamespace>
        <bodyName>base_footprint</bodyName>
        <topicName>odom_ground_truth</topicName>
        <frameName>map</frameName>
        <updateRate>30</updateRate>
      </plugin>
      <pose frame=''>0 0 0 0 -0 0</pose>
    </model>
    <model name='kitchen_table'>
      <link name='link'>
        <pose frame=''>0 0 0 0 -0 0</pose>
        <inertial>
          <mass>10</mass>
          <inertia>
            <ixx>1</ixx>
            <ixy>0</ixy>
            <ixz>0</ixz>
            <iyy>1</iyy>
            <iyz>0</iyz>
            <izz>1</izz>
          </inertia>
        </inertial>
        <visual name='center_board'>
          <pose frame=''>0 0 0.68 0 -0 0</pose>
          <geometry>
            <box>
              <size>0.68 1.13 0.04</size>
            </box>
          </geometry>
          <material>
            <script>
              <uri>model://base_materials/wood/scripts/wood.material</uri>
              <name>base_materials/wood</name>
            </script>
          </material>
        </visual>
        <collision name='collision_center_board'>
          <pose frame=''>0 0 0.68 0 -0 0</pose>
          <geometry>
            <box>
              <size>0.68 1.13 0.04</size>
            </box>
          </geometry>
          <max_contacts>10</max_contacts>
          <surface>
            <bounce/>
            <friction>
              <ode/>
              <torsional>
                <ode/>
              </torsional>
            </friction>
            <contact>
              <ode/>
            </contact>
          </surface>
        </collision>
        <visual name='front_board'>
          <pose frame=''>0.37 0 0.68 0 -0 0</pose>
          <geometry>
            <box>
              <size>0.06 1.13 0.04</size>
            </box>
          </geometry>
          <material>
            <script>
              <uri>model://base_materials/wood/scripts/wood.material</uri>
              <name>base_materials/wood</name>
            </script>
          </material>
        </visual>
        <collision name='collision_front_board'>
          <pose frame=''>0.37 0 0.68 0 -0 0</pose>
          <geometry>
            <box>
              <size>0.06 1.13 0.04</size>
            </box>
          </geometry>
          <max_contacts>10</max_contacts>
          <surface>
            <bounce/>
            <friction>
              <ode/>
              <torsional>
                <ode/>
              </torsional>
            </friction>
            <contact>
              <ode/>
            </contact>
          </surface>
        </collision>
        <visual name='back_board'>
          <pose frame=''>-0.37 0 0.68 0 -0 0</pose>
          <geometry>
            <box>
              <size>0.06 1.13 0.04</size>
            </box>
          </geometry>
          <material>
            <script>
              <uri>model://base_materials/wood/scripts/wood.material</uri>
              <name>base_materials/wood</name>
            </script>
          </material>
        </visual>
        <collision name='collision_back_board'>
          <pose frame=''>-0.37 0 0.68 0 -0 0</pose>
          <geometry>
            <box>
              <size>0.06 1.13 0.04</size>
            </box>
          </geometry>
          <max_contacts>10</max_contacts>
          <surface>
            <bounce/>
            <friction>
              <ode/>
              <torsional>
                <ode/>
              </torsional>
            </friction>
            <contact>
              <ode/>
            </contact>
          </surface>
        </collision>
        <visual name='right_board'>
          <pose frame=''>0 0.595 0.68 0 -0 0</pose>
          <geometry>
            <box>
              <size>0.68 0.06 0.04</size>
            </box>
          </geometry>
          <material>
            <script>
              <uri>model://base_materials/wood/scripts/wood.material</uri>
              <name>base_materials/wood</name>
            </script>
          </material>
        </visual>
        <collision name='collision_right_board'>
          <pose frame=''>0 0.595 0.68 0 -0 0</pose>
          <geometry>
            <box>
              <size>0.68 0.06 0.04</size>
            </box>
          </geometry>
          <max_contacts>10</max_contacts>
          <surface>
            <bounce/>
            <friction>
              <ode/>
              <torsional>
                <ode/>
              </torsional>
            </friction>
            <contact>
              <ode/>
            </contact>
          </surface>
        </collision>
        <visual name='left_board'>
          <pose frame=''>0 -0.595 0.68 0 -0 0</pose>
          <geometry>
            <box>
              <size>0.68 0.06 0.04</size>
            </box>
          </geometry>
          <material>
            <script>
              <uri>model://base_materials/wood/scripts/wood.material</uri>
              <name>base_materials/wood</name>
            </script>
          </material>
        </visual>
        <collision name='collision_left_board'>
          <pose frame=''>0 -0.595 0.68 0 -0 0</pose>
          <geometry>
            <box>
              <size>0.68 0.06 0.04</size>
            </box>
          </geometry>
          <max_contacts>10</max_contacts>
          <surface>
            <bounce/>
            <friction>
              <ode/>
              <torsional>
                <ode/>
              </torsional>
            </friction>
            <contact>
              <ode/>
            </contact>
          </surface>
        </collision>
        <visual name='front_right_corner_board'>
          <pose frame=''>0.34 0.565 0.68 0 -0 0</pose>
          <geometry>
            <cylinder>
              <radius>0.06</radius>
              <length>0.039</length>
            </cylinder>
          </geometry>
          <material>
            <script>
              <uri>model://base_materials/wood/scripts/wood.material</uri>
              <name>base_materials/wood</name>
            </script>
          </material>
        </visual>
        <collision name='collision_front_right_corner_board'>
          <pose frame=''>0.34 0.565 0.68 0 -0 0</pose>
          <geometry>
            <cylinder>
              <radius>0.06</radius>
              <length>0.039</length>
            </cylinder>
          </geometry>
          <max_contacts>10</max_contacts>
          <surface>
            <bounce/>
            <friction>
              <ode/>
              <torsional>
                <ode/>
              </torsional>
            </friction>
            <contact>
              <ode/>
            </contact>
          </surface>
        </collision>
        <visual name='front_left_corner_board'>
          <pose frame=''>0.34 -0.565 0.68 0 -0 0</pose>
          <geometry>
            <cylinder>
              <radius>0.06</radius>
              <length>0.039</length>
            </cylinder>
          </geometry>
          <material>
            <script>
              <uri>model://base_materials/wood/scripts/wood.material</uri>
              <name>base_materials/wood</name>
            </script>
          </material>
        </visual>
        <collision name='collision_front_left_corner_board'>
          <pose frame=''>0.34 -0.565 0.68 0 -0 0</pose>
          <geometry>
            <cylinder>
              <radius>0.06</radius>
              <length>0.039</length>
            </cylinder>
          </geometry>
          <max_contacts>10</max_contacts>
          <surface>
            <bounce/>
            <friction>
              <ode/>
              <torsional>
                <ode/>
              </torsional>
            </friction>
            <contact>
              <ode/>
            </contact>
          </surface>
        </collision>
        <visual name='front_back_right_corner_board'>
          <pose frame=''>-0.34 0.565 0.68 0 -0 0</pose>
          <geometry>
            <cylinder>
              <radius>0.06</radius>
              <length>0.039</length>
            </cylinder>
          </geometry>
          <material>
            <script>
              <uri>model://base_materials/wood/scripts/wood.material</uri>
              <name>base_materials/wood</name>
            </script>
          </material>
        </visual>
        <collision name='collision_back_right_corner_board'>
          <pose frame=''>-0.34 0.565 0.68 0 -0 0</pose>
          <geometry>
            <cylinder>
              <radius>0.06</radius>
              <length>0.039</length>
            </cylinder>
          </geometry>
          <max_contacts>10</max_contacts>
          <surface>
            <bounce/>
            <friction>
              <ode/>
              <torsional>
                <ode/>
              </torsional>
            </friction>
            <contact>
              <ode/>
            </contact>
          </surface>
        </collision>
        <visual name='front_back_left_corner_board'>
          <pose frame=''>-0.34 -0.565 0.68 0 -0 0</pose>
          <geometry>
            <cylinder>
              <radius>0.06</radius>
              <length>0.039</length>
            </cylinder>
          </geometry>
          <material>
            <script>
              <uri>model://base_materials/wood/scripts/wood.material</uri>
              <name>base_materials/wood</name>
            </script>
          </material>
        </visual>
        <collision name='collision_back_left_corner_board'>
          <pose frame=''>-0.34 -0.565 0.68 0 -0 0</pose>
          <geometry>
            <cylinder>
              <radius>0.06</radius>
              <length>0.039</length>
            </cylinder>
          </geometry>
          <max_contacts>10</max_contacts>
          <surface>
            <bounce/>
            <friction>
              <ode/>
              <torsional>
                <ode/>
              </torsional>
            </friction>
            <contact>
              <ode/>
            </contact>
          </surface>
        </collision>
        <visual name='front_left_corner_frame1'>
          <pose frame=''>0.345858 -0.57086 0.33 0 -0 0</pose>
          <geometry>
            <cylinder>
              <radius>0.02</radius>
              <length>0.66</length>
            </cylinder>
          </geometry>
          <material>
            <script>
              <uri>model://base_materials/wood/scripts/wood.material</uri>
              <name>base_materials/wood</name>
            </script>
          </material>
        </visual>
        <collision name='collision_front_left_corner_frame1'>
          <pose frame=''>0.345858 -0.57086 0.33 0 -0 0</pose>
          <geometry>
            <cylinder>
              <radius>0.02</radius>
              <length>0.66</length>
            </cylinder>
          </geometry>
          <max_contacts>10</max_contacts>
          <surface>
            <bounce/>
            <friction>
              <ode/>
              <torsional>
                <ode/>
              </torsional>
            </friction>
            <contact>
              <ode/>
            </contact>
          </surface>
        </collision>
        <visual name='front_left_corner_frame2'>
          <pose frame=''>0.317574 -0.54257 0.33 0 -0 0.7854</pose>
          <geometry>
            <box>
              <size>0.04 0.08 0.66</size>
            </box>
          </geometry>
          <material>
            <script>
              <uri>model://base_materials/wood/scripts/wood.material</uri>
              <name>base_materials/wood</name>
            </script>
          </material>
        </visual>
        <collision name='collision_front_left_corner_frame2'>
          <pose frame=''>0.317574 -0.54257 0.33 0 -0 0.7854</pose>
          <geometry>
            <box>
              <size>0.04 0.08 0.66</size>
            </box>
          </geometry>
          <max_contacts>10</max_contacts>
          <surface>
            <bounce/>
            <friction>
              <ode/>
              <torsional>
                <ode/>
              </torsional>
            </friction>
            <contact>
              <ode/>
            </contact>
          </surface>
        </collision>
        <visual name='front_left_corner_frame3'>
          <pose frame=''>0.289289 -0.51429 0.33 0 -0 0</pose>
          <geometry>
            <cylinder>
              <radius>0.02</radius>
              <length>0.66</length>
            </cylinder>
          </geometry>
          <material>
            <script>
              <uri>model://base_materials/wood/scripts/wood.material</uri>
              <name>base_materials/wood</name>
            </script>
          </material>
        </visual>
        <collision name='collision_front_left_corner_frame3'>
          <pose frame=''>0.289289 -0.51429 0.33 0 -0 0</pose>
          <geometry>
            <cylinder>
              <radius>0.02</radius>
              <length>0.66</length>
            </cylinder>
          </geometry>
          <max_contacts>10</max_contacts>
          <surface>
            <bounce/>
            <friction>
              <ode/>
              <torsional>
                <ode/>
              </torsional>
            </friction>
            <contact>
              <ode/>
            </contact>
          </surface>
        </collision>
        <visual name='front_right_corner_frame1'>
          <pose frame=''>0.345858 0.57086 0.33 0 -0 0</pose>
          <geometry>
            <cylinder>
              <radius>0.02</radius>
              <length>0.66</length>
            </cylinder>
          </geometry>
          <material>
            <script>
              <uri>model://base_materials/wood/scripts/wood.material</uri>
              <name>base_materials/wood</name>
            </script>
          </material>
        </visual>
        <collision name='collision_front_right_corner_frame1'>
          <pose frame=''>0.345858 0.57086 0.33 0 -0 0</pose>
          <geometry>
            <cylinder>
              <radius>0.02</radius>
              <length>0.66</length>
            </cylinder>
          </geometry>
          <max_contacts>10</max_contacts>
          <surface>
            <bounce/>
            <friction>
              <ode/>
              <torsional>
                <ode/>
              </torsional>
            </friction>
            <contact>
              <ode/>
            </contact>
          </surface>
        </collision>
        <visual name='front_right_corner_frame2'>
          <pose frame=''>0.317574 0.54257 0.33 0 0 -0.7854</pose>
          <geometry>
            <box>
              <size>0.04 0.08 0.66</size>
            </box>
          </geometry>
          <material>
            <script>
              <uri>model://base_materials/wood/scripts/wood.material</uri>
              <name>base_materials/wood</name>
            </script>
          </material>
        </visual>
        <collision name='collision_front_right_corner_frame2'>
          <pose frame=''>0.317574 0.54257 0.33 0 0 -0.7854</pose>
          <geometry>
            <box>
              <size>0.04 0.08 0.66</size>
            </box>
          </geometry>
          <max_contacts>10</max_contacts>
          <surface>
            <bounce/>
            <friction>
              <ode/>
              <torsional>
                <ode/>
              </torsional>
            </friction>
            <contact>
              <ode/>
            </contact>
          </surface>
        </collision>
        <visual name='front_right_corner_frame3'>
          <pose frame=''>0.289289 0.51429 0.33 0 -0 0</pose>
          <geometry>
            <cylinder>
              <radius>0.02</radius>
              <length>0.66</length>
            </cylinder>
          </geometry>
          <material>
            <script>
              <uri>model://base_materials/wood/scripts/wood.material</uri>
              <name>base_materials/wood</name>
            </script>
          </material>
        </visual>
        <collision name='collision_front_right_corner_frame3'>
          <pose frame=''>0.289289 0.51429 0.33 0 -0 0</pose>
          <geometry>
            <cylinder>
              <radius>0.02</radius>
              <length>0.66</length>
            </cylinder>
          </geometry>
          <max_contacts>10</max_contacts>
          <surface>
            <bounce/>
            <friction>
              <ode/>
              <torsional>
                <ode/>
              </torsional>
            </friction>
            <contact>
              <ode/>
            </contact>
          </surface>
        </collision>
        <visual name='back_left_corner_frame1'>
          <pose frame=''>-0.345858 -0.57086 0.33 0 -0 0</pose>
          <geometry>
            <cylinder>
              <radius>0.02</radius>
              <length>0.66</length>
            </cylinder>
          </geometry>
          <material>
            <script>
              <uri>model://base_materials/wood/scripts/wood.material</uri>
              <name>base_materials/wood</name>
            </script>
          </material>
        </visual>
        <collision name='collision_back_left_corner_frame1'>
          <pose frame=''>-0.345858 -0.57086 0.33 0 -0 0</pose>
          <geometry>
            <cylinder>
              <radius>0.02</radius>
              <length>0.66</length>
            </cylinder>
          </geometry>
          <max_contacts>10</max_contacts>
          <surface>
            <bounce/>
            <friction>
              <ode/>
              <torsional>
                <ode/>
              </torsional>
            </friction>
            <contact>
              <ode/>
            </contact>
          </surface>
        </collision>
        <visual name='back_left_corner_frame2'>
          <pose frame=''>-0.317574 -0.54257 0.33 0 0 -0.7854</pose>
          <geometry>
            <box>
              <size>0.04 0.08 0.66</size>
            </box>
          </geometry>
          <material>
            <script>
              <uri>model://base_materials/wood/scripts/wood.material</uri>
              <name>base_materials/wood</name>
            </script>
          </material>
        </visual>
        <collision name='collision_back_left_corner_frame2'>
          <pose frame=''>-0.317574 -0.54257 0.33 0 0 -0.7854</pose>
          <geometry>
            <box>
              <size>0.04 0.08 0.66</size>
            </box>
          </geometry>
          <max_contacts>10</max_contacts>
          <surface>
            <bounce/>
            <friction>
              <ode/>
              <torsional>
                <ode/>
              </torsional>
            </friction>
            <contact>
              <ode/>
            </contact>
          </surface>
        </collision>
        <visual name='back_left_corner_frame3'>
          <pose frame=''>-0.289289 -0.51429 0.33 0 -0 0</pose>
          <geometry>
            <cylinder>
              <radius>0.02</radius>
              <length>0.66</length>
            </cylinder>
          </geometry>
          <material>
            <script>
              <uri>model://base_materials/wood/scripts/wood.material</uri>
              <name>base_materials/wood</name>
            </script>
          </material>
        </visual>
        <collision name='collision_back_left_corner_frame3'>
          <pose frame=''>-0.289289 -0.51429 0.33 0 -0 0</pose>
          <geometry>
            <cylinder>
              <radius>0.02</radius>
              <length>0.66</length>
            </cylinder>
          </geometry>
          <max_contacts>10</max_contacts>
          <surface>
            <bounce/>
            <friction>
              <ode/>
              <torsional>
                <ode/>
              </torsional>
            </friction>
            <contact>
              <ode/>
            </contact>
          </surface>
        </collision>
        <visual name='back_right_corner_frame1'>
          <pose frame=''>-0.345858 0.57086 0.33 0 -0 0</pose>
          <geometry>
            <cylinder>
              <radius>0.02</radius>
              <length>0.66</length>
            </cylinder>
          </geometry>
          <material>
            <script>
              <uri>model://base_materials/wood/scripts/wood.material</uri>
              <name>base_materials/wood</name>
            </script>
          </material>
        </visual>
        <collision name='collision_back_right_corner_frame1'>
          <pose frame=''>-0.345858 0.57086 0.33 0 -0 0</pose>
          <geometry>
            <cylinder>
              <radius>0.02</radius>
              <length>0.66</length>
            </cylinder>
          </geometry>
          <max_contacts>10</max_contacts>
          <surface>
            <bounce/>
            <friction>
              <ode/>
              <torsional>
                <ode/>
              </torsional>
            </friction>
            <contact>
              <ode/>
            </contact>
          </surface>
        </collision>
        <visual name='back_right_corner_frame2'>
          <pose frame=''>-0.317574 0.54257 0.33 0 -0 0.7854</pose>
          <geometry>
            <box>
              <size>0.04 0.08 0.66</size>
            </box>
          </geometry>
          <material>
            <script>
              <uri>model://base_materials/wood/scripts/wood.material</uri>
              <name>base_materials/wood</name>
            </script>
          </material>
        </visual>
        <collision name='collision_back_right_corner_frame2'>
          <pose frame=''>-0.317574 0.54257 0.33 0 -0 0.7854</pose>
          <geometry>
            <box>
              <size>0.04 0.08 0.66</size>
            </box>
          </geometry>
          <max_contacts>10</max_contacts>
          <surface>
            <bounce/>
            <friction>
              <ode/>
              <torsional>
                <ode/>
              </torsional>
            </friction>
            <contact>
              <ode/>
            </contact>
          </surface>
        </collision>
        <visual name='back_right_corner_frame3'>
          <pose frame=''>-0.289289 0.51429 0.33 0 -0 0</pose>
          <geometry>
            <cylinder>
              <radius>0.02</radius>
              <length>0.66</length>
            </cylinder>
          </geometry>
          <material>
            <script>
              <uri>model://base_materials/wood/scripts/wood.material</uri>
              <name>base_materials/wood</name>
            </script>
          </material>
        </visual>
        <collision name='collision_back_right_corner_frame3'>
          <pose frame=''>-0.289289 0.51429 0.33 0 -0 0</pose>
          <geometry>
            <cylinder>
              <radius>0.02</radius>
              <length>0.66</length>
            </cylinder>
          </geometry>
          <max_contacts>10</max_contacts>
          <surface>
            <bounce/>
            <friction>
              <ode/>
              <torsional>
                <ode/>
              </torsional>
            </friction>
            <contact>
              <ode/>
            </contact>
          </surface>
        </collision>
        <velocity_decay>
          <linear>0</linear>
          <angular>0</angular>
        </velocity_decay>
        <self_collide>0</self_collide>
        <kinematic>0</kinematic>
        <gravity>1</gravity>
      </link>
      <static>1</static>
      <pose frame=''>0.75977 -0.154467 0 0 -0 0</pose>
    </model>
    <model name='hsr_coke'>
      <link name='link'>
        <pose frame=''>0 0 0 0 -0 0</pose>
        <inertial>
          <mass>0.35</mass>
          <inertia>
            <ixx>0.001481</ixx>
            <ixy>0</ixy>
            <ixz>0</ixz>
            <iyy>0.001481</iyy>
            <iyz>0</iyz>
            <izz>0.000168</izz>
          </inertia>
        </inertial>
        <visual name='hsr_coke'>
          <pose frame=''>0 0 0 0 -0 0</pose>
          <geometry>
            <mesh>
              <uri>model://hsr_coke/meshes/hsr_coke.dae</uri>
              <scale>1 1 1</scale>
            </mesh>
          </geometry>
          <material/>
        </visual>
        <collision name='hsr_coke'>
          <pose frame=''>0 0 0 0 -0 0</pose>
          <geometry>
            <cylinder>
              <radius>0.033</radius>
              <length>0.1235</length>
            </cylinder>
          </geometry>
          <max_contacts>10</max_contacts>
          <surface>
            <bounce>
              <restitution_coefficient>0.2</restitution_coefficient>
              <threshold>0</threshold>
            </bounce>
            <friction>
              <ode/>
              <torsional>
                <ode/>
              </torsional>
            </friction>
            <contact>
              <ode>
                <max_vel>10</max_vel>
              </ode>
            </contact>
          </surface>
        </collision>
        <velocity_decay>
          <linear>0</linear>
          <angular>0</angular>
        </velocity_decay>
        <self_collide>0</self_collide>
        <kinematic>0</kinematic>
        <gravity>1</gravity>
      </link>
      <static>0</static>
      <pose frame=''>0.71909 -0.045027 0 0 -0 0</pose>
    </model>
    <model name='hsr_coke_0'>
      <link name='link'>
        <pose frame=''>0 0 0 0 -0 0</pose>
        <inertial>
          <mass>0.35</mass>
          <inertia>
            <ixx>0.001481</ixx>
            <ixy>0</ixy>
            <ixz>0</ixz>
            <iyy>0.001481</iyy>
            <iyz>0</iyz>
            <izz>0.000168</izz>
          </inertia>
        </inertial>
        <visual name='hsr_coke'>
          <pose frame=''>0 0 0 0 -0 0</pose>
          <geometry>
            <mesh>
              <uri>model://hsr_coke/meshes/hsr_coke.dae</uri>
              <scale>1 1 1</scale>
            </mesh>
          </geometry>
          <material/>
        </visual>
        <collision name='hsr_coke'>
          <pose frame=''>0 0 0 0 -0 0</pose>
          <geometry>
            <cylinder>
              <radius>0.033</radius>
              <length>0.1235</length>
            </cylinder>
          </geometry>
          <max_contacts>10</max_contacts>
          <surface>
            <bounce>
              <restitution_coefficient>0.2</restitution_coefficient>
              <threshold>0</threshold>
            </bounce>
            <friction>
              <ode/>
              <torsional>
                <ode/>
              </torsional>
            </friction>
            <contact>
              <ode>
                <max_vel>10</max_vel>
              </ode>
            </contact>
          </surface>
        </collision>
        <velocity_decay>
          <linear>0</linear>
          <angular>0</angular>
        </velocity_decay>
        <self_collide>0</self_collide>
        <kinematic>0</kinematic>
        <gravity>1</gravity>
      </link>
      <static>0</static>
      <pose frame=''>1.8108 -0.053953 0 0 -0 0</pose>
    </model>
    <state world_name='default'>
      <sim_time>316 560000000</sim_time>
      <real_time>823 734446541</real_time>
      <wall_time>1586105227 557122958</wall_time>
      <iterations>316560</iterations>
      <model name='ground_plane'>
        <pose frame=''>0 0 0 0 -0 0</pose>
        <scale>1 1 1</scale>
        <link name='link'>
          <pose frame=''>0 0 0 0 -0 0</pose>
          <velocity>0 0 0 0 -0 0</velocity>
          <acceleration>0 0 0 0 -0 0</acceleration>
          <wrench>0 0 0 0 -0 0</wrench>
        </link>
      </model>
      <model name='hsr_coke'>
        <pose frame=''>2.25347 -4.61656 0.033 1.5708 -0.003849 0.277742</pose>
        <scale>1 1 1</scale>
        <link name='link'>
          <pose frame=''>2.25347 -4.61656 0.033 1.5708 -0.003849 0.277742</pose>
          <velocity>0 0 0 0 -0 0</velocity>
          <acceleration>0 0 0 0 -0 0</acceleration>
          <wrench>0 0 0 0 -0 0</wrench>
        </link>
      </model>
      <model name='hsr_coke_0'>
        <pose frame=''>0.558231 0.143983 0.761748 2.5e-05 -1e-06 -1.6846</pose>
        <scale>1 1 1</scale>
        <link name='link'>
          <pose frame=''>0.558231 0.143983 0.761748 2.5e-05 -1e-06 -1.6846</pose>
          <velocity>0 0 0 0 -0 0</velocity>
          <acceleration>0 0 -9.8 0 -0 0</acceleration>
          <wrench>0 0 -3.43 0 -0 0</wrench>
        </link>
      </model>
      <model name='hsrb'>
        <pose frame=''>-0.188222 0.361519 -0.000108 1.3e-05 -6e-06 -0.122415</pose>
        <scale>1 1 1</scale>
        <link name='arm_flex_link'>
          <pose frame=''>-0.038755 0.421713 0.389895 1.5e-05 -2e-05 -0.122417</pose>
          <velocity>0.005008 -0.001678 -0.000798 -0.002721 -0.024006 -0.00885</velocity>
          <acceleration>5.38169 -3.58119 -1.53006 -2.17354 1.50439 -0.946277</acceleration>
          <wrench>7.20765 -4.79626 -2.04919 0 -0 0</wrench>
        </link>
        <link name='arm_lift_link'>
          <pose frame=''>-0.188224 0.361514 0.389895 1.6e-05 1e-06 -0.122417</pose>
          <velocity>0.004425 -0.000377 0.002897 0.003596 0.025933 -0.008924</velocity>
          <acceleration>6.30657 -1.96106 3.1401 -0.795649 0.699262 -2.16709</acceleration>
          <wrench>8.04605 -2.50196 4.0062 0 -0 0</wrench>
        </link>
        <link name='arm_roll_link'>
          <pose frame=''>-0.0338 0.421099 0.734895 2.1e-05 1.3e-05 -1.69246</pose>
          <velocity>-0.003268 -0.000628 -0.000611 -0.004771 -0.023539 -0.003955</velocity>
          <acceleration>-1.53581 -2.71436 -1.15818 -0.641678 -0.550368 2.21344</acceleration>
          <wrench>-0.380782 -0.672989 -0.287154 0 -0 0</wrench>
        </link>
        <link name='base_b_bumper_link'>
          <pose frame=''>-0.188063 0.36281 -0.000108 -1.4e-05 6e-06 3.01918</pose>
          <velocity>-0.006203 0.001046 -0.002414 0.004075 0.027597 -0.010051</velocity>
          <acceleration>-12.2147 1.53225 -4.96432 -1.68692 -1.48502 0.012296</acceleration>
          <wrench>-0.732882 0.091935 -0.297859 0 -0 0</wrench>
        </link>
        <link name='base_f_bumper_link'>
          <pose frame=''>-0.188222 0.361519 -0.000108 1.4e-05 -6e-06 -0.122415</pose>
          <velocity>-0.006217 0.001048 -0.002415 0.00408 0.027603 -0.010051</velocity>
          <acceleration>-12.2456 1.53609 -4.96607 -1.68492 -1.4975 0.013919</acceleration>
          <wrench>-0.734734 0.092165 -0.297964 0 -0 0</wrench>
        </link>
        <link name='base_footprint'>
          <pose frame=''>-0.188222 0.361519 -0.000108 1.3e-05 -6e-06 -0.122415</pose>
          <velocity>-0.006174 0.001043 -0.002393 0.003848 0.027405 -0.009979</velocity>
          <acceleration>-2.60468 0.757271 -3.50046 -1.49086 -1.23184 1.24329</acceleration>
          <wrench>-130.286 37.8787 -175.093 0 -0 0</wrench>
        </link>
        <link name='base_l_drive_wheel_link'>
          <pose frame=''>-0.281171 0.506952 0.039889 7e-06 0.308604 -0.122402</pose>
          <velocity>-0.01176 0.00136 0.001541 -0.03407 -0.294584 0.007555</velocity>
          <acceleration>-22.8675 2.63712 2.91207 3.07377 -0.791233 -1.24745</acceleration>
          <wrench>-4.5735 0.527423 0.582414 0 -0 0</wrench>
        </link>
        <link name='base_l_passive_wheel_x_frame'>
          <pose frame=''>-0.03313 0.397854 0.02993 -0.309045 -2.9e-05 -0.122404</pose>
          <velocity>-0.004349 0.001891 -0.015809 0.010085 0.032987 0.007193</velocity>
          <acceleration>-8.39566 2.61982 -31.6887 -1.42938 -0.371903 1.1484</acceleration>
          <wrench>-1.67913 0.523963 -6.33774 0 -0 0</wrench>
        </link>
        <link name='base_l_passive_wheel_y_frame'>
          <pose frame=''>-0.033132 0.397854 0.029954 -0.46502 0.825434 -0.475634</pose>
          <velocity>-0.003984 0.001838 -0.021672 0.015126 0.073459 -0.005827</velocity>
          <acceleration>-7.6733 2.50511 -43.4048 -2.06239 0.244941 0.688442</acceleration>
          <wrench>-1.53466 0.501022 -8.68096 0 -0 0</wrench>
        </link>
        <link name='base_l_passive_wheel_z_link'>
          <pose frame=''>-0.033139 0.397855 0.029977 0.916515 0.088353 1.62664</pose>
          <velocity>-0.002268 0.001591 -0.027508 0.000549 0.070917 -0.016889</velocity>
          <acceleration>-4.28436 1.96972 -55.0676 0.753299 -0.929702 1.94647</acceleration>
          <wrench>-0.856871 0.393944 -11.0135 0 -0 0</wrench>
        </link>
        <link name='base_r_drive_wheel_link'>
          <pose frame=''>-0.313649 0.242949 0.039888 7e-06 0.133632 -0.122405</pose>
          <velocity>-0.00853 0.000933 0.000743 -0.023405 -0.213786 0.007104</velocity>
          <acceleration>-17.2813 1.89258 1.31376 2.84767 0.708607 -2.14722</acceleration>
          <wrench>-3.45626 0.378517 0.262751 0 -0 0</wrench>
        </link>
        <link name='base_r_passive_wheel_x_frame'>
          <pose frame=''>-0.046561 0.288678 0.029928 -0.283705 -1.4e-05 -0.122403</pose>
          <velocity>-0.00329 0.0018 -0.015557 0.010666 0.028902 0.007968</velocity>
          <acceleration>-6.72484 2.48872 -31.1837 -2.88741 1.18647 2.7046</acceleration>
          <wrench>-1.34497 0.497743 -6.23674 0 -0 0</wrench>
        </link>
        <link name='base_r_passive_wheel_y_frame'>
          <pose frame=''>-0.046563 0.288678 0.029952 -0.43992 0.853592 -0.463289</pose>
          <velocity>-0.00295 0.00175 -0.021725 0.014728 0.061503 -0.001612</velocity>
          <acceleration>-6.07599 2.38034 -43.5091 0.394823 1.52463 1.8872</acceleration>
          <wrench>-1.2152 0.476068 -8.70183 0 -0 0</wrench>
        </link>
        <link name='base_r_passive_wheel_z_link'>
          <pose frame=''>-0.046569 0.288679 0.029977 0.770012 0.594588 1.14193</pose>
          <velocity>-0.001359 0.001518 -0.027864 0.000616 0.059471 -0.011979</velocity>
          <acceleration>-3.04327 1.87293 -55.7789 1.59193 -1.46766 1.5835</acceleration>
          <wrench>-0.608653 0.374586 -11.1558 0 -0 0</wrench>
        </link>
        <link name='base_roll_link'>
          <pose frame=''>-0.188223 0.361519 -0.000107 8e-06 -2.9e-05 -0.122403</pose>
          <velocity>-0.005947 0.001029 -0.002692 0.006026 0.033749 0.007973</velocity>
          <acceleration>-6.99552 0.415497 -4.18371 -0.274074 0.129866 2.42175</acceleration>
          <wrench>-71.6299 4.25443 -42.8387 0 -0 0</wrench>
        </link>
        <link name='hand_l_distal_link'>
          <pose frame=''>-0.028379 0.226165 0.706027 -3.08755 -1.57028 -1.72869</pose>
          <velocity>7.4e-05 0.000379 -4.9e-05 -3.7e-05 -0.000453 1.7e-05</velocity>
          <acceleration>0.069906 0.379305 -0.051209 -0.036467 -0.452327 0.016868</acceleration>
          <wrench>0.003337 0.018105 -0.002444 0 -0 0</wrench>
        </link>
        <link name='hand_l_mimic_distal_link'>
          <pose frame=''>-0.028379 0.226165 0.706027 -3.04044 -1.57028 -1.72877</pose>
          <velocity>7.5e-05 0.000403 -4.3e-05 -4e-05 -0.000454 1e-06</velocity>
          <acceleration>0.075177 0.402886 -0.042649 -0.040103 -0.454263 0.000889</acceleration>
          <wrench>0.000752 0.004029 -0.000426 0 -0 0</wrench>
        </link>
        <link name='hand_l_proximal_link'>
          <pose frame=''>-0.024405 0.296052 0.706064 -3.1138 -1.57028 -1.67706</pose>
          <velocity>-0.002409 0.000474 -5.3e-05 -0.000225 9.8e-05 0.002543</velocity>
          <acceleration>-1.14155 0.145525 -0.101693 -0.486515 1.23709 0.002434</acceleration>
          <wrench>-0.011416 0.001455 -0.001017 0 -0 0</wrench>
        </link>
        <link name='hand_l_spring_proximal_link'>
          <pose frame=''>-0.024405 0.296052 0.706064 -3.00662 -1.57028 -1.76256</pose>
          <velocity>-0.002391 0.000467 -2.3e-05 -0.000168 -0.001225 0.036028</velocity>
          <acceleration>-0.702841 0.059477 -0.047877 0.484729 -1.30989 1.70517</acceleration>
          <wrench>-0.030636 0.002593 -0.002087 0 -0 0</wrench>
        </link>
        <link name='hand_motor_dummy_link'>
          <pose frame=''>-0.050849 0.281646 0.722807 -3.114 -1.57028 -1.67687</pose>
          <velocity>-0.002464 0.000373 -9.3e-05 -0.000198 0.000101 -1e-06</velocity>
          <acceleration>-2.46356 0.372854 -0.092519 -0.198026 0.100928 -0.000693</acceleration>
          <wrench>-0.024636 0.003729 -0.000925 0 -0 0</wrench>
        </link>
        <link name='hand_r_distal_link'>
          <pose frame=''>-0.084856 0.233003 0.706029 -3.14112 -1.57031 -1.7104</pose>
          <velocity>-0.002661 0.000585 -3.6e-05 0.000164 -0.000395 0.001294</velocity>
          <acceleration>-2.63381 0.592793 -0.037091 0.164041 -0.395075 1.28841</acceleration>
          <wrench>-0.081456 0.018333 -0.001147 0 -0 0</wrench>
        </link>
        <link name='hand_r_mimic_distal_link'>
          <pose frame=''>-0.084856 0.233003 0.706029 3.11176 -1.57031 -1.71053</pose>
          <velocity>-0.002638 0.000604 -3.2e-05 0.000162 -0.000394 0.005163</velocity>
          <acceleration>-2.63838 0.60377 -0.031666 0.161811 -0.393948 -1.11972</acceleration>
          <wrench>-0.026384 0.006038 -0.000317 0 -0 0</wrench>
        </link>
        <link name='hand_r_proximal_link'>
          <pose frame=''>-0.073043 0.301999 0.706065 3.07859 -1.57028 -1.67734</pose>
          <velocity>-0.002299 0.000528 -5.6e-05 -0.000217 0.000109 0.010082</velocity>
          <acceleration>-1.06517 -0.341932 -0.056395 -0.473528 1.25656 0.526066</acceleration>
          <wrench>-0.010652 -0.003419 -0.000564 0 -0 0</wrench>
        </link>
        <link name='hand_r_spring_proximal_link'>
          <pose frame=''>-0.073043 0.301999 0.706066 -3.05256 -1.57031 -1.82938</pose>
          <velocity>-0.002243 0.000486 -3.4e-05 6.7e-05 -0.000344 -0.007576</velocity>
          <acceleration>-0.955759 -0.421933 -0.018488 -2.41456 0.712408 -2.70967</acceleration>
          <wrench>-0.042011 -0.018546 -0.000813 0 -0 0</wrench>
        </link>
        <link name='head_pan_link'>
          <pose frame=''>-0.188223 0.361509 0.768039 1.2e-05 9e-06 -0.122411</pose>
          <velocity>0.013298 -0.001826 0.000928 0.004496 0.022337 0.00205</velocity>
          <acceleration>25.2357 -3.90279 1.76038 0.428446 0.099429 -1.90837</acceleration>
          <wrench>14.4324 -2.23202 1.00677 0 -0 0</wrench>
        </link>
        <link name='head_tilt_link'>
          <pose frame=''>-0.16837 0.359067 0.768037 1e-05 -0.000995 -0.122421</pose>
          <velocity>0.012168 -0.001604 0.001061 -0.009216 -0.070641 0.00483</velocity>
          <acceleration>7.85062 -1.96012 -5.44815 -0.929247 -1.45546 2.60777</acceleration>
          <wrench>17.3012 -4.3197 -12.0066 0 -0 0</wrench>
        </link>
        <link name='torso_lift_link'>
          <pose frame=''>-0.188225 0.361509 0.768039 1.3e-05 1e-06 -0.122418</pose>
          <velocity>0.01378 -0.001742 0.000889 0.003602 0.025362 -0.009212</velocity>
          <acceleration>13.0438 -0.89463 4.37148 0.825678 0.049717 -1.58434</acceleration>
          <wrench>44.62 -3.06033 14.9539 0 -0 0</wrench>
        </link>
        <link name='wrist_flex_link'>
          <pose frame=''>-0.0338 0.421099 0.734895 3.13397 1.57028 1.44152</pose>
          <velocity>-0.003287 -0.000659 -0.000616 -0.002894 -0.024533 -0.002209</velocity>
          <acceleration>-4.17718 -2.19885 -1.39034 -1.16678 1.32764 1.26028</acceleration>
          <wrench>-2.8456 -1.49791 -0.947134 0 -0 0</wrench>
        </link>
        <link name='wrist_ft_sensor_frame'>
          <pose frame=''>-0.042718 0.348145 0.734842 0.020782 1.57028 1.46992</pose>
          <velocity>-0.002375 0.000371 -0.000104 -0.000188 9.9e-05 -0.001254</velocity>
          <acceleration>-1.49915 -0.315841 -0.172987 -0.394416 1.30854 3.09048</acceleration>
          <wrench>-1.41174 -0.297425 -0.162901 0 -0 0</wrench>
        </link>
        <link name='wrist_ft_sensor_mount_link'>
          <pose frame=''>-0.033798 0.421103 0.734875 -3.12062 1.57028 1.47011</pose>
          <velocity>-0.001823 0.000804 6.4e-05 -4e-05 8.4e-05 -0.002359</velocity>
          <acceleration>-1.52652 0.665493 0.137942 -0.126361 1.19824 1.35949</acceleration>
          <wrench>-0.015265 0.006655 0.001379 0 -0 0</wrench>
        </link>
      </model>
      <model name='kitchen_table'>
        <pose frame=''>0.75977 -0.154467 0 0 -0 0</pose>
        <scale>1 1 1</scale>
        <link name='link'>
          <pose frame=''>0.75977 -0.154467 0 0 -0 0</pose>
          <velocity>0 0 0 0 -0 0</velocity>
          <acceleration>0 0 0 0 -0 0</acceleration>
          <wrench>0 0 0 0 -0 0</wrench>
        </link>
      </model>
      <light name='sun'>
        <pose frame=''>0 0 10 0 -0 0</pose>
      </light>
    </state>
    <gui fullscreen='0'>
      <camera name='user_camera'>
        <pose frame=''>-0.151632 -0.230838 1.35389 0 0.687349 0.5089</pose>
        <view_controller>orbit</view_controller>
        <projection_type>perspective</projection_type>
      </camera>
    </gui>
  </world>
</sdf>
