<sdf version='1.6'>
  <world name='default'>
    <light name='sun' type='directional'>
      <cast_shadows>1</cast_shadows>
      <pose frame=''>0 0 10 0 -0 0</pose>
      <diffuse>0.8 0.8 0.8 1</diffuse>
      <specular>0.2 0.2 0.2 1</specular>
      <attenuation>
        <range>1000</range>
        <constant>0.9</constant>
        <linear>0.01</linear>
        <quadratic>0.001</quadratic>
      </attenuation>
      <direction>-0.5 0.1 -0.9</direction>
    </light>
    <model name='ground_plane'>
      <static>1</static>
      <link name='link'>
        <collision name='collision'>
          <geometry>
            <plane>
              <normal>0 0 1</normal>
              <size>100 100</size>
            </plane>
          </geometry>
          <surface>
            <friction>
              <ode>
                <mu>100</mu>
                <mu2>50</mu2>
              </ode>
              <torsional>
                <ode/>
              </torsional>
            </friction>
            <contact>
              <ode/>
            </contact>
            <bounce/>
          </surface>
          <max_contacts>10</max_contacts>
        </collision>
        <visual name='visual'>
          <cast_shadows>0</cast_shadows>
          <geometry>
            <plane>
              <normal>0 0 1</normal>
              <size>100 100</size>
            </plane>
          </geometry>
          <material>
            <script>
              <uri>file://media/materials/scripts/gazebo.material</uri>
              <name>Gazebo/Grey</name>
            </script>
          </material>
        </visual>
        <self_collide>0</self_collide>
        <enable_wind>0</enable_wind>
        <kinematic>0</kinematic>
      </link>
    </model>
    <gravity>0 0 -9.8</gravity>
    <magnetic_field>6e-06 2.3e-05 -4.2e-05</magnetic_field>
    <atmosphere type='adiabatic'/>
    <physics name='default_physics' default='0' type='ode'>
      <max_step_size>0.001</max_step_size>
      <real_time_factor>1</real_time_factor>
      <real_time_update_rate>1000</real_time_update_rate>
    </physics>
    <scene>
      <ambient>0.4 0.4 0.4 1</ambient>
      <background>0.7 0.7 0.7 1</background>
      <shadows>1</shadows>
    </scene>
    <wind/>
    <spherical_coordinates>
      <surface_model>EARTH_WGS84</surface_model>
      <latitude_deg>0</latitude_deg>
      <longitude_deg>0</longitude_deg>
      <elevation>0</elevation>
      <heading_deg>0</heading_deg>
    </spherical_coordinates>
    <model name='multiple_rooms_walls'>
      <pose frame=''>-0.740066 0.490066 0 0 -0 0</pose>
      <link name='Wall_12'>
        <collision name='Wall_12_Collision'>
          <geometry>
            <box>
              <size>4.65 0.15 0.6</size>
            </box>
          </geometry>
          <pose frame=''>0 0 0.3 0 -0 0</pose>
          <max_contacts>10</max_contacts>
          <surface>
            <contact>
              <ode/>
            </contact>
            <bounce/>
            <friction>
              <torsional>
                <ode/>
              </torsional>
              <ode/>
            </friction>
          </surface>
        </collision>
        <visual name='Wall_12_Visual'>
          <pose frame=''>0 0 0.3 0 -0 0</pose>
          <geometry>
            <box>
              <size>4.65 0.15 0.6</size>
            </box>
          </geometry>
          <material>
            <script>
              <uri>file://media/materials/scripts/gazebo.material</uri>
              <name>Gazebo/Grey</name>
            </script>
            <ambient>1 1 1 1</ambient>
          </material>
          <meta>
            <layer>0</layer>
          </meta>
        </visual>
        <pose frame=''>-1.50993 -4.49007 0 0 -0 0</pose>
        <self_collide>0</self_collide>
        <enable_wind>0</enable_wind>
        <kinematic>0</kinematic>
      </link>
      <link name='Wall_14'>
        <collision name='Wall_14_Collision'>
          <geometry>
            <box>
              <size>3.31228 0.15 0.6</size>
            </box>
          </geometry>
          <pose frame=''>0 0 0.3 0 -0 0</pose>
          <max_contacts>10</max_contacts>
          <surface>
            <contact>
              <ode/>
            </contact>
            <bounce/>
            <friction>
              <torsional>
                <ode/>
              </torsional>
              <ode/>
            </friction>
          </surface>
        </collision>
        <visual name='Wall_14_Visual'>
          <pose frame=''>0 0 0.3 0 -0 0</pose>
          <geometry>
            <box>
              <size>3.31228 0.15 0.6</size>
            </box>
          </geometry>
          <material>
            <script>
              <uri>file://media/materials/scripts/gazebo.material</uri>
              <name>Gazebo/Grey</name>
            </script>
            <ambient>1 1 1 1</ambient>
          </material>
          <meta>
            <layer>0</layer>
          </meta>
        </visual>
        <pose frame=''>2.24007 -3.99007 0 0 -0 0.321751</pose>
        <self_collide>0</self_collide>
        <enable_wind>0</enable_wind>
        <kinematic>0</kinematic>
      </link>
      <link name='Wall_16'>
        <collision name='Wall_16_Collision'>
          <geometry>
            <box>
              <size>8.15 0.15 0.6</size>
            </box>
          </geometry>
          <pose frame=''>0 0 0.3 0 -0 0</pose>
          <max_contacts>10</max_contacts>
          <surface>
            <contact>
              <ode/>
            </contact>
            <bounce/>
            <friction>
              <torsional>
                <ode/>
              </torsional>
              <ode/>
            </friction>
          </surface>
        </collision>
        <visual name='Wall_16_Visual'>
          <pose frame=''>0 0 0.3 0 -0 0</pose>
          <geometry>
            <box>
              <size>8.15 0.15 0.6</size>
            </box>
          </geometry>
          <material>
            <script>
              <uri>file://media/materials/scripts/gazebo.material</uri>
              <name>Gazebo/Grey</name>
            </script>
            <ambient>1 1 1 1</ambient>
          </material>
          <meta>
            <layer>0</layer>
          </meta>
        </visual>
        <pose frame=''>3.74007 0.509934 0 0 -0 1.5708</pose>
        <self_collide>0</self_collide>
        <enable_wind>0</enable_wind>
        <kinematic>0</kinematic>
      </link>
      <link name='Wall_25'>
        <collision name='Wall_25_Collision'>
          <geometry>
            <box>
              <size>4.65 0.15 0.6</size>
            </box>
          </geometry>
          <pose frame=''>0 0 0.3 0 -0 0</pose>
          <max_contacts>10</max_contacts>
          <surface>
            <contact>
              <ode/>
            </contact>
            <bounce/>
            <friction>
              <torsional>
                <ode/>
              </torsional>
              <ode/>
            </friction>
          </surface>
        </collision>
        <visual name='Wall_25_Visual'>
          <pose frame=''>0 0 0.3 0 -0 0</pose>
          <geometry>
            <box>
              <size>4.65 0.15 0.6</size>
            </box>
          </geometry>
          <material>
            <script>
              <uri>file://media/materials/scripts/gazebo.material</uri>
              <name>Gazebo/Grey</name>
            </script>
            <ambient>1 1 1 1</ambient>
          </material>
          <meta>
            <layer>0</layer>
          </meta>
        </visual>
        <pose frame=''>0.740066 0.259934 0 0 -0 1.5708</pose>
        <self_collide>0</self_collide>
        <enable_wind>0</enable_wind>
        <kinematic>0</kinematic>
      </link>
      <link name='Wall_27'>
        <collision name='Wall_27_Collision'>
          <geometry>
            <box>
              <size>0.65 0.15 0.6</size>
            </box>
          </geometry>
          <pose frame=''>0 0 0.3 0 -0 0</pose>
          <max_contacts>10</max_contacts>
          <surface>
            <contact>
              <ode/>
            </contact>
            <bounce/>
            <friction>
              <torsional>
                <ode/>
              </torsional>
              <ode/>
            </friction>
          </surface>
        </collision>
        <visual name='Wall_27_Visual'>
          <pose frame=''>0 0 0.3 0 -0 0</pose>
          <geometry>
            <box>
              <size>0.65 0.15 0.6</size>
            </box>
          </geometry>
          <material>
            <script>
              <uri>file://media/materials/scripts/gazebo.material</uri>
              <name>Gazebo/Grey</name>
            </script>
            <ambient>1 1 1 1</ambient>
          </material>
          <meta>
            <layer>0</layer>
          </meta>
        </visual>
        <pose frame=''>0.490066 2.50993 0 0 -0 3.14159</pose>
        <self_collide>0</self_collide>
        <enable_wind>0</enable_wind>
        <kinematic>0</kinematic>
      </link>
      <link name='Wall_29'>
        <collision name='Wall_29_Collision'>
          <geometry>
            <box>
              <size>1.65 0.15 0.6</size>
            </box>
          </geometry>
          <pose frame=''>0 0 0.3 0 -0 0</pose>
          <max_contacts>10</max_contacts>
          <surface>
            <contact>
              <ode/>
            </contact>
            <bounce/>
            <friction>
              <torsional>
                <ode/>
              </torsional>
              <ode/>
            </friction>
          </surface>
        </collision>
        <visual name='Wall_29_Visual'>
          <pose frame=''>0 0 0.3 0 -0 0</pose>
          <geometry>
            <box>
              <size>1.65 0.15 0.6</size>
            </box>
          </geometry>
          <material>
            <script>
              <uri>file://media/materials/scripts/gazebo.material</uri>
              <name>Gazebo/Grey</name>
            </script>
            <ambient>1 1 1 1</ambient>
          </material>
          <meta>
            <layer>0</layer>
          </meta>
        </visual>
        <pose frame=''>-1.50993 2.50993 0 0 -0 3.14159</pose>
        <self_collide>0</self_collide>
        <enable_wind>0</enable_wind>
        <kinematic>0</kinematic>
      </link>
      <link name='Wall_31'>
        <collision name='Wall_31_Collision'>
          <geometry>
            <box>
              <size>1.15 0.15 0.6</size>
            </box>
          </geometry>
          <pose frame=''>0 0 0.3 0 -0 0</pose>
          <max_contacts>10</max_contacts>
          <surface>
            <contact>
              <ode/>
            </contact>
            <bounce/>
            <friction>
              <torsional>
                <ode/>
              </torsional>
              <ode/>
            </friction>
          </surface>
        </collision>
        <visual name='Wall_31_Visual'>
          <pose frame=''>0 0 0.3 0 -0 0</pose>
          <geometry>
            <box>
              <size>1.15 0.15 0.6</size>
            </box>
          </geometry>
          <material>
            <script>
              <uri>file://media/materials/scripts/gazebo.material</uri>
              <name>Gazebo/Grey</name>
            </script>
            <ambient>1 1 1 1</ambient>
          </material>
          <meta>
            <layer>0</layer>
          </meta>
        </visual>
        <pose frame=''>-2.25993 2.00993 0 0 -0 -1.5708</pose>
        <self_collide>0</self_collide>
        <enable_wind>0</enable_wind>
        <kinematic>0</kinematic>
      </link>
      <link name='Wall_34'>
        <collision name='Wall_34_Collision'>
          <geometry>
            <box>
              <size>2.65 0.15 0.6</size>
            </box>
          </geometry>
          <pose frame=''>0 0 0.3 0 -0 0</pose>
          <max_contacts>10</max_contacts>
          <surface>
            <contact>
              <ode/>
            </contact>
            <bounce/>
            <friction>
              <torsional>
                <ode/>
              </torsional>
              <ode/>
            </friction>
          </surface>
        </collision>
        <visual name='Wall_34_Visual'>
          <pose frame=''>0 0 0.3 0 -0 0</pose>
          <geometry>
            <box>
              <size>2.65 0.15 0.6</size>
            </box>
          </geometry>
          <material>
            <script>
              <uri>file://media/materials/scripts/gazebo.material</uri>
              <name>Gazebo/Grey</name>
            </script>
            <ambient>1 1 1 1</ambient>
          </material>
          <meta>
            <layer>0</layer>
          </meta>
        </visual>
        <pose frame=''>-2.25993 -0.740066 0 0 -0 -1.5708</pose>
        <self_collide>0</self_collide>
        <enable_wind>0</enable_wind>
        <kinematic>0</kinematic>
      </link>
      <link name='Wall_36'>
        <collision name='Wall_36_Collision'>
          <geometry>
            <box>
              <size>3.15 0.15 0.6</size>
            </box>
          </geometry>
          <pose frame=''>0 0 0.3 0 -0 0</pose>
          <max_contacts>10</max_contacts>
          <surface>
            <contact>
              <ode/>
            </contact>
            <bounce/>
            <friction>
              <torsional>
                <ode/>
              </torsional>
              <ode/>
            </friction>
          </surface>
        </collision>
        <visual name='Wall_36_Visual'>
          <pose frame=''>0 0 0.3 0 -0 0</pose>
          <geometry>
            <box>
              <size>3.15 0.15 0.6</size>
            </box>
          </geometry>
          <material>
            <script>
              <uri>file://media/materials/scripts/gazebo.material</uri>
              <name>Gazebo/Grey</name>
            </script>
            <ambient>1 1 1 1</ambient>
          </material>
          <meta>
            <layer>0</layer>
          </meta>
        </visual>
        <pose frame=''>-0.759934 -0.490066 0 0 -0 0</pose>
        <self_collide>0</self_collide>
        <enable_wind>0</enable_wind>
        <kinematic>0</kinematic>
      </link>
      <link name='Wall_38'>
        <collision name='Wall_38_Collision'>
          <geometry>
            <box>
              <size>1.65 0.15 0.6</size>
            </box>
          </geometry>
          <pose frame=''>0 0 0.3 0 -0 0</pose>
          <max_contacts>10</max_contacts>
          <surface>
            <contact>
              <ode/>
            </contact>
            <bounce/>
            <friction>
              <torsional>
                <ode/>
              </torsional>
              <ode/>
            </friction>
          </surface>
        </collision>
        <visual name='Wall_38_Visual'>
          <pose frame=''>0 0 0.3 0 -0 0</pose>
          <geometry>
            <box>
              <size>1.65 0.15 0.6</size>
            </box>
          </geometry>
          <material>
            <script>
              <uri>file://media/materials/scripts/gazebo.material</uri>
              <name>Gazebo/Grey</name>
            </script>
            <ambient>1 1 1 1</ambient>
          </material>
          <meta>
            <layer>0</layer>
          </meta>
        </visual>
        <pose frame=''>-2.25993 -3.74007 0 0 -0 -1.5708</pose>
        <self_collide>0</self_collide>
        <enable_wind>0</enable_wind>
        <kinematic>0</kinematic>
      </link>
      <link name='Wall_4'>
        <collision name='Wall_4_Collision'>
          <geometry>
            <box>
              <size>7.65 0.15 0.6</size>
            </box>
          </geometry>
          <pose frame=''>0 0 0.3 0 -0 0</pose>
          <max_contacts>10</max_contacts>
          <surface>
            <contact>
              <ode/>
            </contact>
            <bounce/>
            <friction>
              <torsional>
                <ode/>
              </torsional>
              <ode/>
            </friction>
          </surface>
        </collision>
        <visual name='Wall_4_Visual'>
          <pose frame=''>0 0 0.3 0 -0 0</pose>
          <geometry>
            <box>
              <size>7.65 0.15 0.6</size>
            </box>
          </geometry>
          <material>
            <script>
              <uri>file://media/materials/scripts/gazebo.material</uri>
              <name>Gazebo/Grey</name>
            </script>
            <ambient>1 1 1 1</ambient>
          </material>
          <meta>
            <layer>0</layer>
          </meta>
        </visual>
        <pose frame=''>-0.009934 4.50993 0 0 -0 0</pose>
        <self_collide>0</self_collide>
        <enable_wind>0</enable_wind>
        <kinematic>0</kinematic>
      </link>
      <link name='Wall_40'>
        <collision name='Wall_40_Collision'>
          <geometry>
            <box>
              <size>1.65 0.15 0.6</size>
            </box>
          </geometry>
          <pose frame=''>0 0 0.3 0 -0 0</pose>
          <max_contacts>10</max_contacts>
          <surface>
            <contact>
              <ode/>
            </contact>
            <bounce/>
            <friction>
              <torsional>
                <ode/>
              </torsional>
              <ode/>
            </friction>
          </surface>
        </collision>
        <visual name='Wall_40_Visual'>
          <pose frame=''>0 0 0.3 0 -0 0</pose>
          <geometry>
            <box>
              <size>1.65 0.15 0.6</size>
            </box>
          </geometry>
          <material>
            <script>
              <uri>file://media/materials/scripts/gazebo.material</uri>
              <name>Gazebo/Grey</name>
            </script>
            <ambient>1 1 1 1</ambient>
          </material>
          <meta>
            <layer>0</layer>
          </meta>
        </visual>
        <pose frame=''>0.740066 -3.74007 0 0 -0 -1.5708</pose>
        <self_collide>0</self_collide>
        <enable_wind>0</enable_wind>
        <kinematic>0</kinematic>
      </link>
      <link name='Wall_6'>
        <collision name='Wall_6_Collision'>
          <geometry>
            <box>
              <size>0.65 0.15 0.6</size>
            </box>
          </geometry>
          <pose frame=''>0 0 0.3 0 -0 0</pose>
          <max_contacts>10</max_contacts>
          <surface>
            <contact>
              <ode/>
            </contact>
            <bounce/>
            <friction>
              <torsional>
                <ode/>
              </torsional>
              <ode/>
            </friction>
          </surface>
        </collision>
        <visual name='Wall_6_Visual'>
          <pose frame=''>0 0 0.3 0 -0 0</pose>
          <geometry>
            <box>
              <size>0.65 0.15 0.6</size>
            </box>
          </geometry>
          <material>
            <script>
              <uri>file://media/materials/scripts/gazebo.material</uri>
              <name>Gazebo/Grey</name>
            </script>
            <ambient>1 1 1 1</ambient>
          </material>
          <meta>
            <layer>0</layer>
          </meta>
        </visual>
        <pose frame=''>-3.75993 4.25993 0 0 -0 -1.5708</pose>
        <self_collide>0</self_collide>
        <enable_wind>0</enable_wind>
        <kinematic>0</kinematic>
      </link>
      <link name='Wall_8'>
        <collision name='Wall_8_Collision'>
          <geometry>
            <box>
              <size>7.65 0.15 0.6</size>
            </box>
          </geometry>
          <pose frame=''>0 0 0.3 0 -0 0</pose>
          <max_contacts>10</max_contacts>
          <surface>
            <contact>
              <ode/>
            </contact>
            <bounce/>
            <friction>
              <torsional>
                <ode/>
              </torsional>
              <ode/>
            </friction>
          </surface>
        </collision>
        <visual name='Wall_8_Visual'>
          <pose frame=''>0 0 0.3 0 -0 0</pose>
          <geometry>
            <box>
              <size>7.65 0.15 0.6</size>
            </box>
          </geometry>
          <material>
            <script>
              <uri>file://media/materials/scripts/gazebo.material</uri>
              <name>Gazebo/Grey</name>
            </script>
            <ambient>1 1 1 1</ambient>
          </material>
          <meta>
            <layer>0</layer>
          </meta>
        </visual>
        <pose frame=''>-3.75993 -0.740066 0 0 -0 -1.5708</pose>
        <self_collide>0</self_collide>
        <enable_wind>0</enable_wind>
        <kinematic>0</kinematic>
      </link>
      <static>1</static>
    </model>
    <model name='openable_hinged_door_z_normally'>
      <joint name='frame_to_world_joint' type='revolute'>
        <parent>world</parent>
        <child>frame</child>
        <pose frame=''>0 -0.45 0 0 -0 0</pose>
        <axis>
          <xyz>0 0 1</xyz>
          <limit>
            <lower>0</lower>
            <upper>0</upper>
          </limit>
          <use_parent_model_frame>1</use_parent_model_frame>
          <dynamics>
            <spring_reference>0</spring_reference>
            <spring_stiffness>0</spring_stiffness>
          </dynamics>
        </axis>
      </joint>
      <link name='frame'>
        <pose frame=''>0 0.45 0 0 -0 0</pose>
        <visual name='left_frame'>
          <pose frame=''>0 -0.4325 1.025 0 -0 0</pose>
          <geometry>
            <box>
              <size>0.055 0.035 2.05</size>
            </box>
          </geometry>
          <material>
            <script>
              <uri>model://base_materials/color/scripts</uri>
              <name>hsr_color/white</name>
            </script>
          </material>
        </visual>
        <collision name='collision_left_frame'>
          <pose frame=''>0 -0.4325 1.025 0 -0 0</pose>
          <geometry>
            <box>
              <size>0.055 0.035 2.05</size>
            </box>
          </geometry>
          <max_contacts>10</max_contacts>
          <surface>
            <bounce/>
            <friction>
              <ode/>
              <torsional>
                <ode/>
              </torsional>
            </friction>
            <contact>
              <ode/>
            </contact>
          </surface>
        </collision>
        <visual name='top_frame'>
          <pose frame=''>0 0 2.07 0 -0 0</pose>
          <geometry>
            <box>
              <size>0.055 0.9 0.04</size>
            </box>
          </geometry>
          <material>
            <script>
              <uri>model://base_materials/color/scripts</uri>
              <name>hsr_color/white</name>
            </script>
          </material>
        </visual>
        <collision name='collision_top_frame'>
          <pose frame=''>0 0 2.07 0 -0 0</pose>
          <geometry>
            <box>
              <size>0.055 0.9 0.04</size>
            </box>
          </geometry>
          <max_contacts>10</max_contacts>
          <surface>
            <bounce/>
            <friction>
              <ode/>
              <torsional>
                <ode/>
              </torsional>
            </friction>
            <contact>
              <ode/>
            </contact>
          </surface>
        </collision>
        <velocity_decay>
          <linear>0</linear>
          <angular>0</angular>
        </velocity_decay>
        <self_collide>0</self_collide>
        <kinematic>0</kinematic>
        <gravity>1</gravity>
        <inertial>
          <pose frame=''>0 0 0 0 -0 0</pose>
          <inertia>
            <ixx>1</ixx>
            <ixy>0</ixy>
            <ixz>0</ixz>
            <iyy>1</iyy>
            <iyz>0</iyz>
            <izz>1</izz>
          </inertia>
          <mass>1</mass>
        </inertial>
        <enable_wind>0</enable_wind>
      </link>
      <link name='door'>
        <pose frame=''>0 0 0 0 -0 0</pose>
        <inertial>
          <mass>50</mass>
          <inertia>
            <ixx>14.2</ixx>
            <ixy>0</ixy>
            <ixz>0</ixz>
            <iyy>17.2</iyy>
            <iyz>0</iyz>
            <izz>3</izz>
          </inertia>
          <pose frame=''>0 0 0 0 -0 0</pose>
        </inertial>
        <visual name='door'>
          <pose frame=''>0 0.45 1.05 0 -0 0</pose>
          <geometry>
            <box>
              <size>0.055 0.83 2</size>
            </box>
          </geometry>
          <material>
            <script>
              <uri>model://base_materials/wood/scripts/wood.material</uri>
              <name>base_materials/wood</name>
            </script>
          </material>
        </visual>
        <collision name='collision_door'>
          <pose frame=''>0 0.45 1.05 0 -0 0</pose>
          <geometry>
            <box>
              <size>0.055 0.83 2</size>
            </box>
          </geometry>
          <max_contacts>10</max_contacts>
          <surface>
            <bounce/>
            <friction>
              <ode/>
              <torsional>
                <ode/>
              </torsional>
            </friction>
            <contact>
              <ode/>
            </contact>
          </surface>
        </collision>
        <visual name='handle_lock1'>
          <pose frame=''>0 0.785 1.03 0 -0 0</pose>
          <geometry>
            <box>
              <size>0.075 0.005 0.04</size>
            </box>
          </geometry>
          <material>
            <script>
              <uri>model://base_materials/color/scripts</uri>
              <name>hsr_color/white</name>
            </script>
          </material>
        </visual>
        <visual name='handle_lock2'>
          <pose frame=''>0 0.785 1.03 3.14159 1.57079 3.14159</pose>
          <geometry>
            <cylinder>
              <radius>0.025</radius>
              <length>0.065</length>
            </cylinder>
          </geometry>
          <material>
            <script>
              <uri>model://base_materials/color/scripts</uri>
              <name>hsr_color/white</name>
            </script>
          </material>
        </visual>
        <velocity_decay>
          <linear>0</linear>
          <angular>0</angular>
        </velocity_decay>
        <self_collide>0</self_collide>
        <kinematic>0</kinematic>
        <gravity>1</gravity>
        <enable_wind>0</enable_wind>
      </link>
      <link name='handles'>
        <pose frame=''>0 0.8 0.93 -3.14159 0.001593 -1.57159</pose>
        <visual name='handle1_visual'>
          <pose frame=''>0.015 0 0 -1.57 0 0</pose>
          <geometry>
            <mesh>
              <uri>model://openable_hinged_door_z_normally/meshes/door_handle_small.dae</uri>
            </mesh>
          </geometry>
        </visual>
        <collision name='handle1_collision'>
          <pose frame=''>0.015 0 0 -1.57 0 0</pose>
          <geometry>
            <mesh>
              <uri>model://openable_hinged_door_z_normally/meshes/door_handle_small.dae</uri>
            </mesh>
          </geometry>
          <max_contacts>10</max_contacts>
          <surface>
            <contact>
              <ode/>
            </contact>
            <bounce/>
            <friction>
              <torsional>
                <ode/>
              </torsional>
              <ode/>
            </friction>
          </surface>
        </collision>
        <self_collide>0</self_collide>
        <inertial>
          <pose frame=''>0 0 0 0 -0 0</pose>
          <inertia>
            <ixx>1</ixx>
            <ixy>0</ixy>
            <ixz>0</ixz>
            <iyy>1</iyy>
            <iyz>0</iyz>
            <izz>1</izz>
          </inertia>
          <mass>1</mass>
        </inertial>
        <enable_wind>0</enable_wind>
        <kinematic>0</kinematic>
      </link>
      <joint name='handle' type='revolute'>
        <parent>door</parent>
        <child>handles</child>
        <pose frame=''>0.013 0 0 0 -0 0</pose>
        <axis>
          <xyz>1 0 0</xyz>
          <limit>
            <lower>0</lower>
            <upper>0.52</upper>
          </limit>
          <dynamics>
            <damping>0.1</damping>
            <spring_stiffness>0.3</spring_stiffness>
            <spring_reference>0</spring_reference>
          </dynamics>
          <use_parent_model_frame>1</use_parent_model_frame>
        </axis>
        <physics>
          <ode>
            <cfm_damping>1</cfm_damping>
            <limit>
              <cfm>0</cfm>
              <erp>0.2</erp>
            </limit>
          </ode>
        </physics>
      </joint>
      <joint name='hinge' type='revolute'>
        <parent>frame</parent>
        <child>door</child>
        <axis>
          <xyz>0 0 1</xyz>
          <limit>
            <lower>0</lower>
            <upper>1.58</upper>
            <effort>-1</effort>
            <velocity>-1</velocity>
          </limit>
          <dynamics>
            <damping>1</damping>
            <friction>1</friction>
            <spring_reference>0</spring_reference>
            <spring_stiffness>0</spring_stiffness>
          </dynamics>
          <use_parent_model_frame>1</use_parent_model_frame>
        </axis>
        <physics>
          <ode>
            <cfm_damping>1</cfm_damping>
            <limit>
              <cfm>0</cfm>
              <erp>0.2</erp>
            </limit>
          </ode>
        </physics>
      </joint>
      <static>0</static>
      <pose frame=''>-5.67685 4.96006 0 0 -0 0</pose>
    </model>
    <state world_name='default'>
      <sim_time>360 737000000</sim_time>
      <real_time>362 703849367</real_time>
      <wall_time>1629577271 437442768</wall_time>
      <iterations>360737</iterations>
      <model name='ground_plane'>
        <pose frame=''>0 0 0 0 -0 0</pose>
        <scale>1 1 1</scale>
        <link name='link'>
          <pose frame=''>0 0 0 0 -0 0</pose>
          <velocity>0 0 0 0 -0 0</velocity>
          <acceleration>0 0 0 0 -0 0</acceleration>
          <wrench>0 0 0 0 -0 0</wrench>
        </link>
      </model>
      <model name='multiple_rooms_walls'>
        <pose frame=''>-0.740066 0.490066 0 0 -0 0</pose>
        <scale>1 1 1</scale>
        <link name='Wall_12'>
          <pose frame=''>-2.25 -4 0 0 -0 0</pose>
          <velocity>0 0 0 0 -0 0</velocity>
          <acceleration>0 0 0 0 -0 0</acceleration>
          <wrench>0 0 0 0 -0 0</wrench>
        </link>
        <link name='Wall_14'>
          <pose frame=''>1.5 -3.5 0 0 -0 0.321751</pose>
          <velocity>0 0 0 0 -0 0</velocity>
          <acceleration>0 0 0 0 -0 0</acceleration>
          <wrench>0 0 0 0 -0 0</wrench>
        </link>
        <link name='Wall_16'>
          <pose frame=''>3 1 0 0 -0 1.5708</pose>
          <velocity>0 0 0 0 -0 0</velocity>
          <acceleration>0 0 0 0 -0 0</acceleration>
          <wrench>0 0 0 0 -0 0</wrench>
        </link>
        <link name='Wall_25'>
          <pose frame=''>0 0.75 0 0 -0 1.5708</pose>
          <velocity>0 0 0 0 -0 0</velocity>
          <acceleration>0 0 0 0 -0 0</acceleration>
          <wrench>0 0 0 0 -0 0</wrench>
        </link>
        <link name='Wall_27'>
          <pose frame=''>-0.25 3 0 0 -0 3.14159</pose>
          <velocity>0 0 0 0 -0 0</velocity>
          <acceleration>0 0 0 0 -0 0</acceleration>
          <wrench>0 0 0 0 -0 0</wrench>
        </link>
        <link name='Wall_29'>
          <pose frame=''>-2.25 3 0 0 -0 3.14159</pose>
          <velocity>0 0 0 0 -0 0</velocity>
          <acceleration>0 0 0 0 -0 0</acceleration>
          <wrench>0 0 0 0 -0 0</wrench>
        </link>
        <link name='Wall_31'>
          <pose frame=''>-3 2.5 0 0 0 -1.5708</pose>
          <velocity>0 0 0 0 -0 0</velocity>
          <acceleration>0 0 0 0 -0 0</acceleration>
          <wrench>0 0 0 0 -0 0</wrench>
        </link>
        <link name='Wall_34'>
          <pose frame=''>-3 -0.25 0 0 0 -1.5708</pose>
          <velocity>0 0 0 0 -0 0</velocity>
          <acceleration>0 0 0 0 -0 0</acceleration>
          <wrench>0 0 0 0 -0 0</wrench>
        </link>
        <link name='Wall_36'>
          <pose frame=''>-1.5 -0 0 0 -0 0</pose>
          <velocity>0 0 0 0 -0 0</velocity>
          <acceleration>0 0 0 0 -0 0</acceleration>
          <wrench>0 0 0 0 -0 0</wrench>
        </link>
        <link name='Wall_38'>
          <pose frame=''>-3 -3.25 0 0 0 -1.5708</pose>
          <velocity>0 0 0 0 -0 0</velocity>
          <acceleration>0 0 0 0 -0 0</acceleration>
          <wrench>0 0 0 0 -0 0</wrench>
        </link>
        <link name='Wall_4'>
          <pose frame=''>-0.75 5 0 0 -0 0</pose>
          <velocity>0 0 0 0 -0 0</velocity>
          <acceleration>0 0 0 0 -0 0</acceleration>
          <wrench>0 0 0 0 -0 0</wrench>
        </link>
        <link name='Wall_40'>
          <pose frame=''>0 -3.25 0 0 0 -1.5708</pose>
          <velocity>0 0 0 0 -0 0</velocity>
          <acceleration>0 0 0 0 -0 0</acceleration>
          <wrench>0 0 0 0 -0 0</wrench>
        </link>
        <link name='Wall_6'>
          <pose frame=''>-4.5 4.75 0 0 0 -1.5708</pose>
          <velocity>0 0 0 0 -0 0</velocity>
          <acceleration>0 0 0 0 -0 0</acceleration>
          <wrench>0 0 0 0 -0 0</wrench>
        </link>
        <link name='Wall_8'>
          <pose frame=''>-4.5 -0.25 0 0 0 -1.5708</pose>
          <velocity>0 0 0 0 -0 0</velocity>
          <acceleration>0 0 0 0 -0 0</acceleration>
          <wrench>0 0 0 0 -0 0</wrench>
        </link>
      </model>
      <model name='openable_hinged_door_z_normally'>
        <pose frame=''>-4.5 3.55 5e-06 0 -0 0</pose>
        <scale>1 1 1</scale>
        <link name='door'>
          <pose frame=''>-4.5 3.55 -7e-06 8e-06 -0 0.000143</pose>
          <velocity>-6e-06 -0 3e-06 -1.9e-05 -0 -0.000109</velocity>
          <acceleration>-0.01172 -0.000742 0.006471 -0.034881 -0.000506 -0.217671</acceleration>
          <wrench>-0.585994 -0.037091 0.323526 0 -0 0</wrench>
        </link>
        <link name='frame'>
          <pose frame=''>-4.5 4 5e-06 0 -0 0</pose>
          <velocity>7.2e-05 0 -1.2e-05 5e-06 -0 -0.000154</velocity>
          <acceleration>0.14369 0.000321 -0.02237 0.008393 0.000224 -0.307956</acceleration>
          <wrench>0.14369 0.000321 -0.02237 0 -0 0</wrench>
        </link>
        <link name='handles'>
          <pose frame=''>-4.50011 4.34999 0.93 -3.14159 0.001601 -1.57145</pose>
          <velocity>8.1e-05 1.7e-05 -1.2e-05 -6.9e-05 -0 -0.000109</velocity>
          <acceleration>0.161611 0.031209 -0.022118 -0.127116 -0.000567 -0.217651</acceleration>
          <wrench>0.161611 0.031209 -0.022118 0 -0 0</wrench>
        </link>
      </model>
      <model name='openable_hinged_door_z_normally_0'>
        <pose frame=''>-3 1.05 0 0 -0 0</pose>
        <scale>1 1 1</scale>
        <link name='door'>
          <pose frame=''>-3 1.05 0 0 -0 0</pose>
          <velocity>0 0 0 0 -0 0</velocity>
          <acceleration>0 0 0 0 -0 0</acceleration>
          <wrench>0 0 0 0 -0 0</wrench>
        </link>
        <link name='frame'>
          <pose frame=''>-3 1.5 0 0 -0 0</pose>
          <velocity>0 0 0 0 -0 0</velocity>
          <acceleration>0 0 0 0 -0 0</acceleration>
          <wrench>0 0 0 0 -0 0</wrench>
        </link>
        <link name='handles'>
          <pose frame=''>-3 1.85 0.93 -3.14159 0.001593 -1.57159</pose>
          <velocity>0 0 0 0 -0 0</velocity>
          <acceleration>0 0 0 0 -0 0</acceleration>
          <wrench>0 0 0 0 -0 0</wrench>
        </link>
      </model>
      <model name='openable_hinged_door_z_normally_1'>
        <pose frame=''>-3 -2.45 0 0 -0 0</pose>
        <scale>1 1 1</scale>
        <link name='door'>
          <pose frame=''>-3 -2.45 0 0 -0 0</pose>
          <velocity>0 0 0 0 -0 0</velocity>
          <acceleration>0 0 0 0 -0 0</acceleration>
          <wrench>0 0 0 0 -0 0</wrench>
        </link>
        <link name='frame'>
          <pose frame=''>-3 -2 0 0 -0 0</pose>
          <velocity>0 0 0 0 -0 0</velocity>
          <acceleration>0 0 0 0 -0 0</acceleration>
          <wrench>0 0 0 0 -0 0</wrench>
        </link>
        <link name='handles'>
          <pose frame=''>-3 -1.65 0.93 -3.14159 0.001593 -1.57159</pose>
          <velocity>0 0 0 0 -0 0</velocity>
          <acceleration>0 0 0 0 -0 0</acceleration>
          <wrench>0 0 0 0 -0 0</wrench>
        </link>
      </model>
      <model name='openable_hinged_door_z_normally_2'>
        <pose frame=''>-0.55 3 0 0 -0 1.57</pose>
        <scale>1 1 1</scale>
        <link name='door'>
          <pose frame=''>-0.55 3 0 0 -0 1.57</pose>
          <velocity>0 0 0 0 -0 0</velocity>
          <acceleration>0 0 0 0 -0 0</acceleration>
          <wrench>0 0 0 0 -0 0</wrench>
        </link>
        <link name='frame'>
          <pose frame=''>-1 3.00036 0 0 -0 1.57</pose>
          <velocity>0 0 0 0 -0 0</velocity>
          <acceleration>0 0 0 0 -0 0</acceleration>
          <wrench>0 0 0 0 -0 0</wrench>
        </link>
        <link name='handles'>
          <pose frame=''>-1.35 3.00064 0.93 -3.14159 0.001593 -0.00159</pose>
          <velocity>0 0 0 0 -0 0</velocity>
          <acceleration>0 0 0 0 -0 0</acceleration>
          <wrench>0 0 0 0 -0 0</wrench>
        </link>
      </model>
      <light name='sun'>
        <pose frame=''>0 0 10 0 -0 0</pose>
      </light>
    </state>
    <model name='openable_hinged_door_z_normally_0'>
      <joint name='frame_to_world_joint' type='revolute'>
        <parent>world</parent>
        <child>frame</child>
        <pose frame=''>0 -0.45 0 0 -0 0</pose>
        <axis>
          <xyz>0 0 1</xyz>
          <limit>
            <lower>0</lower>
            <upper>0</upper>
          </limit>
          <use_parent_model_frame>1</use_parent_model_frame>
          <dynamics>
            <spring_reference>0</spring_reference>
            <spring_stiffness>0</spring_stiffness>
          </dynamics>
        </axis>
      </joint>
      <link name='frame'>
        <pose frame=''>0 0.45 0 0 -0 0</pose>
        <visual name='left_frame'>
          <pose frame=''>0 -0.4325 1.025 0 -0 0</pose>
          <geometry>
            <box>
              <size>0.055 0.035 2.05</size>
            </box>
          </geometry>
          <material>
            <script>
              <uri>model://base_materials/color/scripts</uri>
              <name>hsr_color/white</name>
            </script>
          </material>
        </visual>
        <collision name='collision_left_frame'>
          <pose frame=''>0 -0.4325 1.025 0 -0 0</pose>
          <geometry>
            <box>
              <size>0.055 0.035 2.05</size>
            </box>
          </geometry>
          <max_contacts>10</max_contacts>
          <surface>
            <bounce/>
            <friction>
              <ode/>
              <torsional>
                <ode/>
              </torsional>
            </friction>
            <contact>
              <ode/>
            </contact>
          </surface>
        </collision>
        <visual name='top_frame'>
          <pose frame=''>0 0 2.07 0 -0 0</pose>
          <geometry>
            <box>
              <size>0.055 0.9 0.04</size>
            </box>
          </geometry>
          <material>
            <script>
              <uri>model://base_materials/color/scripts</uri>
              <name>hsr_color/white</name>
            </script>
          </material>
        </visual>
        <collision name='collision_top_frame'>
          <pose frame=''>0 0 2.07 0 -0 0</pose>
          <geometry>
            <box>
              <size>0.055 0.9 0.04</size>
            </box>
          </geometry>
          <max_contacts>10</max_contacts>
          <surface>
            <bounce/>
            <friction>
              <ode/>
              <torsional>
                <ode/>
              </torsional>
            </friction>
            <contact>
              <ode/>
            </contact>
          </surface>
        </collision>
        <velocity_decay>
          <linear>0</linear>
          <angular>0</angular>
        </velocity_decay>
        <self_collide>0</self_collide>
        <kinematic>0</kinematic>
        <gravity>1</gravity>
        <inertial>
          <pose frame=''>0 0 0 0 -0 0</pose>
          <inertia>
            <ixx>1</ixx>
            <ixy>0</ixy>
            <ixz>0</ixz>
            <iyy>1</iyy>
            <iyz>0</iyz>
            <izz>1</izz>
          </inertia>
          <mass>1</mass>
        </inertial>
        <enable_wind>0</enable_wind>
      </link>
      <link name='door'>
        <pose frame=''>0 0 0 0 -0 0</pose>
        <inertial>
          <mass>50</mass>
          <inertia>
            <ixx>14.2</ixx>
            <ixy>0</ixy>
            <ixz>0</ixz>
            <iyy>17.2</iyy>
            <iyz>0</iyz>
            <izz>3</izz>
          </inertia>
          <pose frame=''>0 0 0 0 -0 0</pose>
        </inertial>
        <visual name='door'>
          <pose frame=''>0 0.45 1.05 0 -0 0</pose>
          <geometry>
            <box>
              <size>0.055 0.83 2</size>
            </box>
          </geometry>
          <material>
            <script>
              <uri>model://base_materials/wood/scripts/wood.material</uri>
              <name>base_materials/wood</name>
            </script>
          </material>
        </visual>
        <collision name='collision_door'>
          <pose frame=''>0 0.45 1.05 0 -0 0</pose>
          <geometry>
            <box>
              <size>0.055 0.83 2</size>
            </box>
          </geometry>
          <max_contacts>10</max_contacts>
          <surface>
            <bounce/>
            <friction>
              <ode/>
              <torsional>
                <ode/>
              </torsional>
            </friction>
            <contact>
              <ode/>
            </contact>
          </surface>
        </collision>
        <visual name='handle_lock1'>
          <pose frame=''>0 0.785 1.03 0 -0 0</pose>
          <geometry>
            <box>
              <size>0.075 0.005 0.04</size>
            </box>
          </geometry>
          <material>
            <script>
              <uri>model://base_materials/color/scripts</uri>
              <name>hsr_color/white</name>
            </script>
          </material>
        </visual>
        <visual name='handle_lock2'>
          <pose frame=''>0 0.785 1.03 3.14159 1.57079 3.14159</pose>
          <geometry>
            <cylinder>
              <radius>0.025</radius>
              <length>0.065</length>
            </cylinder>
          </geometry>
          <material>
            <script>
              <uri>model://base_materials/color/scripts</uri>
              <name>hsr_color/white</name>
            </script>
          </material>
        </visual>
        <velocity_decay>
          <linear>0</linear>
          <angular>0</angular>
        </velocity_decay>
        <self_collide>0</self_collide>
        <kinematic>0</kinematic>
        <gravity>1</gravity>
        <enable_wind>0</enable_wind>
      </link>
      <link name='handles'>
        <pose frame=''>0 0.8 0.93 -3.14159 0.001593 -1.57159</pose>
        <visual name='handle1_visual'>
          <pose frame=''>0.015 0 0 -1.57 0 0</pose>
          <geometry>
            <mesh>
              <uri>model://openable_hinged_door_z_normally/meshes/door_handle_small.dae</uri>
            </mesh>
          </geometry>
        </visual>
        <collision name='handle1_collision'>
          <pose frame=''>0.015 0 0 -1.57 0 0</pose>
          <geometry>
            <mesh>
              <uri>model://openable_hinged_door_z_normally/meshes/door_handle_small.dae</uri>
            </mesh>
          </geometry>
          <max_contacts>10</max_contacts>
          <surface>
            <contact>
              <ode/>
            </contact>
            <bounce/>
            <friction>
              <torsional>
                <ode/>
              </torsional>
              <ode/>
            </friction>
          </surface>
        </collision>
        <self_collide>0</self_collide>
        <inertial>
          <pose frame=''>0 0 0 0 -0 0</pose>
          <inertia>
            <ixx>1</ixx>
            <ixy>0</ixy>
            <ixz>0</ixz>
            <iyy>1</iyy>
            <iyz>0</iyz>
            <izz>1</izz>
          </inertia>
          <mass>1</mass>
        </inertial>
        <enable_wind>0</enable_wind>
        <kinematic>0</kinematic>
      </link>
      <joint name='handle' type='revolute'>
        <parent>door</parent>
        <child>handles</child>
        <pose frame=''>0.013 0 0 0 -0 0</pose>
        <axis>
          <xyz>1 0 0</xyz>
          <limit>
            <lower>0</lower>
            <upper>0.52</upper>
          </limit>
          <dynamics>
            <damping>0.1</damping>
            <spring_stiffness>0.3</spring_stiffness>
            <spring_reference>0</spring_reference>
          </dynamics>
          <use_parent_model_frame>1</use_parent_model_frame>
        </axis>
        <physics>
          <ode>
            <cfm_damping>1</cfm_damping>
            <limit>
              <cfm>0</cfm>
              <erp>0.2</erp>
            </limit>
          </ode>
        </physics>
      </joint>
      <joint name='hinge' type='revolute'>
        <parent>frame</parent>
        <child>door</child>
        <axis>
          <xyz>0 0 1</xyz>
          <limit>
            <lower>0</lower>
            <upper>1.58</upper>
            <effort>-1</effort>
            <velocity>-1</velocity>
          </limit>
          <dynamics>
            <damping>1</damping>
            <friction>1</friction>
            <spring_reference>0</spring_reference>
            <spring_stiffness>0</spring_stiffness>
          </dynamics>
          <use_parent_model_frame>1</use_parent_model_frame>
        </axis>
        <physics>
          <ode>
            <cfm_damping>1</cfm_damping>
            <limit>
              <cfm>0</cfm>
              <erp>0.2</erp>
            </limit>
          </ode>
        </physics>
      </joint>
      <static>0</static>
      <pose frame=''>-3.19798 5.49307 0 0 -0 0</pose>
    </model>
    <model name='openable_hinged_door_z_normally_1'>
      <joint name='frame_to_world_joint' type='revolute'>
        <parent>world</parent>
        <child>frame</child>
        <pose frame=''>0 -0.45 0 0 -0 0</pose>
        <axis>
          <xyz>0 0 1</xyz>
          <limit>
            <lower>0</lower>
            <upper>0</upper>
          </limit>
          <use_parent_model_frame>1</use_parent_model_frame>
          <dynamics>
            <spring_reference>0</spring_reference>
            <spring_stiffness>0</spring_stiffness>
          </dynamics>
        </axis>
      </joint>
      <link name='frame'>
        <pose frame=''>0 0.45 0 0 -0 0</pose>
        <visual name='left_frame'>
          <pose frame=''>0 -0.4325 1.025 0 -0 0</pose>
          <geometry>
            <box>
              <size>0.055 0.035 2.05</size>
            </box>
          </geometry>
          <material>
            <script>
              <uri>model://base_materials/color/scripts</uri>
              <name>hsr_color/white</name>
            </script>
          </material>
        </visual>
        <collision name='collision_left_frame'>
          <pose frame=''>0 -0.4325 1.025 0 -0 0</pose>
          <geometry>
            <box>
              <size>0.055 0.035 2.05</size>
            </box>
          </geometry>
          <max_contacts>10</max_contacts>
          <surface>
            <bounce/>
            <friction>
              <ode/>
              <torsional>
                <ode/>
              </torsional>
            </friction>
            <contact>
              <ode/>
            </contact>
          </surface>
        </collision>
        <visual name='top_frame'>
          <pose frame=''>0 0 2.07 0 -0 0</pose>
          <geometry>
            <box>
              <size>0.055 0.9 0.04</size>
            </box>
          </geometry>
          <material>
            <script>
              <uri>model://base_materials/color/scripts</uri>
              <name>hsr_color/white</name>
            </script>
          </material>
        </visual>
        <collision name='collision_top_frame'>
          <pose frame=''>0 0 2.07 0 -0 0</pose>
          <geometry>
            <box>
              <size>0.055 0.9 0.04</size>
            </box>
          </geometry>
          <max_contacts>10</max_contacts>
          <surface>
            <bounce/>
            <friction>
              <ode/>
              <torsional>
                <ode/>
              </torsional>
            </friction>
            <contact>
              <ode/>
            </contact>
          </surface>
        </collision>
        <velocity_decay>
          <linear>0</linear>
          <angular>0</angular>
        </velocity_decay>
        <self_collide>0</self_collide>
        <kinematic>0</kinematic>
        <gravity>1</gravity>
        <inertial>
          <pose frame=''>0 0 0 0 -0 0</pose>
          <inertia>
            <ixx>1</ixx>
            <ixy>0</ixy>
            <ixz>0</ixz>
            <iyy>1</iyy>
            <iyz>0</iyz>
            <izz>1</izz>
          </inertia>
          <mass>1</mass>
        </inertial>
        <enable_wind>0</enable_wind>
      </link>
      <link name='door'>
        <pose frame=''>0 0 0 0 -0 0</pose>
        <inertial>
          <mass>50</mass>
          <inertia>
            <ixx>14.2</ixx>
            <ixy>0</ixy>
            <ixz>0</ixz>
            <iyy>17.2</iyy>
            <iyz>0</iyz>
            <izz>3</izz>
          </inertia>
          <pose frame=''>0 0 0 0 -0 0</pose>
        </inertial>
        <visual name='door'>
          <pose frame=''>0 0.45 1.05 0 -0 0</pose>
          <geometry>
            <box>
              <size>0.055 0.83 2</size>
            </box>
          </geometry>
          <material>
            <script>
              <uri>model://base_materials/wood/scripts/wood.material</uri>
              <name>base_materials/wood</name>
            </script>
          </material>
        </visual>
        <collision name='collision_door'>
          <pose frame=''>0 0.45 1.05 0 -0 0</pose>
          <geometry>
            <box>
              <size>0.055 0.83 2</size>
            </box>
          </geometry>
          <max_contacts>10</max_contacts>
          <surface>
            <bounce/>
            <friction>
              <ode/>
              <torsional>
                <ode/>
              </torsional>
            </friction>
            <contact>
              <ode/>
            </contact>
          </surface>
        </collision>
        <visual name='handle_lock1'>
          <pose frame=''>0 0.785 1.03 0 -0 0</pose>
          <geometry>
            <box>
              <size>0.075 0.005 0.04</size>
            </box>
          </geometry>
          <material>
            <script>
              <uri>model://base_materials/color/scripts</uri>
              <name>hsr_color/white</name>
            </script>
          </material>
        </visual>
        <visual name='handle_lock2'>
          <pose frame=''>0 0.785 1.03 3.14159 1.57079 3.14159</pose>
          <geometry>
            <cylinder>
              <radius>0.025</radius>
              <length>0.065</length>
            </cylinder>
          </geometry>
          <material>
            <script>
              <uri>model://base_materials/color/scripts</uri>
              <name>hsr_color/white</name>
            </script>
          </material>
        </visual>
        <velocity_decay>
          <linear>0</linear>
          <angular>0</angular>
        </velocity_decay>
        <self_collide>0</self_collide>
        <kinematic>0</kinematic>
        <gravity>1</gravity>
        <enable_wind>0</enable_wind>
      </link>
      <link name='handles'>
        <pose frame=''>0 0.8 0.93 -3.14159 0.001593 -1.57159</pose>
        <visual name='handle1_visual'>
          <pose frame=''>0.015 0 0 -1.57 0 0</pose>
          <geometry>
            <mesh>
              <uri>model://openable_hinged_door_z_normally/meshes/door_handle_small.dae</uri>
            </mesh>
          </geometry>
        </visual>
        <collision name='handle1_collision'>
          <pose frame=''>0.015 0 0 -1.57 0 0</pose>
          <geometry>
            <mesh>
              <uri>model://openable_hinged_door_z_normally/meshes/door_handle_small.dae</uri>
            </mesh>
          </geometry>
          <max_contacts>10</max_contacts>
          <surface>
            <contact>
              <ode/>
            </contact>
            <bounce/>
            <friction>
              <torsional>
                <ode/>
              </torsional>
              <ode/>
            </friction>
          </surface>
        </collision>
        <self_collide>0</self_collide>
        <inertial>
          <pose frame=''>0 0 0 0 -0 0</pose>
          <inertia>
            <ixx>1</ixx>
            <ixy>0</ixy>
            <ixz>0</ixz>
            <iyy>1</iyy>
            <iyz>0</iyz>
            <izz>1</izz>
          </inertia>
          <mass>1</mass>
        </inertial>
        <enable_wind>0</enable_wind>
        <kinematic>0</kinematic>
      </link>
      <joint name='handle' type='revolute'>
        <parent>door</parent>
        <child>handles</child>
        <pose frame=''>0.013 0 0 0 -0 0</pose>
        <axis>
          <xyz>1 0 0</xyz>
          <limit>
            <lower>0</lower>
            <upper>0.52</upper>
          </limit>
          <dynamics>
            <damping>0.1</damping>
            <spring_stiffness>0.3</spring_stiffness>
            <spring_reference>0</spring_reference>
          </dynamics>
          <use_parent_model_frame>1</use_parent_model_frame>
        </axis>
        <physics>
          <ode>
            <cfm_damping>1</cfm_damping>
            <limit>
              <cfm>0</cfm>
              <erp>0.2</erp>
            </limit>
          </ode>
        </physics>
      </joint>
      <joint name='hinge' type='revolute'>
        <parent>frame</parent>
        <child>door</child>
        <axis>
          <xyz>0 0 1</xyz>
          <limit>
            <lower>0</lower>
            <upper>1.58</upper>
            <effort>-1</effort>
            <velocity>-1</velocity>
          </limit>
          <dynamics>
            <damping>1</damping>
            <friction>1</friction>
            <spring_reference>0</spring_reference>
            <spring_stiffness>0</spring_stiffness>
          </dynamics>
          <use_parent_model_frame>1</use_parent_model_frame>
        </axis>
        <physics>
          <ode>
            <cfm_damping>1</cfm_damping>
            <limit>
              <cfm>0</cfm>
              <erp>0.2</erp>
            </limit>
          </ode>
        </physics>
      </joint>
      <static>0</static>
      <pose frame=''>-2.86675 -2.45168 0 0 -0 0</pose>
    </model>
    <model name='openable_hinged_door_z_normally_2'>
      <joint name='frame_to_world_joint' type='revolute'>
        <parent>world</parent>
        <child>frame</child>
        <pose frame=''>0 -0.45 0 0 -0 0</pose>
        <axis>
          <xyz>0 0 1</xyz>
          <limit>
            <lower>0</lower>
            <upper>0</upper>
          </limit>
          <use_parent_model_frame>1</use_parent_model_frame>
          <dynamics>
            <spring_reference>0</spring_reference>
            <spring_stiffness>0</spring_stiffness>
          </dynamics>
        </axis>
      </joint>
      <link name='frame'>
        <pose frame=''>0 0.45 0 0 -0 0</pose>
        <visual name='left_frame'>
          <pose frame=''>0 -0.4325 1.025 0 -0 0</pose>
          <geometry>
            <box>
              <size>0.055 0.035 2.05</size>
            </box>
          </geometry>
          <material>
            <script>
              <uri>model://base_materials/color/scripts</uri>
              <name>hsr_color/white</name>
            </script>
          </material>
        </visual>
        <collision name='collision_left_frame'>
          <pose frame=''>0 -0.4325 1.025 0 -0 0</pose>
          <geometry>
            <box>
              <size>0.055 0.035 2.05</size>
            </box>
          </geometry>
          <max_contacts>10</max_contacts>
          <surface>
            <bounce/>
            <friction>
              <ode/>
              <torsional>
                <ode/>
              </torsional>
            </friction>
            <contact>
              <ode/>
            </contact>
          </surface>
        </collision>
        <visual name='top_frame'>
          <pose frame=''>0 0 2.07 0 -0 0</pose>
          <geometry>
            <box>
              <size>0.055 0.9 0.04</size>
            </box>
          </geometry>
          <material>
            <script>
              <uri>model://base_materials/color/scripts</uri>
              <name>hsr_color/white</name>
            </script>
          </material>
        </visual>
        <collision name='collision_top_frame'>
          <pose frame=''>0 0 2.07 0 -0 0</pose>
          <geometry>
            <box>
              <size>0.055 0.9 0.04</size>
            </box>
          </geometry>
          <max_contacts>10</max_contacts>
          <surface>
            <bounce/>
            <friction>
              <ode/>
              <torsional>
                <ode/>
              </torsional>
            </friction>
            <contact>
              <ode/>
            </contact>
          </surface>
        </collision>
        <velocity_decay>
          <linear>0</linear>
          <angular>0</angular>
        </velocity_decay>
        <self_collide>0</self_collide>
        <kinematic>0</kinematic>
        <gravity>1</gravity>
        <inertial>
          <pose frame=''>0 0 0 0 -0 0</pose>
          <inertia>
            <ixx>1</ixx>
            <ixy>0</ixy>
            <ixz>0</ixz>
            <iyy>1</iyy>
            <iyz>0</iyz>
            <izz>1</izz>
          </inertia>
          <mass>1</mass>
        </inertial>
        <enable_wind>0</enable_wind>
      </link>
      <link name='door'>
        <pose frame=''>0 0 0 0 -0 0</pose>
        <inertial>
          <mass>50</mass>
          <inertia>
            <ixx>14.2</ixx>
            <ixy>0</ixy>
            <ixz>0</ixz>
            <iyy>17.2</iyy>
            <iyz>0</iyz>
            <izz>3</izz>
          </inertia>
          <pose frame=''>0 0 0 0 -0 0</pose>
        </inertial>
        <visual name='door'>
          <pose frame=''>0 0.45 1.05 0 -0 0</pose>
          <geometry>
            <box>
              <size>0.055 0.83 2</size>
            </box>
          </geometry>
          <material>
            <script>
              <uri>model://base_materials/wood/scripts/wood.material</uri>
              <name>base_materials/wood</name>
            </script>
          </material>
        </visual>
        <collision name='collision_door'>
          <pose frame=''>0 0.45 1.05 0 -0 0</pose>
          <geometry>
            <box>
              <size>0.055 0.83 2</size>
            </box>
          </geometry>
          <max_contacts>10</max_contacts>
          <surface>
            <bounce/>
            <friction>
              <ode/>
              <torsional>
                <ode/>
              </torsional>
            </friction>
            <contact>
              <ode/>
            </contact>
          </surface>
        </collision>
        <visual name='handle_lock1'>
          <pose frame=''>0 0.785 1.03 0 -0 0</pose>
          <geometry>
            <box>
              <size>0.075 0.005 0.04</size>
            </box>
          </geometry>
          <material>
            <script>
              <uri>model://base_materials/color/scripts</uri>
              <name>hsr_color/white</name>
            </script>
          </material>
        </visual>
        <visual name='handle_lock2'>
          <pose frame=''>0 0.785 1.03 3.14159 1.57079 3.14159</pose>
          <geometry>
            <cylinder>
              <radius>0.025</radius>
              <length>0.065</length>
            </cylinder>
          </geometry>
          <material>
            <script>
              <uri>model://base_materials/color/scripts</uri>
              <name>hsr_color/white</name>
            </script>
          </material>
        </visual>
        <velocity_decay>
          <linear>0</linear>
          <angular>0</angular>
        </velocity_decay>
        <self_collide>0</self_collide>
        <kinematic>0</kinematic>
        <gravity>1</gravity>
        <enable_wind>0</enable_wind>
      </link>
      <link name='handles'>
        <pose frame=''>0 0.8 0.93 -3.14159 0.001593 -1.57159</pose>
        <visual name='handle1_visual'>
          <pose frame=''>0.015 0 0 -1.57 0 0</pose>
          <geometry>
            <mesh>
              <uri>model://openable_hinged_door_z_normally/meshes/door_handle_small.dae</uri>
            </mesh>
          </geometry>
        </visual>
        <collision name='handle1_collision'>
          <pose frame=''>0.015 0 0 -1.57 0 0</pose>
          <geometry>
            <mesh>
              <uri>model://openable_hinged_door_z_normally/meshes/door_handle_small.dae</uri>
            </mesh>
          </geometry>
          <max_contacts>10</max_contacts>
          <surface>
            <contact>
              <ode/>
            </contact>
            <bounce/>
            <friction>
              <torsional>
                <ode/>
              </torsional>
              <ode/>
            </friction>
          </surface>
        </collision>
        <self_collide>0</self_collide>
        <inertial>
          <pose frame=''>0 0 0 0 -0 0</pose>
          <inertia>
            <ixx>1</ixx>
            <ixy>0</ixy>
            <ixz>0</ixz>
            <iyy>1</iyy>
            <iyz>0</iyz>
            <izz>1</izz>
          </inertia>
          <mass>1</mass>
        </inertial>
        <enable_wind>0</enable_wind>
        <kinematic>0</kinematic>
      </link>
      <joint name='handle' type='revolute'>
        <parent>door</parent>
        <child>handles</child>
        <pose frame=''>0.013 0 0 0 -0 0</pose>
        <axis>
          <xyz>1 0 0</xyz>
          <limit>
            <lower>0</lower>
            <upper>0.52</upper>
          </limit>
          <dynamics>
            <damping>0.1</damping>
            <spring_stiffness>0.3</spring_stiffness>
            <spring_reference>0</spring_reference>
          </dynamics>
          <use_parent_model_frame>1</use_parent_model_frame>
        </axis>
        <physics>
          <ode>
            <cfm_damping>1</cfm_damping>
            <limit>
              <cfm>0</cfm>
              <erp>0.2</erp>
            </limit>
          </ode>
        </physics>
      </joint>
      <joint name='hinge' type='revolute'>
        <parent>frame</parent>
        <child>door</child>
        <axis>
          <xyz>0 0 1</xyz>
          <limit>
            <lower>0</lower>
            <upper>1.58</upper>
            <effort>-1</effort>
            <velocity>-1</velocity>
          </limit>
          <dynamics>
            <damping>1</damping>
            <friction>1</friction>
            <spring_reference>0</spring_reference>
            <spring_stiffness>0</spring_stiffness>
          </dynamics>
          <use_parent_model_frame>1</use_parent_model_frame>
        </axis>
        <physics>
          <ode>
            <cfm_damping>1</cfm_damping>
            <limit>
              <cfm>0</cfm>
              <erp>0.2</erp>
            </limit>
          </ode>
        </physics>
      </joint>
      <static>0</static>
      <pose frame=''>-2.58869 -0.86774 0 0 -0 0</pose>
    </model>
    <gui fullscreen='0'>
      <camera name='user_camera'>
        <pose frame=''>4.56317 3.08098 5.77063 0 0.805323 2.76477</pose>
        <view_controller>orbit</view_controller>
        <projection_type>perspective</projection_type>
      </camera>
    </gui>
  </world>
</sdf>
